Workbook

Sheet OBE Details
A1: CO Score | B1: Percentage of Co attained
A2: Attained 3 | B2: 60 | D2: 50 percent and over, CO score attained is 3
A3: Attained 2 | B3: 60 | D3: 50 percent to 49 CO score attained is 2
A4: Attained 1 | B4: 60 | D4: 50 percent to 49 CO score attained is 1
A5: Threshold | B5: 60 | D5: Target achieved is sover threshold value
A8: Types | B8: Weightages
A9: Internal (Avg of ST1,ST2,ST3) | B9: 0.4
A10: External(ETE) | B10: 0.6
A12: CO Score | B12: Perecntage of students attaining Target
A13: 3 | B13: 0.8 | D13: CO score is 3 if 70 precent students attain atleast 50 percent CO's marks
A14: 2 | B14: 0.7 | D14: CO score is 2 if 55 precent students attain atleast 50 percent CO's marks
A15: 1 | B15: 0.6 | D15: CO score is 1 if 40 precent students attain atleast 50 percent CO's marks
A17: Teacher Name | B17: Prateek Singh Gambhir
A18: Employee Code | B18: CET1003740
A19: Course Name | B19: Digital Signal Processing
A20: Course Code | B20: EC118
A21: Batch | B21: 2020-2024
A22: Group | B22: G2

Sheet ST1 CO Question Map
A1: Q_Id | B1: Max Marks | C1: ='OBE Details'!$B$20&"_CO1" -> EC118_CO1 | D1: ='OBE Details'!$B$20&"_CO2" -> EC118_CO2 | E1: ='OBE Details'!$B$20&"_CO3" -> EC118_CO3 | F1: ='OBE Details'!$B$20&"_CO4" -> EC118_CO4 | G1: ='OBE Details'!$B$20&"_CO5" -> EC118_CO5 | H1: ='OBE Details'!$B$20&"_CO6" -> EC118_CO6
A2: 20EC118-ST1-1a | B2: 1 | C2: TRUE | D2: TRUE | E2: FALSE | F2: FALSE | G2: FALSE | H2: FALSE
A3: 20EC118-ST1-1b | B3: 1 | C3: TRUE | D3: TRUE | E3: FALSE | F3: FALSE | G3: FALSE | H3: FALSE
A4: 20EC118-ST1-1c | B4: 1 | C4: TRUE | D4: TRUE | E4: FALSE | F4: FALSE | G4: FALSE | H4: FALSE
A5: 20EC118-ST1-1d | B5: 1 | C5: TRUE | D5: TRUE | E5: FALSE | F5: FALSE | G5: FALSE | H5: FALSE
A6: 20EC118-ST1-1e | B6: 1 | C6: TRUE | D6: TRUE | E6: FALSE | F6: FALSE | G6: FALSE | H6: FALSE
A7: 20EC118-ST1-Q2 | B7: 2 | C7: TRUE | D7: FALSE | E7: FALSE | F7: FALSE | G7: FALSE | H7: FALSE
A8: 20EC118-ST1-Q3 | B8: 2 | C8: TRUE | D8: FALSE | E8: FALSE | F8: FALSE | G8: FALSE | H8: FALSE
A9: 20EC118-ST1-Q4 | B9: 2 | C9: TRUE | D9: FALSE | E9: FALSE | F9: FALSE | G9: FALSE | H9: FALSE
A10: 20EC118-ST1-Q5 | B10: 2 | C10: TRUE | D10: FALSE | E10: FALSE | F10: FALSE | G10: FALSE | H10: FALSE
A11: 20EC118-ST1-Q6 | B11: 2 | C11: TRUE | D11: FALSE | E11: FALSE | F11: FALSE | G11: FALSE | H11: FALSE
A12: 20EC118-ST1-Q7 | B12: 2 | C12: TRUE | D12: FALSE | E12: FALSE | F12: FALSE | G12: FALSE | H12: FALSE
A13: 20EC118-ST1-Q8 | B13: 5 | C13: TRUE | D13: FALSE | E13: FALSE | F13: FALSE | G13: FALSE | H13: FALSE
... A24: 20EC118-ST1-FA2 | B24: 0 | C24: FALSE | D24: FALSE | E24: FALSE | F24: FALSE | G24: FALSE | H24: FALSE

Sheet ST1 Result
A1: Sr.no | B1: Admission No. (Roll No.) | C1: Name of Student | D1: Division(Section) | E1: Course Code | F1: Course Name | G1: Lecture Type (Theory/Practical) | H1: Program Name | I1: Department Name | J1: Class Name (Batch) | K1: Semester Name | L1: Exam Name (ETE/ST/FA) | M1: {=TRANSPOSE('ST1 CO Question Map'!A2:A24)} -> 20EC118-ST1-1a | N1: 20EC118-ST1-1b | O1: 20EC118-ST1-1c | P1: 20EC118-ST1-1d | Q1: 20EC118-ST1-1e | R1: 20EC118-ST1-Q2 | S1: 20EC118-ST1-Q3 | T1: 20EC118-ST1-Q4 | U1: 20EC118-ST1-Q5 | V1: 20EC118-ST1-Q6 | W1: 20EC118-ST1-Q7 | X1: 20EC118-ST1-Q8 | Y1: 20EC118-ST1-Q9 | Z1: 20EC118-ST1-Q10 | AA1: 20EC118-ST1-Q11 | AB1: 20EC118-ST1-Q12 | AC1: 20EC118-ST1-Q13 | AD1: 20EC118-ST1-Q14 | AE1: 20EC118-ST1-Q15 | AF1: 20EC118-ST1-Q16 | AG1: 20EC118-ST1-Assignment | AH1: 20EC118-ST1-FA1 | AI1: 20EC118-ST1-FA2 | AJ1: Total Marks | AK1: Max Marks
A2: 1 | B2: 2010990089 | C2: ANSH GARG | E2: EC118 | F2: Digital Signal Processing | G2: Theory | H2: ECE | I2: CUIET | J2: 2020 | K2: 4 | L2: ST1 | M2: 1 | N2: 1 | O2: 1 | P2: 1 | Q2: 1 | R2: 2 | S2: 2 | T2: 2 | U2: 2 | V2: 2 | W2: U | X2: 1 | Y2: U | Z2: 5 | AA2: 5 | AB2: 1 | AC2: U | AD2: U | AE2: U | AF2: U | AG2: 7 | AH2: U | AI2: U | AJ2: 39 | AK2: 50
A3: 2 | B3: 2010992002 | C3: PANSY VERMA | E3: EC118 | F3: Digital Signal Processing | G3: Theory | H3: ECE | I3: CUIET | J3: 2020 | K3: 4 | L3: ST1 | M3: 1 | N3: 1 | O3: 1 | P3: 1 | Q3: 1 | R3: 2 | S3: 2 | T3: 2 | U3: 2 | V3: 2 | W3: U | X3: 5 | Y3: U | Z3: 5 | AA3: 5 | AB3: 8 | AC3: U | AD3: U | AE3: U | AF3: U | AG3: 10 | AH3: U | AI3: U | AJ3: =SUM(M3:AG3) -> 48 | AK3: 50
A4: 3 | B4: 2010992004 | C4: UTKARSH BHATT | E4: EC118 | F4: Digital Signal Processing | G4: Theory | H4: ECE | I4: CUIET | J4: 2020 | K4: 4 | L4: ST1 | M4: 1 | N4: 1 | O4: 1 | P4: 1 | Q4: 1 | R4: 2 | S4: U | T4: 2 | U4: 2 | V4: 2 | W4: 2 | X4: U | Y4: 4 | Z4: 5 | AA4: 2 | AB4: U | AC4: 1 | AD4: U | AE4: U | AF4: U | AG4: 5 | AH4: U | AI4: U | AJ4: =SUM(M4:AG4) -> 32 | AK4: 50
A5: 4 | B5: 2010992005 | C5: RATANABH SHARMA | E5: EC118 | F5: Digital Signal Processing | G5: Theory | H5: ECE | I5: CUIET | J5: 2020 | K5: 4 | L5: ST1 | M5: 1 | N5: 1 | O5: 1 | P5: 1 | Q5: 1 | R5: 2 | S5: 2 | T5: U | U5: 2 | V5: 2 | W5: 2 | X5: 4 | Y5: U | Z5: U | AA5: U | AB5: 1 | AC5: U | AD5: U | AE5: U | AF5: U | AG5: 7 | AH5: U | AI5: U | AJ5: =SUM(M5:AG5) -> 27 | AK5: 50
A6: 5 | B6: 2010992006 | C6: AYUSH SHARMA | E6: EC118 | F6: Digital Signal Processing | G6: Theory | H6: ECE | I6: CUIET | J6: 2020 | K6: 4 | L6: ST1 | M6: 1 | N6: 1 | O6: 1 | P6: 1 | Q6: 1 | R6: 2 | S6: 2 | T6: 2 | U6: 2 | V6: 2 | W6: U | X6: 4 | Y6: 1 | Z6: 5 | AA6: U | AB6: U | AC6: 1 | AD6: U | AE6: U | AF6: U | AG6: 5 | AH6: U | AI6: U | AJ6: =SUM(M6:AG6) -> 31 | AK6: 50
A7: 6 | B7: 2010992008 | C7: NAVDEEP SINGH | E7: EC118 | F7: Digital Signal Processing | G7: Theory | H7: ECE | I7: CUIET | J7: 2020 | K7: 4 | L7: ST1 | M7: 1 | N7: 1 | O7: 1 | P7: 1 | Q7: 1 | R7: U | S7: 2 | T7: 2 | U7: 2 | V7: 2 | W7: 2 | X7: 1 | Y7: 4 | Z7: U | AA7: 5 | AB7: 1 | AC7: U | AD7: U | AE7: U | AF7: U | AG7: U | AH7: U | AI7: U | AJ7: =SUM(M7:AG7) -> 26 | AK7: 50
A8: 7 | B8: 2010992009 | C8: RIYA | E8: EC118 | F8: Digital Signal Processing | G8: Theory | H8: ECE | I8: CUIET | J8: 2020 | K8: 4 | L8: ST1 | M8: 1 | N8: 1 | O8: 1 | P8: 1 | Q8: 1 | R8: 2 | S8: 2 | T8: 2 | U8: 2 | V8: U | W8: 2 | X8: 5 | Y8: U | Z8: 5 | AA8: 5 | AB8: 2 | AC8: U | AD8: U | AE8: U | AF8: U | AG8: 10 | AH8: U | AI8: U | AJ8: =SUM(M8:AG8) -> 42 | AK8: 50
A9: 8 | B9: 2010992010 | C9: RISHABH TANDON | E9: EC118 | F9: Digital Signal Processing | G9: Theory | H9: ECE | I9: CUIET | J9: 2020 | K9: 4 | L9: ST1 | M9: 1 | N9: 1 | O9: 1 | P9: 1 | Q9: 1 | R9: 2 | S9: 2 | T9: 2 | U9: U | V9: 2 | W9: 2 | X9: U | Y9: 4 | Z9: 5 | AA9: 4 | AB9: 1 | AC9: U | AD9: U | AE9: U | AF9: U | AG9: 7 | AH9: U | AI9: U | AJ9: =SUM(M9:AG9) -> 36 | AK9: 50
A10: 9 | B10: 2010992011 | C10: HEERENDRA SINGH CHAUHAN | E10: EC118 | F10: Digital Signal Processing | G10: Theory | H10: ECE | I10: CUIET | J10: 2020 | K10: 4 | L10: ST1 | M10: 1 | N10: 1 | O10: 1 | P10: 1 | Q10: 1 | R10: U | S10: 2 | T10: 2 | U10: 2 | V10: 2 | W10: 2 | X10: 4 | Y10: U | Z10: U | AA10: 4 | AB10: U | AC10: 1 | AD10: U | AE10: U | AF10: U | AG10: 5 | AH10: U | AI10: U | AJ10: =SUM(M10:AG10) -> 29 | AK10: 50
A11: 10 | B11: 2010992012 | C11: AKSHAT | E11: EC118 | F11: Digital Signal Processing | G11: Theory | H11: ECE | I11: CUIET | J11: 2020 | K11: 4 | L11: ST1 | M11: 1 | N11: 1 | O11: 1 | P11: 1 | Q11: 1 | R11: U | S11: 2 | T11: 2 | U11: 2 | V11: 2 | W11: 2 | X11: 5 | Y11: 5 | Z11: U | AA11: 5 | AB11: 2 | AC11: U | AD11: U | AE11: U | AF11: U | AG11: 10 | AH11: U | AI11: U | AJ11: =SUM(M11:AG11) -> 42 | AK11: 50
A12: 11 | B12: 2010992014 | C12: HARSHIT CHAHAL | E12: EC118 | F12: Digital Signal Processing | G12: Theory | H12: ECE | I12: CUIET | J12: 2020 | K12: 4 | L12: ST1 | M12: 1 | N12: 1 | O12: 1 | P12: 1 | Q12: 1 | R12: 2 | S12: 2 | T12: 2 | U12: 2 | V12: U | W12: 2 | X12: 5 | Y12: 5 | Z12: U | AA12: 5 | AB12: 6 | AC12: U | AD12: U | AE12: U | AF12: U | AG12: U | AH12: U | AI12: U | AJ12: =SUM(M12:AG12) -> 36 | AK12: 50
A13: 12 | B13: 2010992015 | C13: URVANSH NAHATA | E13: EC118 | F13: Digital Signal Processing | G13: Theory | H13: ECE | I13: CUIET | J13: 2020 | K13: 4 | L13: ST1 | M13: 1 | N13: 1 | O13: 1 | P13: 1 | Q13: 1 | R13: 2 | S13: 2 | T13: U | U13: 2 | V13: 2 | W13: 2 | X13: U | Y13: 4 | Z13: U | AA13: 1 | AB13: 1 | AC13: U | AD13: U | AE13: U | AF13: U | AG13: U | AH13: U | AI13: U | AJ13: =SUM(M13:AG13) -> 21 | AK13: 50
A14: 13 | B14: 2010992016 | C14: VARUN | E14: EC118 | F14: Digital Signal Processing | G14: Theory | H14: ECE | I14: CUIET | J14: 2020 | K14: 4 | L14: ST1 | M14: 1 | N14: 1 | O14: 1 | P14: 1 | Q14: 1 | R14: 2 | S14: 2 | T14: 2 | U14: 2 | V14: 2 | W14: U | X14: 4 | Y14: 5 | Z14: U | AA14: 3 | AB14: U | AC14: 1 | AD14: U | AE14: U | AF14: U | AG14: 10 | AH14: U | AI14: U | AJ14: =SUM(M14:AG14) -> 38 | AK14: 50
A15: 14 | B15: 2010992017 | C15: MRIDUL AGGARWAL | E15: EC118 | F15: Digital Signal Processing | G15: Theory | H15: ECE | I15: CUIET | J15: 2020 | K15: 4 | L15: ST1 | M15: 1 | N15: 1 | O15: 1 | P15: 1 | Q15: 1 | R15: 2 | S15: 2 | T15: 2 | U15: 2 | V15: U | W15: 2 | X15: U | Y15: 1 | Z15: U | AA15: 5 | AB15: U | AC15: 1 | AD15: U | AE15: U | AF15: U | AG15: 5 | AH15: U | AI15: U | AJ15: =SUM(M15:AG15) -> 27 | AK15: 50
A16: 15 | B16: 2010992018 | C16: SHAKSHI SINGH | E16: EC118 | F16: Digital Signal Processing | G16: Theory | H16: ECE | I16: CUIET | J16: 2020 | K16: 4 | L16: ST1 | M16: 1 | N16: 1 | O16: 1 | P16: 1 | Q16: 1 | R16: U | S16: 2 | T16: 2 | U16: 2 | V16: 2 | W16: 2 | X16: 2 | Y16: 5 | Z16: 5 | AA16: U | AB16: 1 | AC16: U | AD16: U | AE16: U | AF16: U | AG16: 5 | AH16: U | AI16: U | AJ16: =SUM(M16:AG16) -> 33 | AK16: 50
A17: 16 | B17: 2010992163 | C17: TAMANA SIAG | E17: EC118 | F17: Digital Signal Processing | G17: Theory | H17: ECE | I17: CUIET | J17: 2020 | K17: 4 | L17: ST1 | M17: 1 | N17: 1 | O17: 1 | P17: 1 | Q17: 1 | R17: 2 | S17: U | T17: 2 | U17: 2 | V17: 2 | W17: 2 | X17: 5 | Y17: 5 | Z17: U | AA17: 5 | AB17: 1 | AC17: U | AD17: U | AE17: U | AF17: U | AG17: 10 | AH17: U | AI17: U | AJ17: =SUM(M17:AG17) -> 41 | AK17: 50
A18: 17 | B18: 2010992202 | C18: EKAMJOT SINGH MAINGI | E18: EC118 | F18: Digital Signal Processing | G18: Theory | H18: ECE | I18: CUIET | J18: 2020 | K18: 4 | L18: ST1 | M18: 1 | N18: 1 | O18: 1 | P18: 1 | Q18: 1 | R18: 2 | S18: 2 | T18: 2 | U18: 2 | V18: U | W18: 2 | X18: U | Y18: 2 | Z18: U | AA18: U | AB18: 1 | AC18: U | AD18: U | AE18: U | AF18: U | AG18: 5 | AH18: U | AI18: U | AJ18: =SUM(M18:AG18) -> 23 | AK18: 50
A19: 18 | B19: 2010992203 | C19: Khan | E19: EC118 | F19: Digital Signal Processing | G19: Theory | H19: ECE | I19: CUIET | J19: 2020 | K19: 4 | L19: ST1 | M19: 1 | N19: 1 | O19: 1 | P19: 1 | Q19: 1 | R19: 2 | S19: 2 | T19: 2 | U19: 2 | V19: U | W19: 2 | X19: 4 | Y19: 2 | Z19: 5 | AA19: U | AB19: U | AC19: 1 | AD19: U | AE19: U | AF19: U | AG19: 7 | AH19: U | AI19: U | AJ19: =SUM(M19:AG19) -> 34 | AK19: 50

Sheet ST2 CO Question Map
A1: Q_Id | B1: Max Marks | C1: ='OBE Details'!$B$20&"_CO1" -> EC118_CO1 | D1: ='OBE Details'!$B$20&"_CO2" -> EC118_CO2 | E1: ='OBE Details'!$B$20&"_CO3" -> EC118_CO3 | F1: ='OBE Details'!$B$20&"_CO4" -> EC118_CO4 | G1: ='OBE Details'!$B$20&"_CO5" -> EC118_CO5 | H1: ='OBE Details'!$B$20&"_CO6" -> EC118_CO6
A2: 20EC118-ST2-1a | B2: 1 | C2: TRUE | D2: TRUE | E2: FALSE | F2: FALSE | G2: FALSE | H2: FALSE
A3: 20EC118-ST2-1b | B3: 1 | C3: TRUE | D3: TRUE | E3: FALSE | F3: FALSE | G3: FALSE | H3: FALSE
A4: 20EC118-ST2-1c | B4: 1 | C4: TRUE | D4: TRUE | E4: FALSE | F4: FALSE | G4: FALSE | H4: FALSE
A5: 20EC118-ST2-1d | B5: 1 | C5: TRUE | D5: TRUE | E5: FALSE | F5: FALSE | G5: FALSE | H5: FALSE
A6: 20EC118-ST2-1e | B6: 1 | C6: TRUE | D6: TRUE | E6: FALSE | F6: FALSE | G6: FALSE | H6: FALSE
A7: 20EC118-ST2-Q2 | B7: 2 | C7: FALSE | D7: TRUE | E7: FALSE | F7: FALSE | G7: FALSE | H7: FALSE
A8: 20EC118-ST2-Q3 | B8: 2 | C8: FALSE | D8: TRUE | E8: FALSE | F8: FALSE | G8: FALSE | H8: FALSE
A9: 20EC118-ST2-Q4 | B9: 2 | C9: FALSE | D9: TRUE | E9: FALSE | F9: FALSE | G9: FALSE | H9: FALSE
A10: 20EC118-ST2-Q5 | B10: 2 | C10: FALSE | D10: TRUE | E10: FALSE | F10: FALSE | G10: FALSE | H10: FALSE
A11: 20EC118-ST2-Q6 | B11: 2 | C11: FALSE | D11: TRUE | E11: FALSE | F11: FALSE | G11: FALSE | H11: FALSE
A12: 20EC118-ST2-Q7 | B12: 2 | C12: TRUE | D12: TRUE | E12: FALSE | F12: FALSE | G12: FALSE | H12: FALSE
A13: 20EC118-ST2-Q8 | B13: 5 | C13: TRUE | D13: TRUE | E13: FALSE | F13: FALSE | G13: FALSE | H13: FALSE
... A24: 20EC118-ST2-FA2 | B24: 0 | C24: FALSE | D24: FALSE | E24: FALSE | F24: FALSE | G24: FALSE | H24: FALSE

Sheet ST2 Result
A1: Sr.no | B1: Admission No. (Roll No.) | C1: Name of Student | D1: Division(Section) | E1: Course Code | F1: Course Name | G1: Lecture Type (Theory/Practical) | H1: Program Name | I1: Department Name | J1: Class Name (Batch) | K1: Semester Name | L1: Exam Name (ETE/ST/FA) | M1: {=TRANSPOSE('ST2 CO Question Map'!A2:A24)} -> 20EC118-ST2-1a | N1: 20EC118-ST2-1b | O1: 20EC118-ST2-1c | P1: 20EC118-ST2-1d | Q1: 20EC118-ST2-1e | R1: 20EC118-ST2-Q2 | S1: 20EC118-ST2-Q3 | T1: 20EC118-ST2-Q4 | U1: 20EC118-ST2-Q5 | V1: 20EC118-ST2-Q6 | W1: 20EC118-ST2-Q7 | X1: 20EC118-ST2-Q8 | Y1: 20EC118-ST2-Q9 | Z1: 20EC118-ST2-Q10 | AA1: 20EC118-ST2-Q11 | AB1: 20EC118-ST2-Q12 | AC1: 20EC118-ST2-Q13 | AD1: 20EC118-ST2-Q14 | AE1: 20EC118-ST2-Q15 | AF1: 20EC118-ST2-Q16 | AG1: 20EC118-ST2-Assignment | AH1: 20EC118-ST2-FA1 | AI1: 20EC118-ST2-FA2 | AJ1: Total Marks | AK1: max Marks
A2: 1 | B2: 2010990089 | C2: ANSH GARG | E2: EC118 | F2: Digital Signal Processing | G2: Theory | H2: ECE | I2: CUIET | J2: 2020 | K2: 4 | L2: ST2 | M2: 1 | N2: 1 | O2: 1 | P2: 1 | Q2: 1 | R2: U | S2: 1 | T2: 2 | U2: 2 | V2: U | W2: 2 | X2: U | Y2: U | Z2: U | AA2: U | AB2: 1 | AC2: U | AD2: U | AE2: U | AF2: U | AG2: 8 | AH2: U | AI2: U | AJ2: =SUM(M2:AG2) -> 21 | AK2: 50
A3: 2 | B3: 2010992002 | C3: PANSY VERMA | E3: EC118 | F3: Digital Signal Processing | G3: Theory | H3: ECE | I3: CUIET | J3: 2020 | K3: 4 | L3: ST2 | M3: 1 | N3: 1 | O3: 1 | P3: 1 | Q3: 1 | R3: 2 | S3: 2 | T3: 2 | U3: U | V3: 2 | W3: 2 | X3: 5 | Y3: 5 | Z3: 5 | AA3: U | AB3: U | AC3: 7 | AD3: U | AE3: U | AF3: U | AG3: 10 | AH3: U | AI3: U | AJ3: =SUM(M3:AG3) -> 47 | AK3: 50
A4: 3 | B4: 2010992004 | C4: UTKARSH BHATT | E4: EC118 | F4: Digital Signal Processing | G4: Theory | H4: ECE | I4: CUIET | J4: 2020 | K4: 4 | L4: ST2 | M4: U | N4: U | O4: U | P4: U | Q4: U | R4: U | S4: U | T4: U | U4: U | V4: U | W4: U | X4: U | Y4: U | Z4: U | AA4: U | AB4: U | AC4: U | AD4: U | AE4: U | AF4: U | AG4: 6 | AH4: U | AI4: U | AJ4: =SUM(M4:AG4) -> 6 | AK4: 50
A5: 4 | B5: 2010992005 | C5: RATANABH SHARMA | E5: EC118 | F5: Digital Signal Processing | G5: Theory | H5: ECE | I5: CUIET | J5: 2020 | K5: 4 | L5: ST2 | M5: U | N5: U | O5: U | P5: U | Q5: U | R5: U | S5: U | T5: U | U5: U | V5: U | W5: U | X5: U | Y5: U | Z5: U | AA5: U | AB5: U | AC5: U | AD5: U | AE5: U | AF5: U | AG5: 8 | AH5: U | AI5: U | AJ5: =SUM(M5:AG5) -> 8 | AK5: 50
A6: 5 | B6: 2010992006 | C6: AYUSH SHARMA | E6: EC118 | F6: Digital Signal Processing | G6: Theory | H6: ECE | I6: CUIET | J6: 2020 | K6: 4 | L6: ST2 | M6: U | N6: U | O6: U | P6: U | Q6: U | R6: U | S6: U | T6: U | U6: U | V6: U | W6: U | X6: U | Y6: U | Z6: U | AA6: U | AB6: U | AC6: U | AD6: U | AE6: U | AF6: U | AG6: U | AH6: U | AI6: U | AJ6: =SUM(M6:AG6) -> 0 | AK6: 50
A7: 6 | B7: 2010992008 | C7: NAVDEEP SINGH | E7: EC118 | F7: Digital Signal Processing | G7: Theory | H7: ECE | I7: CUIET | J7: 2020 | K7: 4 | L7: ST2 | M7: U | N7: U | O7: U | P7: U | Q7: U | R7: U | S7: U | T7: U | U7: U | V7: U | W7: U | X7: U | Y7: U | Z7: U | AA7: U | AB7: U | AC7: U | AD7: U | AE7: U | AF7: U | AG7: U | AH7: U | AI7: U | AJ7: =SUM(M7:AG7) -> 0 | AK7: 50
A8: 7 | B8: 2010992009 | C8: RIYA | E8: EC118 | F8: Digital Signal Processing | G8: Theory | H8: ECE | I8: CUIET | J8: 2020 | K8: 4 | L8: ST2 | M8: 1 | N8: 1 | O8: 1 | P8: 1 | Q8: 1 | R8: 2 | S8: 2 | T8: U | U8: 2 | V8: 2 | W8: 2 | X8: U | Y8: 5 | Z8: 5 | AA8: 5 | AB8: 3 | AC8: U | AD8: U | AE8: U | AF8: U | AG8: 9 | AH8: U | AI8: U | AJ8: 43 | AK8: 50
A9: 8 | B9: 2010992010 | C9: RISHABH TANDON | E9: EC118 | F9: Digital Signal Processing | G9: Theory | H9: ECE | I9: CUIET | J9: 2020 | K9: 4 | L9: ST2 | M9: U | N9: U | O9: U | P9: U | Q9: U | R9: U | S9: U | T9: U | U9: U | V9: U | W9: U | X9: U | Y9: U | Z9: U | AA9: U | AB9: U | AC9: U | AD9: U | AE9: U | AF9: U | AG9: U | AH9: U | AI9: U | AJ9: =SUM(M9:AG9) -> 0 | AK9: 50
A10: 9 | B10: 2010992011 | C10: HEERENDRA SINGH CHAUHAN | E10: EC118 | F10: Digital Signal Processing | G10: Theory | H10: ECE | I10: CUIET | J10: 2020 | K10: 4 | L10: ST2 | M10: U | N10: U | O10: U | P10: U | Q10: U | R10: U | S10: U | T10: U | U10: U | V10: U | W10: U | X10: U | Y10: U | Z10: U | AA10: U | AB10: U | AC10: U | AD10: U | AE10: U | AF10: U | AG10: 6 | AH10: U | AI10: U | AJ10: =SUM(M10:AG10) -> 6 | AK10: 50
A11: 10 | B11: 2010992012 | C11: AKSHAT | E11: EC118 | F11: Digital Signal Processing | G11: Theory | H11: ECE | I11: CUIET | J11: 2020 | K11: 4 | L11: ST2 | M11: 1 | N11: 1 | O11: 1 | P11: 1 | Q11: 1 | R11: U | S11: 2 | T11: 2 | U11: 2 | V11: 2 | W11: 2 | X11: U | Y11: U | Z11: 1 | AA11: U | AB11: U | AC11: 1 | AD11: U | AE11: U | AF11: U | AG11: 8 | AH11: U | AI11: U | AJ11: =SUM(M11:AG11) -> 25 | AK11: 50
A12: 11 | B12: 2010992014 | C12: HARSHIT CHAHAL | E12: EC118 | F12: Digital Signal Processing | G12: Theory | H12: ECE | I12: CUIET | J12: 2020 | K12: 4 | L12: ST2 | M12: U | N12: U | O12: U | P12: U | Q12: U | R12: U | S12: U | T12: U | U12: U | V12: U | W12: U | X12: U | Y12: U | Z12: U | AA12: U | AB12: U | AC12: U | AD12: U | AE12: U | AF12: U | AG12: 7 | AH12: U | AI12: U | AJ12: =SUM(M12:AG12) -> 7 | AK12: 50
A13: 12 | B13: 2010992015 | C13: URVANSH NAHATA | E13: EC118 | F13: Digital Signal Processing | G13: Theory | H13: ECE | I13: CUIET | J13: 2020 | K13: 4 | L13: ST2 | M13: U | N13: 1 | O13: 1 | P13: U | Q13: U | R13: U | S13: U | T13: U | U13: U | V13: U | W13: U | X13: U | Y13: U | Z13: U | AA13: U | AB13: U | AC13: 1 | AD13: U | AE13: U | AF13: U | AG13: 7 | AH13: U | AI13: U | AJ13: =SUM(M13:AG13) -> 10 | AK13: 50
A14: 13 | B14: 2010992016 | C14: VARUN | E14: EC118 | F14: Digital Signal Processing | G14: Theory | H14: ECE | I14: CUIET | J14: 2020 | K14: 4 | L14: ST2 | M14: 1 | N14: 1 | O14: 1 | P14: 1 | Q14: 1 | R14: 2 | S14: 2 | T14: 2 | U14: 2 | V14: 2 | W14: U | X14: 4 | Y14: 5 | Z14: 2 | AA14: U | AB14: U | AC14: 1 | AD14: U | AE14: U | AF14: U | AG14: 9 | AH14: U | AI14: U | AJ14: =SUM(M14:AG14) -> 36 | AK14: 50
A15: 14 | B15: 2010992017 | C15: MRIDUL AGGARWAL | E15: EC118 | F15: Digital Signal Processing | G15: Theory | H15: ECE | I15: CUIET | J15: 2020 | K15: 4 | L15: ST2 | M15: U | N15: U | O15: U | P15: U | Q15: U | R15: U | S15: U | T15: U | U15: U | V15: U | W15: U | X15: U | Y15: U | Z15: U | AA15: U | AB15: U | AC15: U | AD15: U | AE15: U | AF15: U | AG15: 8 | AH15: U | AI15: U | AJ15: =SUM(M15:AG15) -> 8 | AK15: 50
A16: 15 | B16: 2010992018 | C16: SHAKSHI SINGH | E16: EC118 | F16: Digital Signal Processing | G16: Theory | H16: ECE | I16: CUIET | J16: 2020 | K16: 4 | L16: ST2 | M16: 1 | N16: 1 | O16: 1 | P16: 1 | Q16: 1 | R16: 2 | S16: U | T16: 2 | U16: 2 | V16: 2 | W16: 2 | X16: 4 | Y16: 5 | Z16: 2 | AA16: U | AB16: 1 | AC16: U | AD16: U | AE16: U | AF16: U | AG16: 8 | AH16: U | AI16: U | AJ16: =SUM(M16:AG16) -> 35 | AK16: 50
A17: 16 | B17: 2010992163 | C17: TAMANA SIAG | E17: EC118 | F17: Digital Signal Processing | G17: Theory | H17: ECE | I17: CUIET | J17: 2020 | K17: 4 | L17: ST2 | M17: 1 | N17: 1 | O17: 1 | P17: 1 | Q17: 1 | R17: U | S17: 2 | T17: 2 | U17: 2 | V17: 2 | W17: 2 | X17: U | Y17: 5 | Z17: 5 | AA17: 5 | AB17: U | AC17: 5 | AD17: U | AE17: U | AF17: U | AG17: 9 | AH17: U | AI17: U | AJ17: =SUM(M17:AG17) -> 44 | AK17: 50
A18: 17 | B18: 2010992202 | C18: EKAMJOT SINGH MAINGI | E18: EC118 | F18: Digital Signal Processing | G18: Theory | H18: ECE | I18: CUIET | J18: 2020 | K18: 4 | L18: ST2 | M18: 1 | N18: 1 | O18: 1 | P18: 1 | Q18: 1 | R18: U | S18: 1 | T18: 2 | U18: U | V18: 2 | W18: 2 | X18: U | Y18: U | Z18: U | AA18: U | AB18: U | AC18: 1 | AD18: U | AE18: U | AF18: U | AG18: 6 | AH18: U | AI18: U | AJ18: =SUM(M18:AG18) -> 19 | AK18: 50
A19: 18 | B19: 2010992203 | C19: Khan | E19: EC118 | F19: Digital Signal Processing | G19: Theory | H19: ECE | I19: CUIET | J19: 2020 | K19: 4 | L19: ST2 | M19: 1 | N19: 1 | O19: 1 | P19: 1 | Q19: 1 | R19: U | S19: 1 | T19: 2 | U19: 2 | V19: 2 | W19: U | X19: U | Y19: U | Z19: U | AA19: U | AB19: U | AC19: 1 | AD19: U | AE19: U | AF19: U | AG19: 9 | AH19: U | AI19: U | AJ19: =SUM(M19:AG19) -> 22 | AK19: 50

Sheet ST3 CO Question Map
A1: Q_Id | B1: Max Marks | C1: ='OBE Details'!$B$20&"_CO1" -> EC118_CO1 | D1: ='OBE Details'!$B$20&"_CO2" -> EC118_CO2 | E1: ='OBE Details'!$B$20&"_CO3" -> EC118_CO3 | F1: ='OBE Details'!$B$20&"_CO4" -> EC118_CO4 | G1: ='OBE Details'!$B$20&"_CO5" -> EC118_CO5 | H1: ='OBE Details'!$B$20&"_CO6" -> EC118_CO6
A2: 20EC118-ST3-1a | B2: 1 | C2: TRUE | D2: FALSE | E2: FALSE | F2: FALSE | G2: FALSE | H2: FALSE
A3: 20EC118-ST3-1b | B3: 1 | C3: TRUE | D3: FALSE | E3: FALSE | F3: FALSE | G3: FALSE | H3: FALSE
A4: 20EC118-ST3-1c | B4: 1 | C4: TRUE | D4: FALSE | E4: FALSE | F4: FALSE | G4: FALSE | H4: FALSE
A5: 20EC118-ST3-1d | B5: 1 | C5: TRUE | D5: FALSE | E5: FALSE | F5: FALSE | G5: FALSE | H5: FALSE
A6: 20EC118-ST3-1e | B6: 1 | C6: TRUE | D6: FALSE | E6: FALSE | F6: FALSE | G6: FALSE | H6: FALSE
A7: 20EC118-ST3-Q2 | B7: 2 | C7: TRUE | D7: FALSE | E7: FALSE | F7: FALSE | G7: FALSE | H7: FALSE
A8: 20EC118-ST3-Q3 | B8: 2 | C8: TRUE | D8: FALSE | E8: FALSE | F8: FALSE | G8: FALSE | H8: FALSE
A9: 20EC118-ST3-Q4 | B9: 2 | C9: FALSE | D9: TRUE | E9: FALSE | F9: FALSE | G9: FALSE | H9: FALSE
A10: 20EC118-ST3-Q5 | B10: 2 | C10: FALSE | D10: TRUE | E10: FALSE | F10: FALSE | G10: FALSE | H10: FALSE
A11: 20EC118-ST3-Q6 | B11: 2 | C11: FALSE | D11: FALSE | E11: TRUE | F11: FALSE | G11: FALSE | H11: FALSE
A12: 20EC118-ST3-Q7 | B12: 2 | C12: FALSE | D12: TRUE | E12: FALSE | F12: FALSE | G12: FALSE | H12: FALSE
A13: 20EC118-ST3-Q8 | B13: 5 | C13: TRUE | D13: FALSE | E13: FALSE | F13: FALSE | G13: FALSE | H13: FALSE
... A24: 20EC118-ST3-FA2 | B24: 15 | C24: FALSE | D24: FALSE | E24: FALSE | F24: FALSE | G24: FALSE | H24: FALSE

Sheet ST3 Result
A1: Sr.no | B1: Admission No. (Roll No.) | C1: Name of Student | D1: Division(Section) | E1: Course Code | F1: Course Name | G1: Lecture Type (Theory/Practical) | H1: Program Name | I1: Department Name | J1: Class Name (Batch) | K1: Semester Name | L1: Exam Name (ETE/ST/FA) | M1: {=TRANSPOSE('ST3 CO Question Map'!A2:A24)} -> 20EC118-ST3-1a | N1: 20EC118-ST3-1b | O1: 20EC118-ST3-1c | P1: 20EC118-ST3-1d | Q1: 20EC118-ST3-1e | R1: 20EC118-ST3-Q2 | S1: 20EC118-ST3-Q3 | T1: 20EC118-ST3-Q4 | U1: 20EC118-ST3-Q5 | V1: 20EC118-ST3-Q6 | W1: 20EC118-ST3-Q7 | X1: 20EC118-ST3-Q8 | Y1: 20EC118-ST3-Q9 | Z1: 20EC118-ST3-Q10 | AA1: 20EC118-ST3-Q11 | AB1: 20EC118-ST3-Q12 | AC1: 20EC118-ST3-Q13 | AD1: 20EC118-ST3-Q14 | AE1: 20EC118-ST3-Q15 | AF1: 20EC118-ST3-Q16 | AG1: 20EC118-ST3-Assignment | AH1: 20EC118-ST3-FA1 | AI1: 20EC118-ST3-FA2 | AJ1: Total Marks | AK1: max Marks
A2: 1 | B2: 2010990089 | C2: ANSH GARG | E2: EC118 | F2: Digital Signal Processing | G2: Theory | H2: ECE | I2: CUIET | J2: 2020 | K2: 4 | L2: ST3 | M2: 1 | N2: 1 | O2: 1 | P2: 1 | Q2: 1 | R2: U | S2: U | T2: U | U2: U | V2: U | W2: U | X2: U | Y2: U | Z2: U | AA2: U | AB2: U | AC2: 1 | AD2: U | AE2: U | AF2: U | AG2: U | AH2: U | AI2: U | AJ2: 39 | AK2: 40
A3: 2 | B3: 2010992002 | C3: PANSY VERMA | E3: EC118 | F3: Digital Signal Processing | G3: Theory | H3: ECE | I3: CUIET | J3: 2020 | K3: 4 | L3: ST3 | M3: 1 | N3: 1 | O3: 1 | P3: 1 | Q3: 1 | R3: 2 | S3: 2 | T3: U | U3: 2 | V3: 2 | W3: 2 | X3: 5 | Y3: 5 | Z3: 5 | AA3: U | AB3: 5 | AC3: U | AD3: U | AE3: U | AF3: U | AG3: U | AH3: U | AI3: U | AJ3: =SUM(M3:AG3) -> 35 | AK3: 40
A4: 3 | B4: 2010992004 | C4: UTKARSH BHATT | E4: EC118 | F4: Digital Signal Processing | G4: Theory | H4: ECE | I4: CUIET | J4: 2020 | K4: 4 | L4: ST3 | M4: 1 | N4: 1 | O4: 1 | P4: 1 | Q4: 1 | R4: 2 | S4: 2 | T4: 2 | U4: U | V4: 2 | W4: 2 | X4: U | Y4: 1 | Z4: U | AA4: U | AB4: 1 | AC4: U | AD4: U | AE4: U | AF4: U | AG4: U | AH4: U | AI4: U | AJ4: =SUM(M4:AG4) -> 17 | AK4: 40
A5: 4 | B5: 2010992005 | C5: RATANABH SHARMA | E5: EC118 | F5: Digital Signal Processing | G5: Theory | H5: ECE | I5: CUIET | J5: 2020 | K5: 4 | L5: ST3 | M5: 1 | N5: 1 | O5: 1 | P5: 1 | Q5: 1 | R5: 1 | S5: U | T5: U | U5: U | V5: U | W5: 2 | X5: U | Y5: U | Z5: U | AA5: U | AB5: U | AC5: 1 | AD5: U | AE5: U | AF5: U | AG5: U | AH5: U | AI5: U | AJ5: =SUM(M5:AG5) -> 9 | AK5: 40
A6: 5 | B6: 2010992006 | C6: AYUSH SHARMA | E6: EC118 | F6: Digital Signal Processing | G6: Theory | H6: ECE | I6: CUIET | J6: 2020 | K6: 4 | L6: ST3 | M6: 1 | N6: 1 | O6: 1 | P6: 1 | Q6: 1 | R6: 1 | S6: 2 | T6: U | U6: U | V6: U | W6: U | X6: U | Y6: U | Z6: U | AA6: U | AB6: 1 | AC6: U | AD6: U | AE6: U | AF6: U | AG6: U | AH6: U | AI6: U | AJ6: =SUM(M6:AG6) -> 9 | AK6: 40
A7: 6 | B7: 2010992008 | C7: NAVDEEP SINGH | E7: EC118 | F7: Digital Signal Processing | G7: Theory | H7: ECE | I7: CUIET | J7: 2020 | K7: 4 | L7: ST3 | M7: 1 | N7: 1 | O7: 1 | P7: 1 | Q7: 1 | R7: U | S7: U | T7: 1 | U7: 2 | V7: 2 | W7: 2 | X7: U | Y7: U | Z7: U | AA7: U | AB7: 1 | AC7: U | AD7: U | AE7: U | AF7: U | AG7: U | AH7: U | AI7: U | AJ7: =SUM(M7:AG7) -> 13 | AK7: 40
A8: 7 | B8: 2010992009 | C8: RIYA | E8: EC118 | F8: Digital Signal Processing | G8: Theory | H8: ECE | I8: CUIET | J8: 2020 | K8: 4 | L8: ST3 | M8: U | N8: U | O8: U | P8: U | Q8: U | R8: U | S8: U | T8: U | U8: U | V8: U | W8: U | X8: U | Y8: U | Z8: U | AA8: U | AB8: U | AC8: U | AD8: U | AE8: U | AF8: U | AG8: U | AH8: U | AI8: U | AJ8: 43 | AK8: 40
A9: 8 | B9: 2010992010 | C9: RISHABH TANDON | E9: EC118 | F9: Digital Signal Processing | G9: Theory | H9: ECE | I9: CUIET | J9: 2020 | K9: 4 | L9: ST3 | M9: 1 | N9: 1 | O9: 1 | P9: 1 | Q9: 1 | R9: 1 | S9: U | T9: U | U9: U | V9: 2 | W9: 2 | X9: U | Y9: U | Z9: U | AA9: U | AB9: 1 | AC9: U | AD9: U | AE9: U | AF9: U | AG9: U | AH9: U | AI9: U | AJ9: =SUM(M9:AG9) -> 11 | AK9: 40
A10: 9 | B10: 2010992011 | C10: HEERENDRA SINGH CHAUHAN | E10: EC118 | F10: Digital Signal Processing | G10: Theory | H10: ECE | I10: CUIET | J10: 2020 | K10: 4 | L10: ST3 | M10: 1 | N10: 1 | O10: 1 | P10: 1 | Q10: 1 | R10: U | S10: 1 | T10: 2 | U10: 2 | V10: 2 | W10: 2 | X10: U | Y10: U | Z10: U | AA10: U | AB10: U | AC10: 1 | AD10: U | AE10: U | AF10: U | AG10: U | AH10: U | AI10: U | AJ10: =SUM(M10:AG10) -> 15 | AK10: 40
A11: 10 | B11: 2010992012 | C11: AKSHAT | E11: EC118 | F11: Digital Signal Processing | G11: Theory | H11: ECE | I11: CUIET | J11: 2020 | K11: 4 | L11: ST3 | M11: 1 | N11: 1 | O11: 1 | P11: 1 | Q11: 1 | R11: U | S11: U | T11: 1 | U11: 1 | V11: U | W11: 2 | X11: U | Y11: U | Z11: U | AA11: U | AB11: 1 | AC11: U | AD11: U | AE11: U | AF11: U | AG11: U | AH11: U | AI11: U | AJ11: =SUM(M11:AG11) -> 10 | AK11: 40
A12: 11 | B12: 2010992014 | C12: HARSHIT CHAHAL | E12: EC118 | F12: Digital Signal Processing | G12: Theory | H12: ECE | I12: CUIET | J12: 2020 | K12: 4 | L12: ST3 | M12: 1 | N12: 1 | O12: 1 | P12: 1 | Q12: 1 | R12: U | S12: U | T12: U | U12: 1 | V12: U | W12: U | X12: U | Y12: U | Z12: U | AA12: U | AB12: 1 | AC12: U | AD12: U | AE12: U | AF12: U | AG12: U | AH12: U | AI12: U | AJ12: =SUM(M12:AG12) -> 7 | AK12: 40
A13: 12 | B13: 2010992015 | C13: URVANSH NAHATA | E13: EC118 | F13: Digital Signal Processing | G13: Theory | H13: ECE | I13: CUIET | J13: 2020 | K13: 4 | L13: ST3 | M13: 1 | N13: 1 | O13: 1 | P13: 1 | Q13: 1 | R13: 2 | S13: U | T13: 2 | U13: 2 | V13: 2 | W13: 2 | X13: 3 | Y13: U | Z13: U | AA13: U | AB13: U | AC13: 1 | AD13: U | AE13: U | AF13: U | AG13: U | AH13: U | AI13: U | AJ13: =SUM(M13:AG13) -> 19 | AK13: 40
A14: 13 | B14: 2010992016 | C14: VARUN | E14: EC118 | F14: Digital Signal Processing | G14: Theory | H14: ECE | I14: CUIET | J14: 2020 | K14: 4 | L14: ST3 | M14: 1 | N14: 1 | O14: 1 | P14: 1 | Q14: 1 | R14: 2 | S14: 2 | T14: 2 | U14: U | V14: 2 | W14: 2 | X14: 5 | Y14: U | Z14: 5 | AA14: 5 | AB14: 5 | AC14: U | AD14: U | AE14: U | AF14: U | AG14: U | AH14: U | AI14: U | AJ14: =SUM(M14:AG14) -> 35 | AK14: 40
A15: 14 | B15: 2010992017 | C15: MRIDUL AGGARWAL | E15: EC118 | F15: Digital Signal Processing | G15: Theory | H15: ECE | I15: CUIET | J15: 2020 | K15: 4 | L15: ST3 | M15: 1 | N15: 1 | O15: 1 | P15: 1 | Q15: 1 | R15: 1 | S15: 2 | T15: U | U15: U | V15: U | W15: 2 | X15: U | Y15: U | Z15: U | AA15: U | AB15: 1 | AC15: U | AD15: U | AE15: U | AF15: U | AG15: U | AH15: U | AI15: U | AJ15: =SUM(M15:AG15) -> 11 | AK15: 40
A16: 15 | B16: 2010992018 | C16: SHAKSHI SINGH | E16: EC118 | F16: Digital Signal Processing | G16: Theory | H16: ECE | I16: CUIET | J16: 2020 | K16: 4 | L16: ST3 | M16: 1 | N16: 1 | O16: 1 | P16: 1 | Q16: 1 | R16: 2 | S16: 2 | T16: 2 | U16: 2 | V16: U | W16: 2 | X16: 1 | Y16: 5 | Z16: U | AA16: U | AB16: U | AC16: 1 | AD16: U | AE16: U | AF16: U | AG16: U | AH16: U | AI16: U | AJ16: =SUM(M16:AG16) -> 22 | AK16: 40
A17: 16 | B17: 2010992163 | C17: TAMANA SIAG | E17: EC118 | F17: Digital Signal Processing | G17: Theory | H17: ECE | I17: CUIET | J17: 2020 | K17: 4 | L17: ST3 | M17: U | N17: U | O17: U | P17: U | Q17: U | R17: U | S17: U | T17: U | U17: U | V17: U | W17: U | X17: U | Y17: U | Z17: U | AA17: U | AB17: U | AC17: U | AD17: U | AE17: U | AF17: U | AG17: U | AH17: U | AI17: U | AJ17: =SUM(M17:AG17) -> 0 | AK17: 40
A18: 17 | B18: 2010992202 | C18: EKAMJOT SINGH MAINGI | E18: EC118 | F18: Digital Signal Processing | G18: Theory | H18: ECE | I18: CUIET | J18: 2020 | K18: 4 | L18: ST3 | M18: 1 | N18: 1 | O18: 1 | P18: 1 | Q18: 1 | R18: 1 | S18: 2 | T18: 2 | U18: 2 | V18: U | W18: 2 | X18: U | Y18: U | Z18: 1 | AA18: U | AB18: U | AC18: 1 | AD18: U | AE18: U | AF18: U | AG18: U | AH18: U | AI18: U | AJ18: =SUM(M18:AG18) -> 16 | AK18: 40
A19: 18 | B19: 2010992203 | C19: Khan | E19: EC118 | F19: Digital Signal Processing | G19: Theory | H19: ECE | I19: CUIET | J19: 2020 | K19: 4 | L19: ST3 | M19: 1 | N19: 1 | O19: 1 | P19: 1 | Q19: 1 | R19: 1 | S19: 1 | T19: U | U19: U | V19: 2 | W19: 2 | X19: U | Y19: U | Z19: U | AA19: U | AB19: U | AC19: 1 | AD19: U | AE19: U | AF19: U | AG19: U | AH19: U | AI19: U | AJ19: =SUM(M19:AG19) -> 12 | AK19: 40

Sheet ETE CO Question Map
A1: Q_Id | B1: Max Marks | C1: ='OBE Details'!$B$20&"_CO1" -> EC118_CO1 | D1: ='OBE Details'!$B$20&"_CO2" -> EC118_CO2 | E1: ='OBE Details'!$B$20&"_CO3" -> EC118_CO3 | F1: ='OBE Details'!$B$20&"_CO4" -> EC118_CO4 | G1: ='OBE Details'!$B$20&"_CO5" -> EC118_CO5 | H1: ='OBE Details'!$B$20&"_CO6" -> EC118_CO6 | I1: Count of Cos
A2: 20EC118-ETE-1a | B2: 1 | C2: TRUE | D2: TRUE | E2: TRUE | F2: FALSE | G2: FALSE | H2: FALSE | I2: =COUNTIF(B2:H2,"TRUE") -> 3
A3: 20EC118-ETE-1b | B3: 1 | C3: TRUE | D3: TRUE | E3: TRUE | F3: FALSE | G3: FALSE | H3: FALSE | I3: =COUNTIF(B3:H3,"TRUE") -> 3
A4: 20EC118-ETE-1c | B4: 1 | C4: TRUE | D4: TRUE | E4: TRUE | F4: FALSE | G4: FALSE | H4: FALSE | I4: =COUNTIF(B4:H4,"TRUE") -> 3
A5: 20EC118-ETE-1d | B5: 1 | C5: TRUE | D5: TRUE | E5: TRUE | F5: FALSE | G5: FALSE | H5: FALSE | I5: =COUNTIF(B5:H5,"TRUE") -> 3
A6: 20EC118-ETE-1e | B6: 1 | C6: TRUE | D6: TRUE | E6: TRUE | F6: FALSE | G6: FALSE | H6: FALSE | I6: =COUNTIF(B6:H6,"TRUE") -> 3
A7: 20EC118-ETE-Q2 | B7: 2 | C7: TRUE | D7: TRUE | E7: FALSE | F7: FALSE | G7: FALSE | H7: FALSE | I7: =COUNTIF(B7:H7,"TRUE") -> 2
A8: 20EC118-ETE-Q3 | B8: 2 | C8: FALSE | D8: TRUE | E8: FALSE | F8: FALSE | G8: FALSE | H8: FALSE | I8: =COUNTIF(B8:H8,"TRUE") -> 1
A9: 20EC118-ETE-Q4 | B9: 2 | C9: TRUE | D9: FALSE | E9: FALSE | F9: FALSE | G9: FALSE | H9: FALSE | I9: =COUNTIF(B9:H9,"TRUE") -> 1
A10: 20EC118-ETE-Q5 | B10: 2 | C10: FALSE | D10: TRUE | E10: FALSE | F10: FALSE | G10: FALSE | H10: FALSE | I10: =COUNTIF(B10:H10,"TRUE") -> 1
A11: 20EC118-ETE-Q6 | B11: 2 | C11: FALSE | D11: TRUE | E11: FALSE | F11: FALSE | G11: FALSE | H11: FALSE | I11: =COUNTIF(B11:H11,"TRUE") -> 1
A12: 20EC118-ETE-Q7 | B12: 2 | C12: TRUE | D12: FALSE | E12: FALSE | F12: FALSE | G12: FALSE | H12: FALSE | I12: =COUNTIF(B12:H12,"TRUE") -> 1
A13: 20EC118-ETE-Q8 | B13: 5 | C13: FALSE | D13: TRUE | E13: FALSE | F13: FALSE | G13: FALSE | H13: FALSE | I13: =COUNTIF(B13:H13,"TRUE") -> 1
... A24: 20EC118-ETE-FA2 | B24: 15 | C24: FALSE | D24: FALSE | E24: FALSE | F24: FALSE | G24: FALSE | H24: FALSE | I24: =COUNTIF(B24:H24,"TRUE") -> 0

Sheet ETE Result
A1: Sr.no | B1: Admission No. (Roll No.) | C1: Name of Student | D1: Division(Section) | E1: Course Code | F1: Course Name | G1: Lecture Type (Theory/Practical) | H1: Program Name | I1: Department Name | J1: Class Name (Batch) | K1: Semester Name | L1: Exam Name (ETE/ST/FA) | M1: {=TRANSPOSE('ETE CO Question Map'!A2:A24)} -> 20EC118-ETE-1a | N1: 20EC118-ETE-1b | O1: 20EC118-ETE-1c | P1: 20EC118-ETE-1d | Q1: 20EC118-ETE-1e | R1: 20EC118-ETE-Q2 | S1: 20EC118-ETE-Q3 | T1: 20EC118-ETE-Q4 | U1: 20EC118-ETE-Q5 | V1: 20EC118-ETE-Q6 | W1: 20EC118-ETE-Q7 | X1: 20EC118-ETE-Q8 | Y1: 20EC118-ETE-Q9 | Z1: 20EC118-ETE-Q10 | AA1: 20EC118-ETE-Q11 | AB1: 20EC118-ETE-Q12 | AC1: 20EC118-ETE-Q13 | AD1: 20EC118-ETE-Q14 | AE1: 20EC118-ETE-Q15 | AF1: 20EC118-ETE-Q16 | AG1: 20EC118-ETE-Assignment | AH1: 20EC118-ETE-FA1 | AI1: 20EC118-ETE-FA2 | AJ1: Total Marks | AK1: max Marks
A2: 1 | B2: 2010990089 | C2: ANSH GARG | E2: EC118 | F2: Digital Signal Processing | G2: Theory | H2: ECE | I2: CUIET | J2: 2020 | K2: 4 | L2: ETE | M2: 1 | N2: 1 | O2: 1 | P2: 1 | Q2: 1 | R2: 2 | S2: 2 | T2: U | U2: U | V2: 2 | W2: 2 | X2: 3 | Y2: U | Z2: 5 | AA2: 5 | AB2: 5 | AC2: U | AD2: U | AE2: U | AF2: 2 | AG2: U | AH2: U | AI2: U | AJ2: =SUM(M2:AI2) -> 33 | AK2: 60
A3: 2 | B3: 2010992002 | C3: PANSY VERMA | E3: EC118 | F3: Digital Signal Processing | G3: Theory | H3: ECE | I3: CUIET | J3: 2020 | K3: 4 | L3: ETE | M3: 1 | N3: 1 | O3: 1 | P3: 1 | Q3: 1 | R3: 2 | S3: 2 | T3: 2 | U3: 2 | V3: U | W3: 2 | X3: 5 | Y3: 5 | Z3: 5 | AA3: 5 | AB3: U | AC3: 5 | AD3: U | AE3: 5 | AF3: 10 | AG3: U | AH3: U | AI3: U | AJ3: =SUM(M3:AI3) -> 55 | AK3: 60
A4: 3 | B4: 2010992004 | C4: UTKARSH BHATT | E4: EC118 | F4: Digital Signal Processing | G4: Theory | H4: ECE | I4: CUIET | J4: 2020 | K4: 4 | L4: ETE | M4: 1 | N4: 1 | O4: 1 | P4: 1 | Q4: 1 | R4: 2 | S4: 2 | T4: U | U4: U | V4: 2 | W4: 2 | X4: 4 | Y4: 5 | Z4: U | AA4: U | AB4: U | AC4: U | AD4: U | AE4: 2 | AF4: U | AG4: U | AH4: U | AI4: U | AJ4: =SUM(M4:AI4) -> 24 | AK4: 60
A5: 4 | B5: 2010992005 | C5: RATANABH SHARMA | E5: EC118 | F5: Digital Signal Processing | G5: Theory | H5: ECE | I5: CUIET | J5: 2020 | K5: 4 | L5: ETE | M5: 1 | N5: 1 | O5: 1 | P5: 1 | Q5: 1 | R5: U | S5: U | T5: U | U5: U | V5: U | W5: U | X5: U | Y5: U | Z5: U | AA5: U | AB5: U | AC5: U | AD5: 1 | AE5: U | AF5: U | AG5: U | AH5: U | AI5: U | AJ5: =SUM(M5:AI5) -> 6 | AK5: 60
A6: 5 | B6: 2010992006 | C6: AYUSH SHARMA | E6: EC118 | F6: Digital Signal Processing | G6: Theory | H6: ECE | I6: CUIET | J6: 2020 | K6: 4 | L6: ETE | M6: 1 | N6: 1 | O6: 1 | P6: 1 | Q6: 1 | R6: 2 | S6: 2 | T6: 2 | U6: 2 | V6: U | W6: U | X6: 5 | Y6: 3 | Z6: U | AA6: U | AB6: U | AC6: 5 | AD6: 2 | AE6: U | AF6: U | AG6: U | AH6: U | AI6: U | AJ6: =SUM(M6:AI6) -> 28 | AK6: 60
A7: 6 | B7: 2010992008 | C7: NAVDEEP SINGH | E7: EC118 | F7: Digital Signal Processing | G7: Theory | H7: ECE | I7: CUIET | J7: 2020 | K7: 4 | L7: ETE | M7: 1 | N7: 1 | O7: 1 | P7: 1 | Q7: 1 | R7: 2 | S7: 2 | T7: 2 | U7: U | V7: 2 | W7: U | X7: 5 | Y7: U | Z7: U | AA7: U | AB7: 5 | AC7: U | AD7: 2 | AE7: U | AF7: U | AG7: U | AH7: U | AI7: U | AJ7: =SUM(M7:AI7) -> 25 | AK7: 60
A8: 7 | B8: 2010992009 | C8: RIYA | E8: EC118 | F8: Digital Signal Processing | G8: Theory | H8: ECE | I8: CUIET | J8: 2020 | K8: 4 | L8: ETE | M8: 1 | N8: 1 | O8: 1 | P8: 1 | Q8: 1 | R8: 2 | S8: 2 | T8: U | U8: 2 | V8: 2 | W8: 2 | X8: 5 | Y8: 5 | Z8: 5 | AA8: 5 | AB8: 5 | AC8: U | AD8: 7 | AE8: 10 | AF8: U | AG8: U | AH8: U | AI8: U | AJ8: =SUM(M8:AI8) -> 57 | AK8: 60
A9: 8 | B9: 2010992010 | C9: RISHABH TANDON | E9: EC118 | F9: Digital Signal Processing | G9: Theory | H9: ECE | I9: CUIET | J9: 2020 | K9: 4 | L9: ETE | M9: 1 | N9: 1 | O9: 1 | P9: 1 | Q9: 1 | R9: 2 | S9: 2 | T9: U | U9: 2 | V9: U | W9: 2 | X9: U | Y9: 4 | Z9: U | AA9: U | AB9: U | AC9: 5 | AD9: U | AE9: U | AF9: 2 | AG9: U | AH9: U | AI9: U | AJ9: =SUM(M9:AI9) -> 24 | AK9: 60
A10: 9 | B10: 2010992011 | C10: HEERENDRA SINGH CHAUHAN | E10: EC118 | F10: Digital Signal Processing | G10: Theory | H10: ECE | I10: CUIET | J10: 2020 | K10: 4 | L10: ETE | M10: 1 | N10: 1 | O10: 1 | P10: 1 | Q10: 1 | R10: 2 | S10: U | T10: 2 | U10: U | V10: 2 | W10: 2 | X10: 3 | Y10: 5 | Z10: 5 | AA10: 5 | AB10: U | AC10: 5 | AD10: U | AE10: U | AF10: 2 | AG10: U | AH10: U | AI10: U | AJ10: =SUM(M10:AI10) -> 38 | AK10: 60
A11: 10 | B11: 2010992012 | C11: AKSHAT | E11: EC118 | F11: Digital Signal Processing | G11: Theory | H11: ECE | I11: CUIET | J11: 2020 | K11: 4 | L11: ETE | M11: 1 | N11: 1 | O11: 1 | P11: 1 | Q11: 1 | R11: 2 | S11: 2 | T11: 2 | U11: U | V11: 2 | W11: U | X11: U | Y11: U | Z11: 3 | AA11: 5 | AB11: 5 | AC11: 5 | AD11: 2 | AE11: U | AF11: U | AG11: U | AH11: U | AI11: U | AJ11: =SUM(M11:AI11) -> 33 | AK11: 60
A12: 11 | B12: 2010992014 | C12: HARSHIT CHAHAL | E12: EC118 | F12: Digital Signal Processing | G12: Theory | H12: ECE | I12: CUIET | J12: 2020 | K12: 4 | L12: ETE | M12: 1 | N12: 1 | O12: 1 | P12: 1 | Q12: 1 | R12: 2 | S12: 2 | T12: U | U12: 2 | V12: U | W12: U | X12: U | Y12: U | Z12: U | AA12: U | AB12: U | AC12: U | AD12: U | AE12: U | AF12: 2 | AG12: U | AH12: U | AI12: U | AJ12: =SUM(M12:AI12) -> 13 | AK12: 60
A13: 12 | B13: 2010992015 | C13: URVANSH NAHATA | E13: EC118 | F13: Digital Signal Processing | G13: Theory | H13: ECE | I13: CUIET | J13: 2020 | K13: 4 | L13: ETE | M13: 1 | N13: 1 | O13: 1 | P13: 1 | Q13: 1 | R13: 2 | S13: 2 | T13: U | U13: U | V13: 2 | W13: 2 | X13: U | Y13: 5 | Z13: U | AA13: 2 | AB13: U | AC13: 5 | AD13: U | AE13: 2 | AF13: U | AG13: U | AH13: U | AI13: U | AJ13: =SUM(M13:AI13) -> 27 | AK13: 60
A14: 13 | B14: 2010992016 | C14: VARUN | E14: EC118 | F14: Digital Signal Processing | G14: Theory | H14: ECE | I14: CUIET | J14: 2020 | K14: 4 | L14: ETE | M14: 1 | N14: 1 | O14: 1 | P14: 1 | Q14: 1 | R14: 2 | S14: U | T14: 2 | U14: U | V14: 2 | W14: 2 | X14: 5 | Y14: 5 | Z14: 5 | AA14: U | AB14: 5 | AC14: 5 | AD14: 2 | AE14: U | AF14: 2 | AG14: U | AH14: U | AI14: U | AJ14: =SUM(M14:AI14) -> 42 | AK14: 60
A15: 14 | B15: 2010992017 | C15: MRIDUL AGGARWAL | E15: EC118 | F15: Digital Signal Processing | G15: Theory | H15: ECE | I15: CUIET | J15: 2020 | K15: 4 | L15: ETE | M15: 1 | N15: 1 | O15: 1 | P15: 1 | Q15: 1 | R15: U | S15: 2 | T15: U | U15: 2 | V15: 2 | W15: 2 | X15: 5 | Y15: U | Z15: U | AA15: U | AB15: U | AC15: 5 | AD15: U | AE15: 2 | AF15: U | AG15: U | AH15: U | AI15: U | AJ15: =SUM(M15:AI15) -> 25 | AK15: 60
A16: 15 | B16: 2010992018 | C16: SHAKSHI SINGH | E16: EC118 | F16: Digital Signal Processing | G16: Theory | H16: ECE | I16: CUIET | J16: 2020 | K16: 4 | L16: ETE | M16: 1 | N16: 1 | O16: 1 | P16: 1 | Q16: 1 | R16: 2 | S16: 2 | T16: U | U16: 2 | V16: U | W16: 2 | X16: 5 | Y16: 2 | Z16: 5 | AA16: U | AB16: U | AC16: 5 | AD16: U | AE16: 2 | AF16: U | AG16: U | AH16: U | AI16: U | AJ16: =SUM(M16:AI16) -> 32 | AK16: 60
A17: 16 | B17: 2010992163 | C17: TAMANA SIAG | E17: EC118 | F17: Digital Signal Processing | G17: Theory | H17: ECE | I17: CUIET | J17: 2020 | K17: 4 | L17: ETE | M17: 1 | N17: 1 | O17: 1 | P17: 1 | Q17: 1 | R17: 2 | S17: U | T17: 2 | U17: 2 | V17: U | W17: 2 | X17: 5 | Y17: 5 | Z17: 5 | AA17: 5 | AB17: 5 | AC17: U | AD17: 2 | AE17: U | AF17: 8 | AG17: U | AH17: U | AI17: U | AJ17: =SUM(M17:AI17) -> 48 | AK17: 60
A18: 17 | B18: 2010992202 | C18: EKAMJOT SINGH MAINGI | E18: EC118 | F18: Digital Signal Processing | G18: Theory | H18: ECE | I18: CUIET | J18: 2020 | K18: 4 | L18: ETE | M18: 1 | N18: 1 | O18: 1 | P18: 1 | Q18: 1 | R18: 2 | S18: 2 | T18: U | U18: U | V18: 2 | W18: 2 | X18: 5 | Y18: U | Z18: 5 | AA18: 5 | AB18: 5 | AC18: 5 | AD18: 2 | AE18: U | AF18: 1 | AG18: U | AH18: U | AI18: U | AJ18: =SUM(M18:AI18) -> 41 | AK18: 60
A19: 18 | B19: 2010992203 | C19: Khan | E19: EC118 | F19: Digital Signal Processing | G19: Theory | H19: ECE | I19: CUIET | J19: 2020 | K19: 4 | L19: ETE | M19: 1 | N19: 1 | O19: 1 | P19: 1 | Q19: 1 | R19: 2 | S19: 2 | T19: U | U19: U | V19: 2 | W19: 2 | X19: 5 | Y19: 5 | Z19: 1 | AA19: 5 | AB19: 5 | AC19: U | AD19: 2 | AE19: U | AF19: U | AG19: U | AH19: U | AI19: U | AJ19: =SUM(M19:AI19) -> 36 | AK19: 60

Sheet ST1 Student Marks
A1: {='ST1 Result'!B1:INDEX('ST1 Result'!B:B,COUNTA('ST1 Result'!B:B))} -> Admission No. (Roll No.) | B1: {='ST1 Result'!M1:INDEX('ST1 Result'!M:M,COUNTA('ST1 Result'!M:M))} -> 20EC118-ST1-1a | C1: {='ST1 Result'!N1:INDEX('ST1 Result'!N:N,COUNTA('ST1 Result'!N:N))} -> 20EC118-ST1-1b | D1: {='ST1 Result'!O1:INDEX('ST1 Result'!O:O,COUNTA('ST1 Result'!O:O))} -> 20EC118-ST1-1c | E1: {='ST1 Result'!P1:INDEX('ST1 Result'!P:P,COUNTA('ST1 Result'!P:P))} -> 20EC118-ST1-1d | F1: {='ST1 Result'!Q1:INDEX('ST1 Result'!Q:Q,COUNTA('ST1 Result'!Q:Q))} -> 20EC118-ST1-1e | G1: {='ST1 Result'!R1:INDEX('ST1 Result'!R:R,COUNTA('ST1 Result'!R:R))} -> 20EC118-ST1-Q2 | H1: {='ST1 Result'!S1:INDEX('ST1 Result'!S:S,COUNTA('ST1 Result'!S:S))} -> 20EC118-ST1-Q3 | I1: {='ST1 Result'!T1:INDEX('ST1 Result'!T:T,COUNTA('ST1 Result'!T:T))} -> 20EC118-ST1-Q4 | J1: {='ST1 Result'!U1:INDEX('ST1 Result'!U:U,COUNTA('ST1 Result'!U:U))} -> 20EC118-ST1-Q5 | K1: {='ST1 Result'!V1:INDEX('ST1 Result'!V:V,COUNTA('ST1 Result'!V:V))} -> 20EC118-ST1-Q6 | L1: {='ST1 Result'!W1:INDEX('ST1 Result'!W:W,COUNTA('ST1 Result'!W:W))} -> 20EC118-ST1-Q7 | M1: {='ST1 Result'!X1:INDEX('ST1 Result'!X:X,COUNTA('ST1 Result'!X:X))} -> 20EC118-ST1-Q8 | N1: {='ST1 Result'!Y1:INDEX('ST1 Result'!Y:Y,COUNTA('ST1 Result'!Y:Y))} -> 20EC118-ST1-Q9 | O1: {='ST1 Result'!Z1:INDEX('ST1 Result'!Z:Z,COUNTA('ST1 Result'!Z:Z))} -> 20EC118-ST1-Q10 | P1: {='ST1 Result'!AA1:INDEX('ST1 Result'!AA:AA,COUNTA('ST1 Result'!AA:AA))} -> 20EC118-ST1-Q11 | Q1: {='ST1 Result'!AB1:INDEX('ST1 Result'!AB:AB,COUNTA('ST1 Result'!AB:AB))} -> 20EC118-ST1-Q12 | R1: {='ST1 Result'!AC1:INDEX('ST1 Result'!AC:AC,COUNTA('ST1 Result'!AC:AC))} -> 20EC118-ST1-Q13 | S1: {='ST1 Result'!AD1:INDEX('ST1 Result'!AD:AD,COUNTA('ST1 Result'!AD:AD))} -> 20EC118-ST1-Q14 | T1: {='ST1 Result'!AE1:INDEX('ST1 Result'!AE:AE,COUNTA('ST1 Result'!AE:AE))} -> 20EC118-ST1-Q15 | U1: {='ST1 Result'!AF1:INDEX('ST1 Result'!AF:AF,COUNTA('ST1 Result'!AF:AF))} -> 20EC118-ST1-Q16 | V1: {='ST1 Result'!AG1:INDEX('ST1 Result'!AG:AG,COUNTA('ST1 Result'!AG:AG))} -> 20EC118-ST1-Assignment | W1: {='ST1 Result'!AH1:INDEX('ST1 Result'!AH:AH,COUNTA('ST1 Result'!AH:AH))} -> 20EC118-ST1-FA1 | X1: {='ST1 Result'!AI1:INDEX('ST1 Result'!AI:AI,COUNTA('ST1 Result'!AI:AI))} -> 20EC118-ST1-FA2
A2: 2010990089 | B2: 1 | C2: 1 | D2: 1 | E2: 1 | F2: 1 | G2: 2 | H2: 2 | I2: 2 | J2: 2 | K2: 2 | L2: U | M2: 1 | N2: U | O2: 5 | P2: 5 | Q2: 1 | R2: U | S2: U | T2: U | U2: U | V2: 7 | W2: U | X2: U
A3: 2010992002 | B3: 1 | C3: 1 | D3: 1 | E3: 1 | F3: 1 | G3: 2 | H3: 2 | I3: 2 | J3: 2 | K3: 2 | L3: U | M3: 5 | N3: U | O3: 5 | P3: 5 | Q3: 8 | R3: U | S3: U | T3: U | U3: U | V3: 10 | W3: U | X3: U
A4: 2010992004 | B4: 1 | C4: 1 | D4: 1 | E4: 1 | F4: 1 | G4: 2 | H4: U | I4: 2 | J4: 2 | K4: 2 | L4: 2 | M4: U | N4: 4 | O4: 5 | P4: 2 | Q4: U | R4: 1 | S4: U | T4: U | U4: U | V4: 5 | W4: U | X4: U
A5: 2010992005 | B5: 1 | C5: 1 | D5: 1 | E5: 1 | F5: 1 | G5: 2 | H5: 2 | I5: U | J5: 2 | K5: 2 | L5: 2 | M5: 4 | N5: U | O5: U | P5: U | Q5: 1 | R5: U | S5: U | T5: U | U5: U | V5: 7 | W5: U | X5: U
A6: 2010992006 | B6: 1 | C6: 1 | D6: 1 | E6: 1 | F6: 1 | G6: 2 | H6: 2 | I6: 2 | J6: 2 | K6: 2 | L6: U | M6: 4 | N6: 1 | O6: 5 | P6: U | Q6: U | R6: 1 | S6: U | T6: U | U6: U | V6: 5 | W6: U | X6: U
A7: 2010992008 | B7: 1 | C7: 1 | D7: 1 | E7: 1 | F7: 1 | G7: U | H7: 2 | I7: 2 | J7: 2 | K7: 2 | L7: 2 | M7: 1 | N7: 4 | O7: U | P7: 5 | Q7: 1 | R7: U | S7: U | T7: U | U7: U | V7: U | W7: U | X7: U
A8: 2010992009 | B8: 1 | C8: 1 | D8: 1 | E8: 1 | F8: 1 | G8: 2 | H8: 2 | I8: 2 | J8: 2 | K8: U | L8: 2 | M8: 5 | N8: U | O8: 5 | P8: 5 | Q8: 2 | R8: U | S8: U | T8: U | U8: U | V8: 10 | W8: U | X8: U
A9: 2010992010 | B9: 1 | C9: 1 | D9: 1 | E9: 1 | F9: 1 | G9: 2 | H9: 2 | I9: 2 | J9: U | K9: 2 | L9: 2 | M9: U | N9: 4 | O9: 5 | P9: 4 | Q9: 1 | R9: U | S9: U | T9: U | U9: U | V9: 7 | W9: U | X9: U
A10: 2010992011 | B10: 1 | C10: 1 | D10: 1 | E10: 1 | F10: 1 | G10: U | H10: 2 | I10: 2 | J10: 2 | K10: 2 | L10: 2 | M10: 4 | N10: U | O10: U | P10: 4 | Q10: U | R10: 1 | S10: U | T10: U | U10: U | V10: 5 | W10: U | X10: U
A11: 2010992012 | B11: 1 | C11: 1 | D11: 1 | E11: 1 | F11: 1 | G11: U | H11: 2 | I11: 2 | J11: 2 | K11: 2 | L11: 2 | M11: 5 | N11: 5 | O11: U | P11: 5 | Q11: 2 | R11: U | S11: U | T11: U | U11: U | V11: 10 | W11: U | X11: U
A12: 2010992014 | B12: 1 | C12: 1 | D12: 1 | E12: 1 | F12: 1 | G12: 2 | H12: 2 | I12: 2 | J12: 2 | K12: U | L12: 2 | M12: 5 | N12: 5 | O12: U | P12: 5 | Q12: 6 | R12: U | S12: U | T12: U | U12: U | V12: U | W12: U | X12: U
A13: 2010992015 | B13: 1 | C13: 1 | D13: 1 | E13: 1 | F13: 1 | G13: 2 | H13: 2 | I13: U | J13: 2 | K13: 2 | L13: 2 | M13: U | N13: 4 | O13: U | P13: 1 | Q13: 1 | R13: U | S13: U | T13: U | U13: U | V13: U | W13: U | X13: U
A14: 2010992016 | B14: 1 | C14: 1 | D14: 1 | E14: 1 | F14: 1 | G14: 2 | H14: 2 | I14: 2 | J14: 2 | K14: 2 | L14: U | M14: 4 | N14: 5 | O14: U | P14: 3 | Q14: U | R14: 1 | S14: U | T14: U | U14: U | V14: 10 | W14: U | X14: U
A15: 2010992017 | B15: 1 | C15: 1 | D15: 1 | E15: 1 | F15: 1 | G15: 2 | H15: 2 | I15: 2 | J15: 2 | K15: U | L15: 2 | M15: U | N15: 1 | O15: U | P15: 5 | Q15: U | R15: 1 | S15: U | T15: U | U15: U | V15: 5 | W15: U | X15: U
A16: 2010992018 | B16: 1 | C16: 1 | D16: 1 | E16: 1 | F16: 1 | G16: U | H16: 2 | I16: 2 | J16: 2 | K16: 2 | L16: 2 | M16: 2 | N16: 5 | O16: 5 | P16: U | Q16: 1 | R16: U | S16: U | T16: U | U16: U | V16: 5 | W16: U | X16: U
A17: 2010992163 | B17: 1 | C17: 1 | D17: 1 | E17: 1 | F17: 1 | G17: 2 | H17: U | I17: 2 | J17: 2 | K17: 2 | L17: 2 | M17: 5 | N17: 5 | O17: U | P17: 5 | Q17: 1 | R17: U | S17: U | T17: U | U17: U | V17: 10 | W17: U | X17: U
A18: 2010992202 | B18: 1 | C18: 1 | D18: 1 | E18: 1 | F18: 1 | G18: 2 | H18: 2 | I18: 2 | J18: 2 | K18: U | L18: 2 | M18: U | N18: 2 | O18: U | P18: U | Q18: 1 | R18: U | S18: U | T18: U | U18: U | V18: 5 | W18: U | X18: U
A19: 2010992203 | B19: 1 | C19: 1 | D19: 1 | E19: 1 | F19: 1 | G19: 2 | H19: 2 | I19: 2 | J19: 2 | K19: U | L19: 2 | M19: 4 | N19: 2 | O19: 5 | P19: U | Q19: U | R19: 1 | S19: U | T19: U | U19: U | V19: 7 | W19: U | X19: U

Sheet ST1 Question Map
A1: {='ST1 Result'!B1:INDEX('ST1 Result'!B:B,COUNTA('ST1 Result'!B:B))} -> Admission No. (Roll No.) | B1: {=TRANSPOSE('ST1 CO Question Map'!A2:A24)} -> 20EC118-ST1-1a | C1: 20EC118-ST1-1b | D1: 20EC118-ST1-1c | E1: 20EC118-ST1-1d | F1: 20EC118-ST1-1e | G1: 20EC118-ST1-Q2 | H1: 20EC118-ST1-Q3 | I1: 20EC118-ST1-Q4 | J1: 20EC118-ST1-Q5 | K1: 20EC118-ST1-Q6 | L1: 20EC118-ST1-Q7 | M1: 20EC118-ST1-Q8 | N1: 20EC118-ST1-Q9 | O1: 20EC118-ST1-Q10 | P1: 20EC118-ST1-Q11 | Q1: 20EC118-ST1-Q12 | R1: 20EC118-ST1-Q13 | S1: 20EC118-ST1-Q14 | T1: 20EC118-ST1-Q15 | U1: 20EC118-ST1-Q16 | V1: 20EC118-ST1-Assignment | W1: 20EC118-ST1-FA1 | X1: 20EC118-ST1-FA2
A2: 2010990089 | B2: {=IF(_xlfn.XLOOKUP($A2:INDEX($A:$A,COUNTA($A:$A)),'ST1 Student Marks'!$A$1:INDEX('ST1 Student Marks'!$A:$A,COUNTA('ST1 Student Marks'!$A:$A)),'ST1 Student Marks'!B$1:INDEX('ST1 Student Marks'!B:B,COUNTA('ST1 Student Marks'!B:B)))="U","Unattempted",'ST1 Student Marks'!B1)} -> 20EC118-ST1-1a | C2: {=IF(_xlfn.XLOOKUP($A2:INDEX($A:$A,COUNTA($A:$A)),'ST1 Student Marks'!$A$1:INDEX('ST1 Student Marks'!$A:$A,COUNTA('ST1 Student Marks'!$A:$A)),'ST1 Student Marks'!C$1:INDEX('ST1 Student Marks'!C:C,COUNTA('ST1 Student Marks'!C:C)))="U","Unattempted",'ST1 Student Marks'!C1)} -> 20EC118-ST1-1b | D2: {=IF(_xlfn.XLOOKUP($A2:INDEX($A:$A,COUNTA($A:$A)),'ST1 Student Marks'!$A$1:INDEX('ST1 Student Marks'!$A:$A,COUNTA('ST1 Student Marks'!$A:$A)),'ST1 Student Marks'!D$1:INDEX('ST1 Student Marks'!D:D,COUNTA('ST1 Student Marks'!D:D)))="U","Unattempted",'ST1 Student Marks'!D1)} -> 20EC118-ST1-1c | E2: {=IF(_xlfn.XLOOKUP($A2:INDEX($A:$A,COUNTA($A:$A)),'ST1 Student Marks'!$A$1:INDEX('ST1 Student Marks'!$A:$A,COUNTA('ST1 Student Marks'!$A:$A)),'ST1 Student Marks'!E$1:INDEX('ST1 Student Marks'!E:E,COUNTA('ST1 Student Marks'!E:E)))="U","Unattempted",'ST1 Student Marks'!E1)} -> 20EC118-ST1-1d | F2: {=IF(_xlfn.XLOOKUP($A2:INDEX($A:$A,COUNTA($A:$A)),'ST1 Student Marks'!$A$1:INDEX('ST1 Student Marks'!$A:$A,COUNTA('ST1 Student Marks'!$A:$A)),'ST1 Student Marks'!F$1:INDEX('ST1 Student Marks'!F:F,COUNTA('ST1 Student Marks'!F:F)))="U","Unattempted",'ST1 Student Marks'!F1)} -> 20EC118-ST1-1e | G2: {=IF(_xlfn.XLOOKUP($A2:INDEX($A:$A,COUNTA($A:$A)),'ST1 Student Marks'!$A$1:INDEX('ST1 Student Marks'!$A:$A,COUNTA('ST1 Student Marks'!$A:$A)),'ST1 Student Marks'!G$1:INDEX('ST1 Student Marks'!G:G,COUNTA('ST1 Student Marks'!G:G)))="U","Unattempted",'ST1 Student Marks'!G1)} -> 20EC118-ST1-Q2 | H2: {=IF(_xlfn.XLOOKUP($A2:INDEX($A:$A,COUNTA($A:$A)),'ST1 Student Marks'!$A$1:INDEX('ST1 Student Marks'!$A:$A,COUNTA('ST1 Student Marks'!$A:$A)),'ST1 Student Marks'!H$1:INDEX('ST1 Student Marks'!H:H,COUNTA('ST1 Student Marks'!H:H)))="U","Unattempted",'ST1 Student Marks'!H1)} -> 20EC118-ST1-Q3 | I2: {=IF(_xlfn.XLOOKUP($A2:INDEX($A:$A,COUNTA($A:$A)),'ST1 Student Marks'!$A$1:INDEX('ST1 Student Marks'!$A:$A,COUNTA('ST1 Student Marks'!$A:$A)),'ST1 Student Marks'!I$1:INDEX('ST1 Student Marks'!I:I,COUNTA('ST1 Student Marks'!I:I)))="U","Unattempted",'ST1 Student Marks'!I1)} -> 20EC118-ST1-Q4 | J2: {=IF(_xlfn.XLOOKUP($A2:INDEX($A:$A,COUNTA($A:$A)),'ST1 Student Marks'!$A$1:INDEX('ST1 Student Marks'!$A:$A,COUNTA('ST1 Student Marks'!$A:$A)),'ST1 Student Marks'!J$1:INDEX('ST1 Student Marks'!J:J,COUNTA('ST1 Student Marks'!J:J)))="U","Unattempted",'ST1 Student Marks'!J1)} -> 20EC118-ST1-Q5 | K2: {=IF(_xlfn.XLOOKUP($A2:INDEX($A:$A,COUNTA($A:$A)),'ST1 Student Marks'!$A$1:INDEX('ST1 Student Marks'!$A:$A,COUNTA('ST1 Student Marks'!$A:$A)),'ST1 Student Marks'!K$1:INDEX('ST1 Student Marks'!K:K,COUNTA('ST1 Student Marks'!K:K)))="U","Unattempted",'ST1 Student Marks'!K1)} -> 20EC118-ST1-Q6 | L2: {=IF(_xlfn.XLOOKUP($A2:INDEX($A:$A,COUNTA($A:$A)),'ST1 Student Marks'!$A$1:INDEX('ST1 Student Marks'!$A:$A,COUNTA('ST1 Student Marks'!$A:$A)),'ST1 Student Marks'!L$1:INDEX('ST1 Student Marks'!L:L,COUNTA('ST1 Student Marks'!L:L)))="U","Unattempted",'ST1 Student Marks'!L1)} -> Unattempted | M2: {=IF(_xlfn.XLOOKUP($A2:INDEX($A:$A,COUNTA($A:$A)),'ST1 Student Marks'!$A$1:INDEX('ST1 Student Marks'!$A:$A,COUNTA('ST1 Student Marks'!$A:$A)),'ST1 Student Marks'!M$1:INDEX('ST1 Student Marks'!M:M,COUNTA('ST1 Student Marks'!M:M)))="U","Unattempted",'ST1 Student Marks'!M1)} -> 20EC118-ST1-Q8 | N2: {=IF(_xlfn.XLOOKUP($A2:INDEX($A:$A,COUNTA($A:$A)),'ST1 Student Marks'!$A$1:INDEX('ST1 Student Marks'!$A:$A,COUNTA('ST1 Student Marks'!$A:$A)),'ST1 Student Marks'!N$1:INDEX('ST1 Student Marks'!N:N,COUNTA('ST1 Student Marks'!N:N)))="U","Unattempted",'ST1 Student Marks'!N1)} -> Unattempted | O2: {=IF(_xlfn.XLOOKUP($A2:INDEX($A:$A,COUNTA($A:$A)),'ST1 Student Marks'!$A$1:INDEX('ST1 Student Marks'!$A:$A,COUNTA('ST1 Student Marks'!$A:$A)),'ST1 Student Marks'!O$1:INDEX('ST1 Student Marks'!O:O,COUNTA('ST1 Student Marks'!O:O)))="U","Unattempted",'ST1 Student Marks'!O1)} -> 20EC118-ST1-Q10 | P2: {=IF(_xlfn.XLOOKUP($A2:INDEX($A:$A,COUNTA($A:$A)),'ST1 Student Marks'!$A$1:INDEX('ST1 Student Marks'!$A:$A,COUNTA('ST1 Student Marks'!$A:$A)),'ST1 Student Marks'!P$1:INDEX('ST1 Student Marks'!P:P,COUNTA('ST1 Student Marks'!P:P)))="U","Unattempted",'ST1 Student Marks'!P1)} -> 20EC118-ST1-Q11 | Q2: {=IF(_xlfn.XLOOKUP($A2:INDEX($A:$A,COUNTA($A:$A)),'ST1 Student Marks'!$A$1:INDEX('ST1 Student Marks'!$A:$A,COUNTA('ST1 Student Marks'!$A:$A)),'ST1 Student Marks'!Q$1:INDEX('ST1 Student Marks'!Q:Q,COUNTA('ST1 Student Marks'!Q:Q)))="U","Unattempted",'ST1 Student Marks'!Q1)} -> 20EC118-ST1-Q12 | R2: {=IF(_xlfn.XLOOKUP($A2:INDEX($A:$A,COUNTA($A:$A)),'ST1 Student Marks'!$A$1:INDEX('ST1 Student Marks'!$A:$A,COUNTA('ST1 Student Marks'!$A:$A)),'ST1 Student Marks'!R$1:INDEX('ST1 Student Marks'!R:R,COUNTA('ST1 Student Marks'!R:R)))="U","Unattempted",'ST1 Student Marks'!R1)} -> Unattempted | S2: {=IF(_xlfn.XLOOKUP($A2:INDEX($A:$A,COUNTA($A:$A)),'ST1 Student Marks'!$A$1:INDEX('ST1 Student Marks'!$A:$A,COUNTA('ST1 Student Marks'!$A:$A)),'ST1 Student Marks'!S$1:INDEX('ST1 Student Marks'!S:S,COUNTA('ST1 Student Marks'!S:S)))="U","Unattempted",'ST1 Student Marks'!S1)} -> Unattempted | T2: {=IF(_xlfn.XLOOKUP($A2:INDEX($A:$A,COUNTA($A:$A)),'ST1 Student Marks'!$A$1:INDEX('ST1 Student Marks'!$A:$A,COUNTA('ST1 Student Marks'!$A:$A)),'ST1 Student Marks'!T$1:INDEX('ST1 Student Marks'!T:T,COUNTA('ST1 Student Marks'!T:T)))="U","Unattempted",'ST1 Student Marks'!T1)} -> Unattempted | U2: {=IF(_xlfn.XLOOKUP($A2:INDEX($A:$A,COUNTA($A:$A)),'ST1 Student Marks'!$A$1:INDEX('ST1 Student Marks'!$A:$A,COUNTA('ST1 Student Marks'!$A:$A)),'ST1 Student Marks'!U$1:INDEX('ST1 Student Marks'!U:U,COUNTA('ST1 Student Marks'!U:U)))="U","Unattempted",'ST1 Student Marks'!U1)} -> Unattempted | V2: {=IF(_xlfn.XLOOKUP($A2:INDEX($A:$A,COUNTA($A:$A)),'ST1 Student Marks'!$A$1:INDEX('ST1 Student Marks'!$A:$A,COUNTA('ST1 Student Marks'!$A:$A)),'ST1 Student Marks'!V$1:INDEX('ST1 Student Marks'!V:V,COUNTA('ST1 Student Marks'!V:V)))="U","Unattempted",'ST1 Student Marks'!V1)} -> 20EC118-ST1-Assignment | W2: {=IF(_xlfn.XLOOKUP($A2:INDEX($A:$A,COUNTA($A:$A)),'ST1 Student Marks'!$A$1:INDEX('ST1 Student Marks'!$A:$A,COUNTA('ST1 Student Marks'!$A:$A)),'ST1 Student Marks'!W$1:INDEX('ST1 Student Marks'!W:W,COUNTA('ST1 Student Marks'!W:W)))="U","Unattempted",'ST1 Student Marks'!W1)} -> Unattempted | X2: {=IF(_xlfn.XLOOKUP($A2:INDEX($A:$A,COUNTA($A:$A)),'ST1 Student Marks'!$A$1:INDEX('ST1 Student Marks'!$A:$A,COUNTA('ST1 Student Marks'!$A:$A)),'ST1 Student Marks'!X$1:INDEX('ST1 Student Marks'!X:X,COUNTA('ST1 Student Marks'!X:X)))="U","Unattempted",'ST1 Student Marks'!X1)} -> Unattempted
A3: 2010992002 | B3: 20EC118-ST1-1a | C3: 20EC118-ST1-1b | D3: 20EC118-ST1-1c | E3: 20EC118-ST1-1d | F3: 20EC118-ST1-1e | G3: 20EC118-ST1-Q2 | H3: 20EC118-ST1-Q3 | I3: 20EC118-ST1-Q4 | J3: 20EC118-ST1-Q5 | K3: 20EC118-ST1-Q6 | L3: Unattempted | M3: 20EC118-ST1-Q8 | N3: Unattempted | O3: 20EC118-ST1-Q10 | P3: 20EC118-ST1-Q11 | Q3: 20EC118-ST1-Q12 | R3: Unattempted | S3: Unattempted | T3: Unattempted | U3: Unattempted | V3: 20EC118-ST1-Assignment | W3: Unattempted | X3: Unattempted
A4: 2010992004 | B4: 20EC118-ST1-1a | C4: 20EC118-ST1-1b | D4: 20EC118-ST1-1c | E4: 20EC118-ST1-1d | F4: 20EC118-ST1-1e | G4: 20EC118-ST1-Q2 | H4: Unattempted | I4: 20EC118-ST1-Q4 | J4: 20EC118-ST1-Q5 | K4: 20EC118-ST1-Q6 | L4: 20EC118-ST1-Q7 | M4: Unattempted | N4: 20EC118-ST1-Q9 | O4: 20EC118-ST1-Q10 | P4: 20EC118-ST1-Q11 | Q4: Unattempted | R4: 20EC118-ST1-Q13 | S4: Unattempted | T4: Unattempted | U4: Unattempted | V4: 20EC118-ST1-Assignment | W4: Unattempted | X4: Unattempted
A5: 2010992005 | B5: 20EC118-ST1-1a | C5: 20EC118-ST1-1b | D5: 20EC118-ST1-1c | E5: 20EC118-ST1-1d | F5: 20EC118-ST1-1e | G5: 20EC118-ST1-Q2 | H5: 20EC118-ST1-Q3 | I5: Unattempted | J5: 20EC118-ST1-Q5 | K5: 20EC118-ST1-Q6 | L5: 20EC118-ST1-Q7 | M5: 20EC118-ST1-Q8 | N5: Unattempted | O5: Unattempted | P5: Unattempted | Q5: 20EC118-ST1-Q12 | R5: Unattempted | S5: Unattempted | T5: Unattempted | U5: Unattempted | V5: 20EC118-ST1-Assignment | W5: Unattempted | X5: Unattempted
A6: 2010992006 | B6: 20EC118-ST1-1a | C6: 20EC118-ST1-1b | D6: 20EC118-ST1-1c | E6: 20EC118-ST1-1d | F6: 20EC118-ST1-1e | G6: 20EC118-ST1-Q2 | H6: 20EC118-ST1-Q3 | I6: 20EC118-ST1-Q4 | J6: 20EC118-ST1-Q5 | K6: 20EC118-ST1-Q6 | L6: Unattempted | M6: 20EC118-ST1-Q8 | N6: 20EC118-ST1-Q9 | O6: 20EC118-ST1-Q10 | P6: Unattempted | Q6: Unattempted | R6: 20EC118-ST1-Q13 | S6: Unattempted | T6: Unattempted | U6: Unattempted | V6: 20EC118-ST1-Assignment | W6: Unattempted | X6: Unattempted
A7: 2010992008 | B7: 20EC118-ST1-1a | C7: 20EC118-ST1-1b | D7: 20EC118-ST1-1c | E7: 20EC118-ST1-1d | F7: 20EC118-ST1-1e | G7: Unattempted | H7: 20EC118-ST1-Q3 | I7: 20EC118-ST1-Q4 | J7: 20EC118-ST1-Q5 | K7: 20EC118-ST1-Q6 | L7: 20EC118-ST1-Q7 | M7: 20EC118-ST1-Q8 | N7: 20EC118-ST1-Q9 | O7: Unattempted | P7: 20EC118-ST1-Q11 | Q7: 20EC118-ST1-Q12 | R7: Unattempted | S7: Unattempted | T7: Unattempted | U7: Unattempted | V7: Unattempted | W7: Unattempted | X7: Unattempted
A8: 2010992009 | B8: 20EC118-ST1-1a | C8: 20EC118-ST1-1b | D8: 20EC118-ST1-1c | E8: 20EC118-ST1-1d | F8: 20EC118-ST1-1e | G8: 20EC118-ST1-Q2 | H8: 20EC118-ST1-Q3 | I8: 20EC118-ST1-Q4 | J8: 20EC118-ST1-Q5 | K8: Unattempted | L8: 20EC118-ST1-Q7 | M8: 20EC118-ST1-Q8 | N8: Unattempted | O8: 20EC118-ST1-Q10 | P8: 20EC118-ST1-Q11 | Q8: 20EC118-ST1-Q12 | R8: Unattempted | S8: Unattempted | T8: Unattempted | U8: Unattempted | V8: 20EC118-ST1-Assignment | W8: Unattempted | X8: Unattempted
A9: 2010992010 | B9: 20EC118-ST1-1a | C9: 20EC118-ST1-1b | D9: 20EC118-ST1-1c | E9: 20EC118-ST1-1d | F9: 20EC118-ST1-1e | G9: 20EC118-ST1-Q2 | H9: 20EC118-ST1-Q3 | I9: 20EC118-ST1-Q4 | J9: Unattempted | K9: 20EC118-ST1-Q6 | L9: 20EC118-ST1-Q7 | M9: Unattempted | N9: 20EC118-ST1-Q9 | O9: 20EC118-ST1-Q10 | P9: 20EC118-ST1-Q11 | Q9: 20EC118-ST1-Q12 | R9: Unattempted | S9: Unattempted | T9: Unattempted | U9: Unattempted | V9: 20EC118-ST1-Assignment | W9: Unattempted | X9: Unattempted
A10: 2010992011 | B10: 20EC118-ST1-1a | C10: 20EC118-ST1-1b | D10: 20EC118-ST1-1c | E10: 20EC118-ST1-1d | F10: 20EC118-ST1-1e | G10: Unattempted | H10: 20EC118-ST1-Q3 | I10: 20EC118-ST1-Q4 | J10: 20EC118-ST1-Q5 | K10: 20EC118-ST1-Q6 | L10: 20EC118-ST1-Q7 | M10: 20EC118-ST1-Q8 | N10: Unattempted | O10: Unattempted | P10: 20EC118-ST1-Q11 | Q10: Unattempted | R10: 20EC118-ST1-Q13 | S10: Unattempted | T10: Unattempted | U10: Unattempted | V10: 20EC118-ST1-Assignment | W10: Unattempted | X10: Unattempted
A11: 2010992012 | B11: 20EC118-ST1-1a | C11: 20EC118-ST1-1b | D11: 20EC118-ST1-1c | E11: 20EC118-ST1-1d | F11: 20EC118-ST1-1e | G11: Unattempted | H11: 20EC118-ST1-Q3 | I11: 20EC118-ST1-Q4 | J11: 20EC118-ST1-Q5 | K11: 20EC118-ST1-Q6 | L11: 20EC118-ST1-Q7 | M11: 20EC118-ST1-Q8 | N11: 20EC118-ST1-Q9 | O11: Unattempted | P11: 20EC118-ST1-Q11 | Q11: 20EC118-ST1-Q12 | R11: Unattempted | S11: Unattempted | T11: Unattempted | U11: Unattempted | V11: 20EC118-ST1-Assignment | W11: Unattempted | X11: Unattempted
A12: 2010992014 | B12: 20EC118-ST1-1a | C12: 20EC118-ST1-1b | D12: 20EC118-ST1-1c | E12: 20EC118-ST1-1d | F12: 20EC118-ST1-1e | G12: 20EC118-ST1-Q2 | H12: 20EC118-ST1-Q3 | I12: 20EC118-ST1-Q4 | J12: 20EC118-ST1-Q5 | K12: Unattempted | L12: 20EC118-ST1-Q7 | M12: 20EC118-ST1-Q8 | N12: 20EC118-ST1-Q9 | O12: Unattempted | P12: 20EC118-ST1-Q11 | Q12: 20EC118-ST1-Q12 | R12: Unattempted | S12: Unattempted | T12: Unattempted | U12: Unattempted | V12: Unattempted | W12: Unattempted | X12: Unattempted
A13: 2010992015 | B13: 20EC118-ST1-1a | C13: 20EC118-ST1-1b | D13: 20EC118-ST1-1c | E13: 20EC118-ST1-1d | F13: 20EC118-ST1-1e | G13: 20EC118-ST1-Q2 | H13: 20EC118-ST1-Q3 | I13: Unattempted | J13: 20EC118-ST1-Q5 | K13: 20EC118-ST1-Q6 | L13: 20EC118-ST1-Q7 | M13: Unattempted | N13: 20EC118-ST1-Q9 | O13: Unattempted | P13: 20EC118-ST1-Q11 | Q13: 20EC118-ST1-Q12 | R13: Unattempted | S13: Unattempted | T13: Unattempted | U13: Unattempted | V13: Unattempted | W13: Unattempted | X13: Unattempted
A14: 2010992016 | B14: 20EC118-ST1-1a | C14: 20EC118-ST1-1b | D14: 20EC118-ST1-1c | E14: 20EC118-ST1-1d | F14: 20EC118-ST1-1e | G14: 20EC118-ST1-Q2 | H14: 20EC118-ST1-Q3 | I14: 20EC118-ST1-Q4 | J14: 20EC118-ST1-Q5 | K14: 20EC118-ST1-Q6 | L14: Unattempted | M14: 20EC118-ST1-Q8 | N14: 20EC118-ST1-Q9 | O14: Unattempted | P14: 20EC118-ST1-Q11 | Q14: Unattempted | R14: 20EC118-ST1-Q13 | S14: Unattempted | T14: Unattempted | U14: Unattempted | V14: 20EC118-ST1-Assignment | W14: Unattempted | X14: Unattempted
