Workbook

Sheet OBE Data
A1: {='[1]OBE Details'!$A$1:$B$15} -> CO Score | B1: Percentage of Co attained
A2: Attained 3 | B2: 60
A3: Attained 2 | B3: 60
A4: Attained 1 | B4: 60
A5: Threshold | B5: 60
A6: 0 | B6: 0
A7: 0 | B7: 0
A8: Types | B8: Weightages
A9: Internal (Avg of ST1,ST2,ST3) | B9: 0.4
A10: External(ETE) | B10: 0.6
A11: 0 | B11: 0
A12: CO Score | B12: Perecntage of students attaining Target
A13: 3 | B13: 0.8
A14: 2 | B14: 0.7
A15: 1 | B15: 0.6

Sheet ST1 Questions
A1: {='[1]ST1 Question Map'!$A$1:$H$21} -> Q_Id | B1: Max Marks | C1: CO1 | D1: CO2 | E1: CO3 | F1: CO4 | G1: CO5 | H1: CO6
A2: 1a | B2: 0 | C2: FALSE | D2: FALSE | E2: FALSE | F2: FALSE | G2: FALSE | H2: FALSE
A3: 1b | B3: 0 | C3: FALSE | D3: FALSE | E3: FALSE | F3: FALSE | G3: FALSE | H3: FALSE
A4: 1c | B4: 0 | C4: FALSE | D4: FALSE | E4: FALSE | F4: FALSE | G4: FALSE | H4: FALSE
A5: 1d | B5: 0 | C5: FALSE | D5: FALSE | E5: FALSE | F5: FALSE | G5: FALSE | H5: FALSE
A6: 1e | B6: 0 | C6: FALSE | D6: FALSE | E6: FALSE | F6: FALSE | G6: FALSE | H6: FALSE
A7: Q2 | B7: 2 | C7: TRUE | D7: FALSE | E7: TRUE | F7: FALSE | G7: FALSE | H7: FALSE
A8: Q3 | B8: 2 | C8: TRUE | D8: FALSE | E8: FALSE | F8: FALSE | G8: FALSE | H8: FALSE
A9: Q4 | B9: 2 | C9: TRUE | D9: TRUE | E9: FALSE | F9: TRUE | G9: FALSE | H9: FALSE
A10: Q5 | B10: 2 | C10: TRUE | D10: TRUE | E10: FALSE | F10: FALSE | G10: TRUE | H10: FALSE
A11: Q6 | B11: 2 | C11: TRUE | D11: TRUE | E11: FALSE | F11: FALSE | G11: FALSE | H11: FALSE
A12: Q7 | B12: 0 | C12: FALSE | D12: FALSE | E12: FALSE | F12: FALSE | G12: FALSE | H12: FALSE
A13: Q8 | B13: 5 | C13: TRUE | D13: TRUE | E13: FALSE | F13: FALSE | G13: FALSE | H13: FALSE
... A21: Q16 | B21: 0 | C21: FALSE | D21: FALSE | E21: TRUE | F21: FALSE | G21: FALSE | H21: TRUE

Sheet ST1 Result
A1: {=INDEX('[1]ST1 Result'!$A:$AK, 1, 1):INDEX('[1]ST1 Result'!$AK:$AK,COUNTA('[1]ST1 Result'!$AK:$AK))} -> Sr.no | B1: Admission No. (Roll No.) | C1: Name of Student | D1: Division(Section) | E1: Course Code | F1: Course Name | G1: Lecture Type (Theory/Practical) | H1: Program Name | I1: Department Name | J1: Class Name (Batch) | K1: Semester Name | L1: Exam Name (ETE/ST/FA) | M1: 1a | N1: 1b | O1: 1c | P1: 1d | Q1: 1e | R1: Q2 | S1: Q3 | T1: Q4 | U1: Q5 | V1: Q6 | W1: Q7 | X1: Q8 | Y1: Q9 | Z1: Q10 | AA1: Q11 | AB1: Q12 | AC1: Q13 | AD1: Q14 | AE1: Q15 | AF1: Q16 | AG1: Assignment | AH1: FA1 | AI1: FA2 | AJ1: Total Marks | AK1: max Marks
A2: 1 | B2: 2010990089 | C2: ANSH GARG | D2: 0 | E2: EC112 | F2: Network Analysis and Synthesis | G2: Theory | H2: B.E | I2: ECE | J2: 2020 | K2: 3 | L2: ST1 | M2: U | N2: U | O2: U | P2: U | Q2: U | R2: 0 | S2: 0 | T2: 1 | U2: U | V2: U | W2: U | X2: 2 | Y2: 2 | Z2: 1 | AA2: 4 | AB2: U | AC2: U | AD2: 4 | AE2: U | AF2: U | AG2: 7 | AH2: U | AI2: U | AJ2: 21 | AK2: 50
A3: 2 | B3: 2010992002 | C3: PANSY VERMA | D3: 0 | E3: EC112 | F3: Network Analysis and Synthesis | G3: Theory | H3: B.E | I3: ECE | J3: 2020 | K3: 3 | L3: ST1 | M3: U | N3: U | O3: U | P3: U | Q3: U | R3: 2 | S3: 2 | T3: 2 | U3: U | V3: U | W3: U | X3: 5 | Y3: 5 | Z3: 4 | AA3: 4 | AB3: U | AC3: U | AD3: 10 | AE3: U | AF3: U | AG3: 10 | AH3: U | AI3: U | AJ3: 44 | AK3: 50
A4: 3 | B4: 2010992004 | C4: UTKARSH BHATT | D4: 0 | E4: EC112 | F4: Network Analysis and Synthesis | G4: Theory | H4: B.E | I4: ECE | J4: 2020 | K4: 3 | L4: ST1 | M4: U | N4: U | O4: U | P4: U | Q4: U | R4: 2 | S4: 2 | T4: 1 | U4: 2 | V4: 1 | W4: U | X4: 3 | Y4: 3 | Z4: 4 | AA4: 3 | AB4: U | AC4: U | AD4: 7 | AE4: U | AF4: U | AG4: 10 | AH4: U | AI4: U | AJ4: 38 | AK4: 50
A5: 4 | B5: 2010992005 | C5: RATANABH SHARMA | D5: 0 | E5: EC112 | F5: Network Analysis and Synthesis | G5: Theory | H5: B.E | I5: ECE | J5: 2020 | K5: 3 | L5: ST1 | M5: U | N5: U | O5: U | P5: U | Q5: U | R5: 2 | S5: 1 | T5: 1 | U5: U | V5: U | W5: U | X5: 3 | Y5: 3 | Z5: 4 | AA5: 3 | AB5: U | AC5: U | AD5: 8 | AE5: U | AF5: U | AG5: 10 | AH5: U | AI5: U | AJ5: 35 | AK5: 50
A6: 5 | B6: 2010992006 | C6: AYUSH SHARMA | D6: 0 | E6: EC112 | F6: Network Analysis and Synthesis | G6: Theory | H6: B.E | I6: ECE | J6: 2020 | K6: 3 | L6: ST1 | M6: U | N6: U | O6: U | P6: U | Q6: U | R6: 1 | S6: 2 | T6: 2 | U6: 2 | V6: 1 | W6: U | X6: 3 | Y6: 4 | Z6: 3 | AA6: 3 | AB6: U | AC6: U | AD6: 7 | AE6: U | AF6: U | AG6: 7 | AH6: U | AI6: U | AJ6: 35 | AK6: 50
A7: 6 | B7: 2010992008 | C7: NAVDEEP SINGH | D7: 0 | E7: EC112 | F7: Network Analysis and Synthesis | G7: Theory | H7: B.E | I7: ECE | J7: 2020 | K7: 3 | L7: ST1 | M7: U | N7: U | O7: U | P7: U | Q7: U | R7: 1 | S7: 1 | T7: 2 | U7: 2 | V7: 1 | W7: U | X7: 4 | Y7: 4 | Z7: 3 | AA7: 4 | AB7: U | AC7: U | AD7: 7 | AE7: U | AF7: U | AG7: 9 | AH7: U | AI7: U | AJ7: 38 | AK7: 50
A8: 7 | B8: 2010992009 | C8: RIYA | D8: 0 | E8: EC112 | F8: Network Analysis and Synthesis | G8: Theory | H8: B.E | I8: ECE | J8: 2020 | K8: 3 | L8: ST1 | M8: U | N8: U | O8: U | P8: U | Q8: U | R8: 2 | S8: 1 | T8: 2 | U8: 1 | V8: 1 | W8: U | X8: 3 | Y8: 4 | Z8: 3 | AA8: 3 | AB8: U | AC8: U | AD8: 8 | AE8: U | AF8: U | AG8: 9 | AH8: U | AI8: U | AJ8: 37 | AK8: 50
A9: 8 | B9: 2010992010 | C9: RISHABH TANDON | D9: 0 | E9: EC112 | F9: Network Analysis and Synthesis | G9: Theory | H9: B.E | I9: ECE | J9: 2020 | K9: 3 | L9: ST1 | M9: U | N9: U | O9: U | P9: U | Q9: U | R9: 1 | S9: 1 | T9: 2 | U9: 1 | V9: 1 | W9: U | X9: 4 | Y9: 4 | Z9: 3 | AA9: 4 | AB9: U | AC9: U | AD9: 8 | AE9: U | AF9: U | AG9: 9 | AH9: U | AI9: U | AJ9: 38 | AK9: 50
A10: 9 | B10: 2010992011 | C10: HEERENDRA SINGH CHAUHAN | D10: 0 | E10: EC112 | F10: Network Analysis and Synthesis | G10: Theory | H10: B.E | I10: ECE | J10: 2020 | K10: 3 | L10: ST1 | M10: U | N10: U | O10: U | P10: U | Q10: U | R10: 1 | S10: 1 | T10: 2 | U10: 1 | V10: 1 | W10: U | X10: 4 | Y10: 3 | Z10: 3 | AA10: 4 | AB10: U | AC10: U | AD10: 8 | AE10: U | AF10: U | AG10: 10 | AH10: U | AI10: U | AJ10: 38 | AK10: 50
A11: 10 | B11: 2010992012 | C11: AKSHAT | D11: 0 | E11: EC112 | F11: Network Analysis and Synthesis | G11: Theory | H11: B.E | I11: ECE | J11: 2020 | K11: 3 | L11: ST1 | M11: U | N11: U | O11: U | P11: U | Q11: U | R11: 1 | S11: 1 | T11: 2 | U11: 1 | V11: 1 | W11: U | X11: 4 | Y11: 3 | Z11: 3 | AA11: 4 | AB11: U | AC11: U | AD11: 6 | AE11: U | AF11: U | AG11: 10 | AH11: U | AI11: U | AJ11: 36 | AK11: 50
A12: 11 | B12: 2010992014 | C12: HARSHIT CHAHAL | D12: 0 | E12: EC112 | F12: Network Analysis and Synthesis | G12: Theory | H12: B.E | I12: ECE | J12: 2020 | K12: 3 | L12: ST1 | M12: U | N12: U | O12: U | P12: U | Q12: U | R12: 1 | S12: 1 | T12: 2 | U12: 1 | V12: 1 | W12: U | X12: 4 | Y12: 4 | Z12: 3 | AA12: 4 | AB12: U | AC12: U | AD12: 8 | AE12: U | AF12: U | AG12: 7 | AH12: U | AI12: U | AJ12: 36 | AK12: 50
A13: 12 | B13: 2010992015 | C13: URVANSH NAHATA | D13: 0 | E13: EC112 | F13: Network Analysis and Synthesis | G13: Theory | H13: B.E | I13: ECE | J13: 2020 | K13: 3 | L13: ST1 | M13: U | N13: U | O13: U | P13: U | Q13: U | R13: 1 | S13: 1 | T13: 2 | U13: 1 | V13: 1 | W13: U | X13: U | Y13: 4 | Z13: 3 | AA13: 3 | AB13: U | AC13: U | AD13: 7 | AE13: U | AF13: U | AG13: 9 | AH13: U | AI13: U | AJ13: 32 | AK13: 50
A14: 13 | B14: 2010992016 | C14: VARUN | D14: 0 | E14: EC112 | F14: Network Analysis and Synthesis | G14: Theory | H14: B.E | I14: ECE | J14: 2020 | K14: 3 | L14: ST1 | M14: U | N14: U | O14: U | P14: U | Q14: U | R14: 1 | S14: 1 | T14: 1 | U14: 1 | V14: 1 | W14: U | X14: 4 | Y14: 2 | Z14: 3 | AA14: 2 | AB14: U | AC14: U | AD14: 5 | AE14: U | AF14: U | AG14: 9 | AH14: U | AI14: U | AJ14: 30 | AK14: 50
A15: 14 | B15: 2010992017 | C15: MRIDUL AGGARWAL | D15: 0 | E15: EC112 | F15: Network Analysis and Synthesis | G15: Theory | H15: B.E | I15: ECE | J15: 2020 | K15: 3 | L15: ST1 | M15: U | N15: U | O15: U | P15: U | Q15: U | R15: 1 | S15: 2 | T15: 2 | U15: 2 | V15: 1 | W15: U | X15: 4 | Y15: 4 | Z15: 3 | AA15: 4 | AB15: U | AC15: U | AD15: 8 | AE15: U | AF15: U | AG15: 7 | AH15: U | AI15: U | AJ15: 38 | AK15: 50
A16: 15 | B16: 2010992018 | C16: SHAKSHI SINGH | D16: 0 | E16: EC112 | F16: Network Analysis and Synthesis | G16: Theory | H16: B.E | I16: ECE | J16: 2020 | K16: 3 | L16: ST1 | M16: U | N16: U | O16: U | P16: U | Q16: U | R16: 1 | S16: 1 | T16: 1 | U16: 1 | V16: 1 | W16: U | X16: 2 | Y16: 4 | Z16: 4 | AA16: 3 | AB16: U | AC16: U | AD16: 8 | AE16: U | AF16: U | AG16: 7 | AH16: U | AI16: U | AJ16: 33 | AK16: 50
A17: 16 | B17: 2010992019 | C17: KHAN MUBASHIR RASOOL | D17: 0 | E17: EC112 | F17: Network Analysis and Synthesis | G17: Theory | H17: B.E | I17: ECE | J17: 2020 | K17: 3 | L17: ST1 | M17: U | N17: U | O17: U | P17: U | Q17: U | R17: 1 | S17: 1 | T17: 2 | U17: 1 | V17: 1 | W17: U | X17: 2 | Y17: 3 | Z17: 2 | AA17: 4 | AB17: U | AC17: U | AD17: 5 | AE17: U | AF17: U | AG17: 9 | AH17: U | AI17: U | AJ17: 31 | AK17: 50
A18: 17 | B18: 2010992163 | C18: TAMANA SIAG | D18: 0 | E18: EC112 | F18: Network Analysis and Synthesis | G18: Theory | H18: B.E | I18: ECE | J18: 2020 | K18: 3 | L18: ST1 | M18: U | N18: U | O18: U | P18: U | Q18: U | R18: 1 | S18: 1 | T18: 2 | U18: 2 | V18: 1 | W18: U | X18: 4 | Y18: 4 | Z18: 3 | AA18: 4 | AB18: U | AC18: U | AD18: 9 | AE18: U | AF18: U | AG18: 10 | AH18: U | AI18: U | AJ18: 41 | AK18: 50
A19: 18 | B19: 2010992202 | C19: EKAMJOT SINGH MAINGI | D19: 0 | E19: EC112 | F19: Network Analysis and Synthesis | G19: Theory | H19: B.E | I19: ECE | J19: 2020 | K19: 3 | L19: ST1 | M19: U | N19: U | O19: U | P19: U | Q19: U | R19: 1 | S19: 1 | T19: 2 | U19: 2 | V19: 1 | W19: U | X19: 4 | Y19: 4 | Z19: 3 | AA19: 4 | AB19: U | AC19: U | AD19: 8 | AE19: U | AF19: U | AG19: 7 | AH19: U | AI19: U | AJ19: 37 | AK19: 50

Sheet ST1 Student Marks
A1: {=INDEX('ST1 Result'!B:B, 1):INDEX('ST1 Result'!B:B, COUNTA('ST1 Result'!B:B))} -> Admission No. (Roll No.) | B1: {=INDEX('ST1 Result'!M:M, 1):INDEX('ST1 Result'!M:M, COUNTA('ST1 Result'!M:M) )} -> 1a | C1: {=INDEX('ST1 Result'!N:N, 1):INDEX('ST1 Result'!N:N, COUNTA('ST1 Result'!N:N) )} -> 1b | D1: {=INDEX('ST1 Result'!O:O, 1):INDEX('ST1 Result'!O:O, COUNTA('ST1 Result'!O:O) )} -> 1c | E1: {=INDEX('ST1 Result'!P:P, 1):INDEX('ST1 Result'!P:P, COUNTA('ST1 Result'!P:P) )} -> 1d | F1: {=INDEX('ST1 Result'!Q:Q, 1):INDEX('ST1 Result'!Q:Q, COUNTA('ST1 Result'!Q:Q) )} -> 1e | G1: {=INDEX('ST1 Result'!R:R, 1):INDEX('ST1 Result'!R:R, COUNTA('ST1 Result'!R:R) )} -> Q2 | H1: {=INDEX('ST1 Result'!S:S, 1):INDEX('ST1 Result'!S:S, COUNTA('ST1 Result'!S:S) )} -> Q3 | I1: {=INDEX('ST1 Result'!T:T, 1):INDEX('ST1 Result'!T:T, COUNTA('ST1 Result'!T:T) )} -> Q4 | J1: {=INDEX('ST1 Result'!U:U, 1):INDEX('ST1 Result'!U:U, COUNTA('ST1 Result'!U:U) )} -> Q5 | K1: {=INDEX('ST1 Result'!V:V, 1):INDEX('ST1 Result'!V:V, COUNTA('ST1 Result'!V:V) )} -> Q6 | L1: {=INDEX('ST1 Result'!W:W, 1):INDEX('ST1 Result'!W:W, COUNTA('ST1 Result'!W:W) )} -> Q7 | M1: {=INDEX('ST1 Result'!X:X, 1):INDEX('ST1 Result'!X:X, COUNTA('ST1 Result'!X:X) )} -> Q8 | N1: {=INDEX('ST1 Result'!Y:Y, 1):INDEX('ST1 Result'!Y:Y, COUNTA('ST1 Result'!Y:Y) )} -> Q9 | O1: {=INDEX('ST1 Result'!Z:Z, 1):INDEX('ST1 Result'!Z:Z, COUNTA('ST1 Result'!Z:Z) )} -> Q10 | P1: {=INDEX('ST1 Result'!AA:AA, 1):INDEX('ST1 Result'!AA:AA, COUNTA('ST1 Result'!AA:AA) )} -> Q11 | Q1: {=INDEX('ST1 Result'!AB:AB, 1):INDEX('ST1 Result'!AB:AB, COUNTA('ST1 Result'!AB:AB) )} -> Q12 | R1: {=INDEX('ST1 Result'!AC:AC, 1):INDEX('ST1 Result'!AC:AC, COUNTA('ST1 Result'!AC:AC) )} -> Q13 | S1: {=INDEX('ST1 Result'!AD:AD, 1):INDEX('ST1 Result'!AD:AD, COUNTA('ST1 Result'!AD:AD) )} -> Q14 | T1: {=INDEX('ST1 Result'!AE:AE, 1):INDEX('ST1 Result'!AE:AE, COUNTA('ST1 Result'!AE:AE) )} -> Q15 | U1: {=INDEX('ST1 Result'!AF:AF, 1):INDEX('ST1 Result'!AF:AF, COUNTA('ST1 Result'!AF:AF) )} -> Q16
A2: 2010990089 | B2: U | C2: U | D2: U | E2: U | F2: U | G2: 0 | H2: 0 | I2: 1 | J2: U | K2: U | L2: U | M2: 2 | N2: 2 | O2: 1 | P2: 4 | Q2: U | R2: U | S2: 4 | T2: U | U2: U
A3: 2010992002 | B3: U | C3: U | D3: U | E3: U | F3: U | G3: 2 | H3: 2 | I3: 2 | J3: U | K3: U | L3: U | M3: 5 | N3: 5 | O3: 4 | P3: 4 | Q3: U | R3: U | S3: 10 | T3: U | U3: U
A4: 2010992004 | B4: U | C4: U | D4: U | E4: U | F4: U | G4: 2 | H4: 2 | I4: 1 | J4: 2 | K4: 1 | L4: U | M4: 3 | N4: 3 | O4: 4 | P4: 3 | Q4: U | R4: U | S4: 7 | T4: U | U4: U
A5: 2010992005 | B5: U | C5: U | D5: U | E5: U | F5: U | G5: 2 | H5: 1 | I5: 1 | J5: U | K5: U | L5: U | M5: 3 | N5: 3 | O5: 4 | P5: 3 | Q5: U | R5: U | S5: 8 | T5: U | U5: U
A6: 2010992006 | B6: U | C6: U | D6: U | E6: U | F6: U | G6: 1 | H6: 2 | I6: 2 | J6: 2 | K6: 1 | L6: U | M6: 3 | N6: 4 | O6: 3 | P6: 3 | Q6: U | R6: U | S6: 7 | T6: U | U6: U
A7: 2010992008 | B7: U | C7: U | D7: U | E7: U | F7: U | G7: 1 | H7: 1 | I7: 2 | J7: 2 | K7: 1 | L7: U | M7: 4 | N7: 4 | O7: 3 | P7: 4 | Q7: U | R7: U | S7: 7 | T7: U | U7: U
A8: 2010992009 | B8: U | C8: U | D8: U | E8: U | F8: U | G8: 2 | H8: 1 | I8: 2 | J8: 1 | K8: 1 | L8: U | M8: 3 | N8: 4 | O8: 3 | P8: 3 | Q8: U | R8: U | S8: 8 | T8: U | U8: U
A9: 2010992010 | B9: U | C9: U | D9: U | E9: U | F9: U | G9: 1 | H9: 1 | I9: 2 | J9: 1 | K9: 1 | L9: U | M9: 4 | N9: 4 | O9: 3 | P9: 4 | Q9: U | R9: U | S9: 8 | T9: U | U9: U
A10: 2010992011 | B10: U | C10: U | D10: U | E10: U | F10: U | G10: 1 | H10: 1 | I10: 2 | J10: 1 | K10: 1 | L10: U | M10: 4 | N10: 3 | O10: 3 | P10: 4 | Q10: U | R10: U | S10: 8 | T10: U | U10: U
A11: 2010992012 | B11: U | C11: U | D11: U | E11: U | F11: U | G11: 1 | H11: 1 | I11: 2 | J11: 1 | K11: 1 | L11: U | M11: 4 | N11: 3 | O11: 3 | P11: 4 | Q11: U | R11: U | S11: 6 | T11: U | U11: U
A12: 2010992014 | B12: U | C12: U | D12: U | E12: U | F12: U | G12: 1 | H12: 1 | I12: 2 | J12: 1 | K12: 1 | L12: U | M12: 4 | N12: 4 | O12: 3 | P12: 4 | Q12: U | R12: U | S12: 8 | T12: U | U12: U
A13: 2010992015 | B13: U | C13: U | D13: U | E13: U | F13: U | G13: 1 | H13: 1 | I13: 2 | J13: 1 | K13: 1 | L13: U | M13: U | N13: 4 | O13: 3 | P13: 3 | Q13: U | R13: U | S13: 7 | T13: U | U13: U
A14: 2010992016 | B14: U | C14: U | D14: U | E14: U | F14: U | G14: 1 | H14: 1 | I14: 1 | J14: 1 | K14: 1 | L14: U | M14: 4 | N14: 2 | O14: 3 | P14: 2 | Q14: U | R14: U | S14: 5 | T14: U | U14: U
A15: 2010992017 | B15: U | C15: U | D15: U | E15: U | F15: U | G15: 1 | H15: 2 | I15: 2 | J15: 2 | K15: 1 | L15: U | M15: 4 | N15: 4 | O15: 3 | P15: 4 | Q15: U | R15: U | S15: 8 | T15: U | U15: U
A16: 2010992018 | B16: U | C16: U | D16: U | E16: U | F16: U | G16: 1 | H16: 1 | I16: 1 | J16: 1 | K16: 1 | L16: U | M16: 2 | N16: 4 | O16: 4 | P16: 3 | Q16: U | R16: U | S16: 8 | T16: U | U16: U
A17: 2010992019 | B17: U | C17: U | D17: U | E17: U | F17: U | G17: 1 | H17: 1 | I17: 2 | J17: 1 | K17: 1 | L17: U | M17: 2 | N17: 3 | O17: 2 | P17: 4 | Q17: U | R17: U | S17: 5 | T17: U | U17: U
A18: 2010992163 | B18: U | C18: U | D18: U | E18: U | F18: U | G18: 1 | H18: 1 | I18: 2 | J18: 2 | K18: 1 | L18: U | M18: 4 | N18: 4 | O18: 3 | P18: 4 | Q18: U | R18: U | S18: 9 | T18: U | U18: U
A19: 2010992202 | B19: U | C19: U | D19: U | E19: U | F19: U | G19: 1 | H19: 1 | I19: 2 | J19: 2 | K19: 1 | L19: U | M19: 4 | N19: 4 | O19: 3 | P19: 4 | Q19: U | R19: U | S19: 8 | T19: U | U19: U

Sheet ST1 Question Map
A1: {=INDEX('ST1 Result'!B:B, 1):INDEX('ST1 Result'!B:B, COUNTA('ST1 Result'!B:B))} -> Admission No. (Roll No.) | B1: {=TRANSPOSE('ST1 Questions'!A2:A21)} -> 1a | C1: 1b | D1: 1c | E1: 1d | F1: 1e | G1: Q2 | H1: Q3 | I1: Q4 | J1: Q5 | K1: Q6 | L1: Q7 | M1: Q8 | N1: Q9 | O1: Q10 | P1: Q11 | Q1: Q12 | R1: Q13 | S1: Q14 | T1: Q15 | U1: Q16
A2: 2010990089 | B2: {=IF(_xlfn.XLOOKUP($A2:INDEX($A:$A,COUNTA($A:$A)),'ST1 Student Marks'!$A$1:INDEX('ST1 Student Marks'!$A:$A,COUNTA('ST1 Student Marks'!$A:$A)),'ST1 Student Marks'!B$1:INDEX('ST1 Student Marks'!B:B,COUNTA('ST1 Student Marks'!B:B)))="U","Unattempted",'ST1 Student Marks'!B1)} -> Unattempted | C2: {=IF(_xlfn.XLOOKUP($A2:INDEX($A:$A,COUNTA($A:$A)),'ST1 Student Marks'!$A$1:INDEX('ST1 Student Marks'!$A:$A,COUNTA('ST1 Student Marks'!$A:$A)),'ST1 Student Marks'!C$1:INDEX('ST1 Student Marks'!C:C,COUNTA('ST1 Student Marks'!C:C)))="U","Unattempted",'ST1 Student Marks'!C1)} -> Unattempted | D2: {=IF(_xlfn.XLOOKUP($A2:INDEX($A:$A,COUNTA($A:$A)),'ST1 Student Marks'!$A$1:INDEX('ST1 Student Marks'!$A:$A,COUNTA('ST1 Student Marks'!$A:$A)),'ST1 Student Marks'!D$1:INDEX('ST1 Student Marks'!D:D,COUNTA('ST1 Student Marks'!D:D)))="U","Unattempted",'ST1 Student Marks'!D1)} -> Unattempted | E2: {=IF(_xlfn.XLOOKUP($A2:INDEX($A:$A,COUNTA($A:$A)),'ST1 Student Marks'!$A$1:INDEX('ST1 Student Marks'!$A:$A,COUNTA('ST1 Student Marks'!$A:$A)),'ST1 Student Marks'!E$1:INDEX('ST1 Student Marks'!E:E,COUNTA('ST1 Student Marks'!E:E)))="U","Unattempted",'ST1 Student Marks'!E1)} -> Unattempted | F2: {=IF(_xlfn.XLOOKUP($A2:INDEX($A:$A,COUNTA($A:$A)),'ST1 Student Marks'!$A$1:INDEX('ST1 Student Marks'!$A:$A,COUNTA('ST1 Student Marks'!$A:$A)),'ST1 Student Marks'!F$1:INDEX('ST1 Student Marks'!F:F,COUNTA('ST1 Student Marks'!F:F)))="U","Unattempted",'ST1 Student Marks'!F1)} -> Unattempted | G2: {=IF(_xlfn.XLOOKUP($A2:INDEX($A:$A,COUNTA($A:$A)),'ST1 Student Marks'!$A$1:INDEX('ST1 Student Marks'!$A:$A,COUNTA('ST1 Student Marks'!$A:$A)),'ST1 Student Marks'!G$1:INDEX('ST1 Student Marks'!G:G,COUNTA('ST1 Student Marks'!G:G)))="U","Unattempted",'ST1 Student Marks'!G1)} -> Q2 | H2: {=IF(_xlfn.XLOOKUP($A2:INDEX($A:$A,COUNTA($A:$A)),'ST1 Student Marks'!$A$1:INDEX('ST1 Student Marks'!$A:$A,COUNTA('ST1 Student Marks'!$A:$A)),'ST1 Student Marks'!H$1:INDEX('ST1 Student Marks'!H:H,COUNTA('ST1 Student Marks'!H:H)))="U","Unattempted",'ST1 Student Marks'!H1)} -> Q3 | I2: {=IF(_xlfn.XLOOKUP($A2:INDEX($A:$A,COUNTA($A:$A)),'ST1 Student Marks'!$A$1:INDEX('ST1 Student Marks'!$A:$A,COUNTA('ST1 Student Marks'!$A:$A)),'ST1 Student Marks'!I$1:INDEX('ST1 Student Marks'!I:I,COUNTA('ST1 Student Marks'!I:I)))="U","Unattempted",'ST1 Student Marks'!I1)} -> Q4 | J2: {=IF(_xlfn.XLOOKUP($A2:INDEX($A:$A,COUNTA($A:$A)),'ST1 Student Marks'!$A$1:INDEX('ST1 Student Marks'!$A:$A,COUNTA('ST1 Student Marks'!$A:$A)),'ST1 Student Marks'!J$1:INDEX('ST1 Student Marks'!J:J,COUNTA('ST1 Student Marks'!J:J)))="U","Unattempted",'ST1 Student Marks'!J1)} -> Unattempted | K2: {=IF(_xlfn.XLOOKUP($A2:INDEX($A:$A,COUNTA($A:$A)),'ST1 Student Marks'!$A$1:INDEX('ST1 Student Marks'!$A:$A,COUNTA('ST1 Student Marks'!$A:$A)),'ST1 Student Marks'!K$1:INDEX('ST1 Student Marks'!K:K,COUNTA('ST1 Student Marks'!K:K)))="U","Unattempted",'ST1 Student Marks'!K1)} -> Unattempted | L2: {=IF(_xlfn.XLOOKUP($A2:INDEX($A:$A,COUNTA($A:$A)),'ST1 Student Marks'!$A$1:INDEX('ST1 Student Marks'!$A:$A,COUNTA('ST1 Student Marks'!$A:$A)),'ST1 Student Marks'!L$1:INDEX('ST1 Student Marks'!L:L,COUNTA('ST1 Student Marks'!L:L)))="U","Unattempted",'ST1 Student Marks'!L1)} -> Unattempted | M2: {=IF(_xlfn.XLOOKUP($A2:INDEX($A:$A,COUNTA($A:$A)),'ST1 Student Marks'!$A$1:INDEX('ST1 Student Marks'!$A:$A,COUNTA('ST1 Student Marks'!$A:$A)),'ST1 Student Marks'!M$1:INDEX('ST1 Student Marks'!M:M,COUNTA('ST1 Student Marks'!M:M)))="U","Unattempted",'ST1 Student Marks'!M1)} -> Q8 | N2: {=IF(_xlfn.XLOOKUP($A2:INDEX($A:$A,COUNTA($A:$A)),'ST1 Student Marks'!$A$1:INDEX('ST1 Student Marks'!$A:$A,COUNTA('ST1 Student Marks'!$A:$A)),'ST1 Student Marks'!N$1:INDEX('ST1 Student Marks'!N:N,COUNTA('ST1 Student Marks'!N:N)))="U","Unattempted",'ST1 Student Marks'!N1)} -> Q9 | O2: {=IF(_xlfn.XLOOKUP($A2:INDEX($A:$A,COUNTA($A:$A)),'ST1 Student Marks'!$A$1:INDEX('ST1 Student Marks'!$A:$A,COUNTA('ST1 Student Marks'!$A:$A)),'ST1 Student Marks'!O$1:INDEX('ST1 Student Marks'!O:O,COUNTA('ST1 Student Marks'!O:O)))="U","Unattempted",'ST1 Student Marks'!O1)} -> Q10 | P2: {=IF(_xlfn.XLOOKUP($A2:INDEX($A:$A,COUNTA($A:$A)),'ST1 Student Marks'!$A$1:INDEX('ST1 Student Marks'!$A:$A,COUNTA('ST1 Student Marks'!$A:$A)),'ST1 Student Marks'!P$1:INDEX('ST1 Student Marks'!P:P,COUNTA('ST1 Student Marks'!P:P)))="U","Unattempted",'ST1 Student Marks'!P1)} -> Q11 | Q2: {=IF(_xlfn.XLOOKUP($A2:INDEX($A:$A,COUNTA($A:$A)),'ST1 Student Marks'!$A$1:INDEX('ST1 Student Marks'!$A:$A,COUNTA('ST1 Student Marks'!$A:$A)),'ST1 Student Marks'!Q$1:INDEX('ST1 Student Marks'!Q:Q,COUNTA('ST1 Student Marks'!Q:Q)))="U","Unattempted",'ST1 Student Marks'!Q1)} -> Unattempted | R2: {=IF(_xlfn.XLOOKUP($A2:INDEX($A:$A,COUNTA($A:$A)),'ST1 Student Marks'!$A$1:INDEX('ST1 Student Marks'!$A:$A,COUNTA('ST1 Student Marks'!$A:$A)),'ST1 Student Marks'!R$1:INDEX('ST1 Student Marks'!R:R,COUNTA('ST1 Student Marks'!R:R)))="U","Unattempted",'ST1 Student Marks'!R1)} -> Unattempted | S2: {=IF(_xlfn.XLOOKUP($A2:INDEX($A:$A,COUNTA($A:$A)),'ST1 Student Marks'!$A$1:INDEX('ST1 Student Marks'!$A:$A,COUNTA('ST1 Student Marks'!$A:$A)),'ST1 Student Marks'!S$1:INDEX('ST1 Student Marks'!S:S,COUNTA('ST1 Student Marks'!S:S)))="U","Unattempted",'ST1 Student Marks'!S1)} -> Q14 | T2: {=IF(_xlfn.XLOOKUP($A2:INDEX($A:$A,COUNTA($A:$A)),'ST1 Student Marks'!$A$1:INDEX('ST1 Student Marks'!$A:$A,COUNTA('ST1 Student Marks'!$A:$A)),'ST1 Student Marks'!T$1:INDEX('ST1 Student Marks'!T:T,COUNTA('ST1 Student Marks'!T:T)))="U","Unattempted",'ST1 Student Marks'!T1)} -> Unattempted | U2: {=IF(_xlfn.XLOOKUP($A2:INDEX($A:$A,COUNTA($A:$A)),'ST1 Student Marks'!$A$1:INDEX('ST1 Student Marks'!$A:$A,COUNTA('ST1 Student Marks'!$A:$A)),'ST1 Student Marks'!U$1:INDEX('ST1 Student Marks'!U:U,COUNTA('ST1 Student Marks'!U:U)))="U","Unattempted",'ST1 Student Marks'!U1)} -> Unattempted
A3: 2010992002 | B3: Unattempted | C3: Unattempted | D3: Unattempted | E3: Unattempted | F3: Unattempted | G3: Q2 | H3: Q3 | I3: Q4 | J3: Unattempted | K3: Unattempted | L3: Unattempted | M3: Q8 | N3: Q9 | O3: Q10 | P3: Q11 | Q3: Unattempted | R3: Unattempted | S3: Q14 | T3: Unattempted | U3: Unattempted
A4: 2010992004 | B4: Unattempted | C4: Unattempted | D4: Unattempted | E4: Unattempted | F4: Unattempted | G4: Q2 | H4: Q3 | I4: Q4 | J4: Q5 | K4: Q6 | L4: Unattempted | M4: Q8 | N4: Q9 | O4: Q10 | P4: Q11 | Q4: Unattempted | R4: Unattempted | S4: Q14 | T4: Unattempted | U4: Unattempted
A5: 2010992005 | B5: Unattempted | C5: Unattempted | D5: Unattempted | E5: Unattempted | F5: Unattempted | G5: Q2 | H5: Q3 | I5: Q4 | J5: Unattempted | K5: Unattempted | L5: Unattempted | M5: Q8 | N5: Q9 | O5: Q10 | P5: Q11 | Q5: Unattempted | R5: Unattempted | S5: Q14 | T5: Unattempted | U5: Unattempted
A6: 2010992006 | B6: Unattempted | C6: Unattempted | D6: Unattempted | E6: Unattempted | F6: Unattempted | G6: Q2 | H6: Q3 | I6: Q4 | J6: Q5 | K6: Q6 | L6: Unattempted | M6: Q8 | N6: Q9 | O6: Q10 | P6: Q11 | Q6: Unattempted | R6: Unattempted | S6: Q14 | T6: Unattempted | U6: Unattempted
A7: 2010992008 | B7: Unattempted | C7: Unattempted | D7: Unattempted | E7: Unattempted | F7: Unattempted | G7: Q2 | H7: Q3 | I7: Q4 | J7: Q5 | K7: Q6 | L7: Unattempted | M7: Q8 | N7: Q9 | O7: Q10 | P7: Q11 | Q7: Unattempted | R7: Unattempted | S7: Q14 | T7: Unattempted | U7: Unattempted
A8: 2010992009 | B8: Unattempted | C8: Unattempted | D8: Unattempted | E8: Unattempted | F8: Unattempted | G8: Q2 | H8: Q3 | I8: Q4 | J8: Q5 | K8: Q6 | L8: Unattempted | M8: Q8 | N8: Q9 | O8: Q10 | P8: Q11 | Q8: Unattempted | R8: Unattempted | S8: Q14 | T8: Unattempted | U8: Unattempted
A9: 2010992010 | B9: Unattempted | C9: Unattempted | D9: Unattempted | E9: Unattempted | F9: Unattempted | G9: Q2 | H9: Q3 | I9: Q4 | J9: Q5 | K9: Q6 | L9: Unattempted | M9: Q8 | N9: Q9 | O9: Q10 | P9: Q11 | Q9: Unattempted | R9: Unattempted | S9: Q14 | T9: Unattempted | U9: Unattempted
A10: 2010992011 | B10: Unattempted | C10: Unattempted | D10: Unattempted | E10: Unattempted | F10: Unattempted | G10: Q2 | H10: Q3 | I10: Q4 | J10: Q5 | K10: Q6 | L10: Unattempted | M10: Q8 | N10: Q9 | O10: Q10 | P10: Q11 | Q10: Unattempted | R10: Unattempted | S10: Q14 | T10: Unattempted | U10: Unattempted
A11: 2010992012 | B11: Unattempted | C11: Unattempted | D11: Unattempted | E11: Unattempted | F11: Unattempted | G11: Q2 | H11: Q3 | I11: Q4 | J11: Q5 | K11: Q6 | L11: Unattempted | M11: Q8 | N11: Q9 | O11: Q10 | P11: Q11 | Q11: Unattempted | R11: Unattempted | S11: Q14 | T11: Unattempted | U11: Unattempted
A12: 2010992014 | B12: Unattempted | C12: Unattempted | D12: Unattempted | E12: Unattempted | F12: Unattempted | G12: Q2 | H12: Q3 | I12: Q4 | J12: Q5 | K12: Q6 | L12: Unattempted | M12: Q8 | N12: Q9 | O12: Q10 | P12: Q11 | Q12: Unattempted | R12: Unattempted | S12: Q14 | T12: Unattempted | U12: Unattempted
A13: 2010992015 | B13: Unattempted | C13: Unattempted | D13: Unattempted | E13: Unattempted | F13: Unattempted | G13: Q2 | H13: Q3 | I13: Q4 | J13: Q5 | K13: Q6 | L13: Unattempted | M13: Unattempted | N13: Q9 | O13: Q10 | P13: Q11 | Q13: Unattempted | R13: Unattempted | S13: Q14 | T13: Unattempted | U13: Unattempted
A14: 2010992016 | B14: Unattempted | C14: Unattempted | D14: Unattempted | E14: Unattempted | F14: Unattempted | G14: Q2 | H14: Q3 | I14: Q4 | J14: Q5 | K14: Q6 | L14: Unattempted | M14: Q8 | N14: Q9 | O14: Q10 | P14: Q11 | Q14: Unattempted | R14: Unattempted | S14: Q14 | T14: Unattempted | U14: Unattempted
... A19: 2010992202 | B19: Unattempted | C19: Unattempted | D19: Unattempted | E19: Unattempted | F19: Unattempted | G19: Q2 | H19: Q3 | I19: Q4 | J19: Q5 | K19: Q6 | L19: Unattempted | M19: Q8 | N19: Q9 | O19: Q10 | P19: Q11 | Q19: Unattempted | R19: Unattempted | S19: Q14 | T19: Unattempted | U19: Unattempted

Sheet ST1 Attemped Qs
A1: {=TRANSPOSE('ST1 Questions'!A2:A21)} -> 1a | B1: 1b | C1: 1c | D1: 1d | E1: 1e | F1: Q2 | G1: Q3 | H1: Q4 | I1: Q5 | J1: Q6 | K1: Q7 | L1: Q8 | M1: Q9 | N1: Q10 | O1: Q11 | P1: Q12 | Q1: Q13 | R1: Q14 | S1: Q15 | T1: Q16
A2: {=_xlfn.LET( _xlpm.student_ids, 'ST1 Question Map'!A2:INDEX('ST1 Question Map'!A:A,COUNTA('ST1 Question Map'!A:A)), _xlpm.answers, 'ST1 Question Map'!B2:INDEX('ST1 Question Map'!U:U,COUNTA('ST1 Question Map'!U:U)), _xlpm.num_students, ROWS(_xlpm.student_ids), _xlpm.num_questions, COLUMNS(_xlpm.answers), _xlfn.MAKEARRAY(_xlpm.num_students, _xlpm.num_questions, _xlfn.LAMBDA(_xlpm.r,_xlpm.c, _xlfn.LET( _xlpm.current_col, INDEX(_xlpm.answers, 0, _xlpm.c), _xlpm.filtered_list, _xlfn._xlws.FILTER(_xlpm.student_ids, (_xlpm.current_col<>"") * (NOT(ISNUMBER(SEARCH("Unattemp", _xlpm.current_col)))), ""), IFERROR(INDEX(_xlpm.filtered_list, _xlpm.r), "") ) )) )} | F2: 2010990089 | G2: 2010990089 | H2: 2010990089 | I2: 2010992004 | J2: 2010992004 | L2: 2010990089 | M2: 2010990089 | N2: 2010990089 | O2: 2010990089 | R2: 2010990089
F3: 2010992002 | G3: 2010992002 | H3: 2010992002 | I3: 2010992006 | J3: 2010992006 | L3: 2010992002 | M3: 2010992002 | N3: 2010992002 | O3: 2010992002 | R3: 2010992002
F4: 2010992004 | G4: 2010992004 | H4: 2010992004 | I4: 2010992008 | J4: 2010992008 | L4: 2010992004 | M4: 2010992004 | N4: 2010992004 | O4: 2010992004 | R4: 2010992004
F5: 2010992005 | G5: 2010992005 | H5: 2010992005 | I5: 2010992009 | J5: 2010992009 | L5: 2010992005 | M5: 2010992005 | N5: 2010992005 | O5: 2010992005 | R5: 2010992005
F6: 2010992006 | G6: 2010992006 | H6: 2010992006 | I6: 2010992010 | J6: 2010992010 | L6: 2010992006 | M6: 2010992006 | N6: 2010992006 | O6: 2010992006 | R6: 2010992006
F7: 2010992008 | G7: 2010992008 | H7: 2010992008 | I7: 2010992011 | J7: 2010992011 | L7: 2010992008 | M7: 2010992008 | N7: 2010992008 | O7: 2010992008 | R7: 2010992008
F8: 2010992009 | G8: 2010992009 | H8: 2010992009 | I8: 2010992012 | J8: 2010992012 | L8: 2010992009 | M8: 2010992009 | N8: 2010992009 | O8: 2010992009 | R8: 2010992009
F9: 2010992010 | G9: 2010992010 | H9: 2010992010 | I9: 2010992014 | J9: 2010992014 | L9: 2010992010 | M9: 2010992010 | N9: 2010992010 | O9: 2010992010 | R9: 2010992010
F10: 2010992011 | G10: 2010992011 | H10: 2010992011 | I10: 2010992015 | J10: 2010992015 | L10: 2010992011 | M10: 2010992011 | N10: 2010992011 | O10: 2010992011 | R10: 2010992011
F11: 2010992012 | G11: 2010992012 | H11: 2010992012 | I11: 2010992016 | J11: 2010992016 | L11: 2010992012 | M11: 2010992012 | N11: 2010992012 | O11: 2010992012 | R11: 2010992012
F12: 2010992014 | G12: 2010992014 | H12: 2010992014 | I12: 2010992017 | J12: 2010992017 | L12: 2010992014 | M12: 2010992014 | N12: 2010992014 | O12: 2010992014 | R12: 2010992014
F13: 2010992015 | G13: 2010992015 | H13: 2010992015 | I13: 2010992018 | J13: 2010992018 | L13: 2010992016 | M13: 2010992015 | N13: 2010992015 | O13: 2010992015 | R13: 2010992015
F14: 2010992016 | G14: 2010992016 | H14: 2010992016 | I14: 2010992019 | J14: 2010992019 | L14: 2010992017 | M14: 2010992016 | N14: 2010992016 | O14: 2010992016 | R14: 2010992016
... F16: 2010992018 | G16: 2010992018 | H16: 2010992018 | I16: 2010992202 | J16: 2010992202 | L16: 2010992019 | M16: 2010992018 | N16: 2010992018 | O16: 2010992018 | R16: 2010992018
F17: 2010992019 | G17: 2010992019 | H17: 2010992019 | L17: 2010992163 | M17: 2010992019 | N17: 2010992019 | O17: 2010992019 | R17: 2010992019
F18: 2010992163 | G18: 2010992163 | H18: 2010992163 | L18: 2010992202 | M18: 2010992163 | N18: 2010992163 | O18: 2010992163 | R18: 2010992163
F19: 2010992202 | G19: 2010992202 | H19: 2010992202 | M19: 2010992202 | N19: 2010992202 | O19: 2010992202 | R19: 2010992202

Sheet ST1 Attempted COs
A1: {='ST1 Questions'!C1:H1} -> CO1 | B1: CO2 | C1: CO3 | D1: CO4 | E1: CO5 | F1: CO6
A2: {=_xlfn.LET( _xlpm.TargetStudents, TRANSPOSE( _xlfn._xlws.FILTER( 'ST1 Questions'!$A$2:INDEX('ST1 Questions'!$A:$A, COUNTA('ST1 Questions'!$A:$A)), _xlfn.XLOOKUP( A$1, 'ST1 Questions'!$C$1:$H$1, 'ST1 Questions'!$C$2:INDEX('ST1 Questions'!$H:$H, COUNTA('ST1 Questions'!$H:$H)) ), "No Matches" ) ), _xlpm.DataGrid, _xlfn.DROP( _xlfn.REDUCE("", _xlpm.TargetStudents, _xlfn.LAMBDA(_xlpm.accumulator,_xlpm.student, _xlfn.HSTACK( _xlpm.accumulator, _xlfn.XLOOKUP( _xlpm.student, 'ST1 Attemped Qs'!$A$1:$T$1, 'ST1 Attemped Qs'!$A$2:INDEX('ST1 Attemped Qs'!$T:$T, COUNTA('ST1 Attemped Qs'!$T:$T)), "" ) ) )), , 1 ), _xlpm.FlattenedList, _xlfn.TOCOL(_xlpm.DataGrid, 1), _xlfn.UNIQUE( _xlfn._xlws.FILTER(_xlpm.FlattenedList, _xlpm.FlattenedList <> "") ) )} -> 2010990089 | B2: {=_xlfn.LET( _xlpm.TargetStudents, TRANSPOSE( _xlfn._xlws.FILTER( 'ST1 Questions'!$A$2:INDEX('ST1 Questions'!$A:$A, COUNTA('ST1 Questions'!$A:$A)), _xlfn.XLOOKUP( B$1, 'ST1 Questions'!$C$1:$H$1, 'ST1 Questions'!$C$2:INDEX('ST1 Questions'!$H:$H, COUNTA('ST1 Questions'!$H:$H)) ), "No Matches" ) ), _xlpm.DataGrid, _xlfn.DROP( _xlfn.REDUCE("", _xlpm.TargetStudents, _xlfn.LAMBDA(_xlpm.accumulator,_xlpm.student, _xlfn.HSTACK( _xlpm.accumulator, _xlfn.XLOOKUP( _xlpm.student, 'ST1 Attemped Qs'!$A$1:$T$1, 'ST1 Attemped Qs'!$A$2:INDEX('ST1 Attemped Qs'!$T:$T, COUNTA('ST1 Attemped Qs'!$T:$T)), "" ) ) )), , 1 ), _xlpm.FlattenedList, _xlfn.TOCOL(_xlpm.DataGrid, 1), _xlfn.UNIQUE( _xlfn._xlws.FILTER(_xlpm.FlattenedList, _xlpm.FlattenedList <> "") ) )} -> 2010990089 | C2: {=_xlfn.LET( _xlpm.TargetStudents, TRANSPOSE( _xlfn._xlws.FILTER( 'ST1 Questions'!$A$2:INDEX('ST1 Questions'!$A:$A, COUNTA('ST1 Questions'!$A:$A)), _xlfn.XLOOKUP( C$1, 'ST1 Questions'!$C$1:$H$1, 'ST1 Questions'!$C$2:INDEX('ST1 Questions'!$H:$H, COUNTA('ST1 Questions'!$H:$H)) ), "No Matches" ) ), _xlpm.DataGrid, _xlfn.DROP( _xlfn.REDUCE("", _xlpm.TargetStudents, _xlfn.LAMBDA(_xlpm.accumulator,_xlpm.student, _xlfn.HSTACK( _xlpm.accumulator, _xlfn.XLOOKUP( _xlpm.student, 'ST1 Attemped Qs'!$A$1:$T$1, 'ST1 Attemped Qs'!$A$2:INDEX('ST1 Attemped Qs'!$T:$T, COUNTA('ST1 Attemped Qs'!$T:$T)), "" ) ) )), , 1 ), _xlpm.FlattenedList, _xlfn.TOCOL(_xlpm.DataGrid, 1), _xlfn.UNIQUE( _xlfn._xlws.FILTER(_xlpm.FlattenedList, _xlpm.FlattenedList <> "") ) )} -> 2010990089 | D2: {=_xlfn.LET( _xlpm.TargetStudents, TRANSPOSE( _xlfn._xlws.FILTER( 'ST1 Questions'!$A$2:INDEX('ST1 Questions'!$A:$A, COUNTA('ST1 Questions'!$A:$A)), _xlfn.XLOOKUP( D$1, 'ST1 Questions'!$C$1:$H$1, 'ST1 Questions'!$C$2:INDEX('ST1 Questions'!$H:$H, COUNTA('ST1 Questions'!$H:$H)) ), "No Matches" ) ), _xlpm.DataGrid, _xlfn.DROP( _xlfn.REDUCE("", _xlpm.TargetStudents, _xlfn.LAMBDA(_xlpm.accumulator,_xlpm.student, _xlfn.HSTACK( _xlpm.accumulator, _xlfn.XLOOKUP( _xlpm.student, 'ST1 Attemped Qs'!$A$1:$T$1, 'ST1 Attemped Qs'!$A$2:INDEX('ST1 Attemped Qs'!$T:$T, COUNTA('ST1 Attemped Qs'!$T:$T)), "" ) ) )), , 1 ), _xlpm.FlattenedList, _xlfn.TOCOL(_xlpm.DataGrid, 1), _xlfn.UNIQUE( _xlfn._xlws.FILTER(_xlpm.FlattenedList, _xlpm.FlattenedList <> "") ) )} -> 2010990089 | E2: {=_xlfn.LET( _xlpm.TargetStudents, TRANSPOSE( _xlfn._xlws.FILTER( 'ST1 Questions'!$A$2:INDEX('ST1 Questions'!$A:$A, COUNTA('ST1 Questions'!$A:$A)), _xlfn.XLOOKUP( E$1, 'ST1 Questions'!$C$1:$H$1, 'ST1 Questions'!$C$2:INDEX('ST1 Questions'!$H:$H, COUNTA('ST1 Questions'!$H:$H)) ), "No Matches" ) ), _xlpm.DataGrid, _xlfn.DROP( _xlfn.REDUCE("", _xlpm.TargetStudents, _xlfn.LAMBDA(_xlpm.accumulator,_xlpm.student, _xlfn.HSTACK( _xlpm.accumulator, _xlfn.XLOOKUP( _xlpm.student, 'ST1 Attemped Qs'!$A$1:$T$1, 'ST1 Attemped Qs'!$A$2:INDEX('ST1 Attemped Qs'!$T:$T, COUNTA('ST1 Attemped Qs'!$T:$T)), "" ) ) )), , 1 ), _xlpm.FlattenedList, _xlfn.TOCOL(_xlpm.DataGrid, 1), _xlfn.UNIQUE( _xlfn._xlws.FILTER(_xlpm.FlattenedList, _xlpm.FlattenedList <> "") ) )} -> 2010992004 | F2: {=_xlfn.LET( _xlpm.TargetStudents, TRANSPOSE( _xlfn._xlws.FILTER( 'ST1 Questions'!$A$2:INDEX('ST1 Questions'!$A:$A, COUNTA('ST1 Questions'!$A:$A)), _xlfn.XLOOKUP( F$1, 'ST1 Questions'!$C$1:$H$1, 'ST1 Questions'!$C$2:INDEX('ST1 Questions'!$H:$H, COUNTA('ST1 Questions'!$H:$H)) ), "No Matches" ) ), _xlpm.DataGrid, _xlfn.DROP( _xlfn.REDUCE("", _xlpm.TargetStudents, _xlfn.LAMBDA(_xlpm.accumulator,_xlpm.student, _xlfn.HSTACK( _xlpm.accumulator, _xlfn.XLOOKUP( _xlpm.student, 'ST1 Attemped Qs'!$A$1:$T$1, 'ST1 Attemped Qs'!$A$2:INDEX('ST1 Attemped Qs'!$T:$T, COUNTA('ST1 Attemped Qs'!$T:$T)), "" ) ) )), , 1 ), _xlpm.FlattenedList, _xlfn.TOCOL(_xlpm.DataGrid, 1), _xlfn.UNIQUE( _xlfn._xlws.FILTER(_xlpm.FlattenedList, _xlpm.FlattenedList <> "") ) )} -> 2010990089
A3: 2010992004 | B3: 2010992004 | C3: 2010992002 | D3: 2010992002 | E3: 2010992006 | F3: 2010992002
A4: 2010992002 | B4: 2010992002 | C4: 2010992004 | D4: 2010992004 | E4: 2010992008 | F4: 2010992004
A5: 2010992006 | B5: 2010992006 | C5: 2010992005 | D5: 2010992005 | E5: 2010992009 | F5: 2010992005
A6: 2010992008 | B6: 2010992008 | C6: 2010992006 | D6: 2010992006 | E6: 2010992010 | F6: 2010992006
A7: 2010992005 | B7: 2010992005 | C7: 2010992008 | D7: 2010992008 | E7: 2010992011 | F7: 2010992008
A8: 2010992009 | B8: 2010992009 | C8: 2010992009 | D8: 2010992009 | E8: 2010992012 | F8: 2010992009
A9: 2010992010 | B9: 2010992010 | C9: 2010992010 | D9: 2010992010 | E9: 2010992014 | F9: 2010992010
A10: 2010992011 | B10: 2010992011 | C10: 2010992011 | D10: 2010992011 | E10: 2010992015 | F10: 2010992011
A11: 2010992012 | B11: 2010992012 | C11: 2010992012 | D11: 2010992012 | E11: 2010992016 | F11: 2010992012
A12: 2010992014 | B12: 2010992014 | C12: 2010992014 | D12: 2010992014 | E12: 2010992017 | F12: 2010992014
A13: 2010992015 | B13: 2010992015 | C13: 2010992015 | D13: 2010992015 | E13: 2010992018 | F13: 2010992015
A14: 2010992016 | B14: 2010992016 | C14: 2010992016 | D14: 2010992016 | E14: 2010992019 | F14: 2010992016
... A16: 2010992018 | B16: 2010992018 | C16: 2010992018 | D16: 2010992018 | E16: 2010992202 | F16: 2010992018
A17: 2010992019 | B17: 2010992019 | C17: 2010992019 | D17: 2010992019 | F17: 2010992019
A18: 2010992163 | B18: 2010992163 | C18: 2010992163 | D18: 2010992163 | F18: 2010992163
A19: 2010992202 | B19: 2010992202 | C19: 2010992202 | D19: 2010992202 | F19: 2010992202

Sheet ST1 Student MO CO Score
A1: {=INDEX('ST1 Result'!B:B, 1):INDEX('ST1 Result'!B:B, COUNTA('ST1 Result'!B:B))} -> Admission No. (Roll No.) | B1: {='ST1 Questions'!C1:H1} -> CO1 | C1: CO2 | D1: CO3 | E1: CO4 | F1: CO5 | G1: CO6
A2: 2010990089 | B2: {=_xlfn.BYROW($A2:INDEX($A:$A,COUNTA($A:$A)),_xlfn.LAMBDA(_xlpm.studentID,SUM(IFERROR(_xlfn.XLOOKUP(IF(_xlfn.XLOOKUP(B$1,'ST1 Questions'!$C$1:$H$1, 'ST1 Questions'!$C$2:$H$21) = TRUE, TRANSPOSE( _xlfn.XLOOKUP(_xlpm.studentID,'ST1 Question Map'!$A$2:INDEX('ST1 Question Map'!$A:$A, COUNTA('ST1 Question Map'!$A:$A)), 'ST1 Question Map'!$B$2:INDEX('ST1 Question Map'!$U:$U, COUNTA('ST1 Question Map'!$U:$U))))),'ST1 Questions'!$A$2:$A$21, 'ST1 Questions'!$B$2:$B$21),0))))} -> 36 | C2: {=_xlfn.BYROW($A2:INDEX($A:$A,COUNTA($A:$A)),_xlfn.LAMBDA(_xlpm.studentID,SUM(IFERROR(_xlfn.XLOOKUP(IF(_xlfn.XLOOKUP(C$1,'ST1 Questions'!$C$1:$H$1, 'ST1 Questions'!$C$2:$H$21) = TRUE, TRANSPOSE( _xlfn.XLOOKUP(_xlpm.studentID,'ST1 Question Map'!$A$2:INDEX('ST1 Question Map'!$A:$A, COUNTA('ST1 Question Map'!$A:$A)), 'ST1 Question Map'!$B$2:INDEX('ST1 Question Map'!$U:$U, COUNTA('ST1 Question Map'!$U:$U))))),'ST1 Questions'!$A$2:$A$21, 'ST1 Questions'!$B$2:$B$21),0))))} -> 22 | D2: {=_xlfn.BYROW($A2:INDEX($A:$A,COUNTA($A:$A)),_xlfn.LAMBDA(_xlpm.studentID,SUM(IFERROR(_xlfn.XLOOKUP(IF(_xlfn.XLOOKUP(D$1,'ST1 Questions'!$C$1:$H$1, 'ST1 Questions'!$C$2:$H$21) = TRUE, TRANSPOSE( _xlfn.XLOOKUP(_xlpm.studentID,'ST1 Question Map'!$A$2:INDEX('ST1 Question Map'!$A:$A, COUNTA('ST1 Question Map'!$A:$A)), 'ST1 Question Map'!$B$2:INDEX('ST1 Question Map'!$U:$U, COUNTA('ST1 Question Map'!$U:$U))))),'ST1 Questions'!$A$2:$A$21, 'ST1 Questions'!$B$2:$B$21),0))))} -> 17 | E2: {=_xlfn.BYROW($A2:INDEX($A:$A,COUNTA($A:$A)),_xlfn.LAMBDA(_xlpm.studentID,SUM(IFERROR(_xlfn.XLOOKUP(IF(_xlfn.XLOOKUP(E$1,'ST1 Questions'!$C$1:$H$1, 'ST1 Questions'!$C$2:$H$21) = TRUE, TRANSPOSE( _xlfn.XLOOKUP(_xlpm.studentID,'ST1 Question Map'!$A$2:INDEX('ST1 Question Map'!$A:$A, COUNTA('ST1 Question Map'!$A:$A)), 'ST1 Question Map'!$B$2:INDEX('ST1 Question Map'!$U:$U, COUNTA('ST1 Question Map'!$U:$U))))),'ST1 Questions'!$A$2:$A$21, 'ST1 Questions'!$B$2:$B$21),0))))} -> 22 | F2: {=_xlfn.BYROW($A2:INDEX($A:$A,COUNTA($A:$A)),_xlfn.LAMBDA(_xlpm.studentID,SUM(IFERROR(_xlfn.XLOOKUP(IF(_xlfn.XLOOKUP(F$1,'ST1 Questions'!$C$1:$H$1, 'ST1 Questions'!$C$2:$H$21) = TRUE, TRANSPOSE( _xlfn.XLOOKUP(_xlpm.studentID,'ST1 Question Map'!$A$2:INDEX('ST1 Question Map'!$A:$A, COUNTA('ST1 Question Map'!$A:$A)), 'ST1 Question Map'!$B$2:INDEX('ST1 Question Map'!$U:$U, COUNTA('ST1 Question Map'!$U:$U))))),'ST1 Questions'!$A$2:$A$21, 'ST1 Questions'!$B$2:$B$21),0))))} -> 0 | G2: {=_xlfn.BYROW($A2:INDEX($A:$A,COUNTA($A:$A)),_xlfn.LAMBDA(_xlpm.studentID,SUM(IFERROR(_xlfn.XLOOKUP(IF(_xlfn.XLOOKUP(G$1,'ST1 Questions'!$C$1:$H$1, 'ST1 Questions'!$C$2:$H$21) = TRUE, TRANSPOSE( _xlfn.XLOOKUP(_xlpm.studentID,'ST1 Question Map'!$A$2:INDEX('ST1 Question Map'!$A:$A, COUNTA('ST1 Question Map'!$A:$A)), 'ST1 Question Map'!$B$2:INDEX('ST1 Question Map'!$U:$U, COUNTA('ST1 Question Map'!$U:$U))))),'ST1 Questions'!$A$2:$A$21, 'ST1 Questions'!$B$2:$B$21),0))))} -> 15
A3: 2010992002 | B3: 36 | C3: 22 | D3: 17 | E3: 22 | F3: 0 | G3: 15 | S3: SUM(IFERROR(XLOOKUP(IF(XLOOKUP(B$1,'ST1 Questions'!$C$1:$H$1,'ST1 Questions'!$C$2:$H$17)=TRUE,TRANSPOSE(XLOOKUP($A2,'ST1 Question Map'!$A$2:INDEX('ST1 Question Map'!$A:$A,COUNTA('ST1 Question Map'!$A:$A)),'ST1 Question Map'!$B$2:$Q$98))),'ST1 Questions'!$A$2:$A$17,'ST1 Questions'!$B$2:$B$17),0))
A4: 2010992004 | B4: 40 | C4: 26 | D4: 17 | E4: 22 | F4: 2 | G4: 15
A5: 2010992005 | B5: 36 | C5: 22 | D5: 17 | E5: 22 | F5: 0 | G5: 15 | S5: SUM(IFERROR(XLOOKUP(IF(XLOOKUP(B$1,'ST1 Questions'!$C$1:$H$1,'ST1 Questions'!$C$2:$H$17)=TRUE,TRANSPOSE(XLOOKUP($A2,'ST1 Question Map'!$A$2:INDEX('ST1 Question Map'!$A:$A,COUNTA('ST1 Question Map'!$A:$A)),'ST1 Question Map'!$B$2:INDEX('ST1 Question Map'!$Q:$Q,COUNTA('ST1 Question Map'!$Q:$Q))))),'ST1 Questions'!$A$2:$A$17,'ST1 Questions'!$B$2:$B$17),0))
A6: 2010992006 | B6: 40 | C6: 26 | D6: 17 | E6: 22 | F6: 2 | G6: 15
A7: 2010992008 | B7: 40 | C7: 26 | D7: 17 | E7: 22 | F7: 2 | G7: 15
A8: 2010992009 | B8: 40 | C8: 26 | D8: 17 | E8: 22 | F8: 2 | G8: 15
A9: 2010992010 | B9: 40 | C9: 26 | D9: 17 | E9: 22 | F9: 2 | G9: 15
A10: 2010992011 | B10: 40 | C10: 26 | D10: 17 | E10: 22 | F10: 2 | G10: 15
A11: 2010992012 | B11: 40 | C11: 26 | D11: 17 | E11: 22 | F11: 2 | G11: 15
A12: 2010992014 | B12: 40 | C12: 26 | D12: 17 | E12: 22 | F12: 2 | G12: 15
A13: 2010992015 | B13: 35 | C13: 21 | D13: 17 | E13: 22 | F13: 2 | G13: 15
A14: 2010992016 | B14: 40 | C14: 26 | D14: 17 | E14: 22 | F14: 2 | G14: 15
A15: 2010992017 | B15: 40 | C15: 26 | D15: 17 | E15: 22 | F15: 2 | G15: 15
A16: 2010992018 | B16: 40 | C16: 26 | D16: 17 | E16: 22 | F16: 2 | G16: 15
A17: 2010992019 | B17: 40 | C17: 26 | D17: 17 | E17: 22 | F17: 2 | G17: 15
... A19: 2010992202 | B19: 40 | C19: 26 | D19: 17 | E19: 22 | F19: 2 | G19: 15

Sheet ST1 Student Attained CO Score
A1: {=INDEX('ST1 Result'!B:B, 1):INDEX('ST1 Result'!B:B, COUNTA('ST1 Result'!B:B))} -> Admission No. (Roll No.) | B1: {='ST1 Questions'!C1:H1} -> CO1 | C1: CO2 | D1: CO3 | E1: CO4 | F1: CO5 | G1: CO6
A2: 2010990089 | B2: {=_xlfn.BYROW($A2:INDEX($A:$A,COUNTA($A:$A)),_xlfn.LAMBDA(_xlpm.studentID,SUM(IFERROR(_xlfn.XLOOKUP(IF(_xlfn.XLOOKUP(B$1,'ST1 Questions'!$C$1:$H$1,'ST1 Questions'!$C$2:$H$24)=TRUE,TRANSPOSE(_xlfn.XLOOKUP(_xlpm.studentID,'ST1 Question Map'!$A$2:INDEX('ST1 Question Map'!$A:$A,COUNTA('ST1 Question Map'!$A:$A)), 'ST1 Question Map'!$B$2:INDEX('ST1 Question Map'!$U:$U,COUNTA('ST1 Question Map'!$U:$U))))),'ST1 Student Marks'!$B$1:$U$1,_xlfn.XLOOKUP( _xlpm.studentID,'ST1 Student Marks'!$A$1:INDEX('ST1 Student Marks'!$A:$A,COUNTA('ST1 Student Marks'!$A:$A)),'ST1 Student Marks'!$B$1:INDEX('ST1 Student Marks'!$U:$U,COUNTA('ST1 Student Marks'!$U:$U)))),0))))} -> 14 | C2: {=_xlfn.BYROW($A2:INDEX($A:$A,COUNTA($A:$A)),_xlfn.LAMBDA(_xlpm.studentID,SUM(IFERROR(_xlfn.XLOOKUP(IF(_xlfn.XLOOKUP(C$1,'ST1 Questions'!$C$1:$H$1,'ST1 Questions'!$C$2:$H$24)=TRUE,TRANSPOSE(_xlfn.XLOOKUP(_xlpm.studentID,'ST1 Question Map'!$A$2:INDEX('ST1 Question Map'!$A:$A,COUNTA('ST1 Question Map'!$A:$A)), 'ST1 Question Map'!$B$2:INDEX('ST1 Question Map'!$U:$U,COUNTA('ST1 Question Map'!$U:$U))))),'ST1 Student Marks'!$B$1:$U$1,_xlfn.XLOOKUP( _xlpm.studentID,'ST1 Student Marks'!$A$1:INDEX('ST1 Student Marks'!$A:$A,COUNTA('ST1 Student Marks'!$A:$A)),'ST1 Student Marks'!$B$1:INDEX('ST1 Student Marks'!$U:$U,COUNTA('ST1 Student Marks'!$U:$U)))),0))))} -> 8 | D2: {=_xlfn.BYROW($A2:INDEX($A:$A,COUNTA($A:$A)),_xlfn.LAMBDA(_xlpm.studentID,SUM(IFERROR(_xlfn.XLOOKUP(IF(_xlfn.XLOOKUP(D$1,'ST1 Questions'!$C$1:$H$1,'ST1 Questions'!$C$2:$H$24)=TRUE,TRANSPOSE(_xlfn.XLOOKUP(_xlpm.studentID,'ST1 Question Map'!$A$2:INDEX('ST1 Question Map'!$A:$A,COUNTA('ST1 Question Map'!$A:$A)), 'ST1 Question Map'!$B$2:INDEX('ST1 Question Map'!$U:$U,COUNTA('ST1 Question Map'!$U:$U))))),'ST1 Student Marks'!$B$1:$U$1,_xlfn.XLOOKUP( _xlpm.studentID,'ST1 Student Marks'!$A$1:INDEX('ST1 Student Marks'!$A:$A,COUNTA('ST1 Student Marks'!$A:$A)),'ST1 Student Marks'!$B$1:INDEX('ST1 Student Marks'!$U:$U,COUNTA('ST1 Student Marks'!$U:$U)))),0))))} -> 6 | E2: {=_xlfn.BYROW($A2:INDEX($A:$A,COUNTA($A:$A)),_xlfn.LAMBDA(_xlpm.studentID,SUM(IFERROR(_xlfn.XLOOKUP(IF(_xlfn.XLOOKUP(E$1,'ST1 Questions'!$C$1:$H$1,'ST1 Questions'!$C$2:$H$24)=TRUE,TRANSPOSE(_xlfn.XLOOKUP(_xlpm.studentID,'ST1 Question Map'!$A$2:INDEX('ST1 Question Map'!$A:$A,COUNTA('ST1 Question Map'!$A:$A)), 'ST1 Question Map'!$B$2:INDEX('ST1 Question Map'!$U:$U,COUNTA('ST1 Question Map'!$U:$U))))),'ST1 Student Marks'!$B$1:$U$1,_xlfn.XLOOKUP( _xlpm.studentID,'ST1 Student Marks'!$A$1:INDEX('ST1 Student Marks'!$A:$A,COUNTA('ST1 Student Marks'!$A:$A)),'ST1 Student Marks'!$B$1:INDEX('ST1 Student Marks'!$U:$U,COUNTA('ST1 Student Marks'!$U:$U)))),0))))} -> 10 | F2: {=_xlfn.BYROW($A2:INDEX($A:$A,COUNTA($A:$A)),_xlfn.LAMBDA(_xlpm.studentID,SUM(IFERROR(_xlfn.XLOOKUP(IF(_xlfn.XLOOKUP(F$1,'ST1 Questions'!$C$1:$H$1,'ST1 Questions'!$C$2:$H$24)=TRUE,TRANSPOSE(_xlfn.XLOOKUP(_xlpm.studentID,'ST1 Question Map'!$A$2:INDEX('ST1 Question Map'!$A:$A,COUNTA('ST1 Question Map'!$A:$A)), 'ST1 Question Map'!$B$2:INDEX('ST1 Question Map'!$U:$U,COUNTA('ST1 Question Map'!$U:$U))))),'ST1 Student Marks'!$B$1:$U$1,_xlfn.XLOOKUP( _xlpm.studentID,'ST1 Student Marks'!$A$1:INDEX('ST1 Student Marks'!$A:$A,COUNTA('ST1 Student Marks'!$A:$A)),'ST1 Student Marks'!$B$1:INDEX('ST1 Student Marks'!$U:$U,COUNTA('ST1 Student Marks'!$U:$U)))),0))))} -> 0 | G2: {=_xlfn.BYROW($A2:INDEX($A:$A,COUNTA($A:$A)),_xlfn.LAMBDA(_xlpm.studentID,SUM(IFERROR(_xlfn.XLOOKUP(IF(_xlfn.XLOOKUP(G$1,'ST1 Questions'!$C$1:$H$1,'ST1 Questions'!$C$2:$H$24)=TRUE,TRANSPOSE(_xlfn.XLOOKUP(_xlpm.studentID,'ST1 Question Map'!$A$2:INDEX('ST1 Question Map'!$A:$A,COUNTA('ST1 Question Map'!$A:$A)), 'ST1 Question Map'!$B$2:INDEX('ST1 Question Map'!$U:$U,COUNTA('ST1 Question Map'!$U:$U))))),'ST1 Student Marks'!$B$1:$U$1,_xlfn.XLOOKUP( _xlpm.studentID,'ST1 Student Marks'!$A$1:INDEX('ST1 Student Marks'!$A:$A,COUNTA('ST1 Student Marks'!$A:$A)),'ST1 Student Marks'!$B$1:INDEX('ST1 Student Marks'!$U:$U,COUNTA('ST1 Student Marks'!$U:$U)))),0))))} -> 8
A3: 2010992002 | B3: 34 | C3: 21 | D3: 17 | E3: 20 | F3: 0 | G3: 14
A4: 2010992004 | B4: 28 | C4: 18 | D4: 12 | E4: 15 | F4: 2 | G4: 10
A5: 2010992005 | B5: 25 | C5: 16 | D5: 13 | E5: 16 | F5: 0 | G5: 11
A6: 2010992006 | B6: 28 | C6: 18 | D6: 12 | E6: 15 | F6: 2 | G6: 10
A7: 2010992008 | B7: 29 | C7: 19 | D7: 12 | E7: 16 | F7: 2 | G7: 11
A8: 2010992009 | B8: 28 | C8: 18 | D8: 14 | E8: 16 | F8: 1 | G8: 11
A9: 2010992010 | B9: 29 | C9: 19 | D9: 13 | E9: 17 | F9: 1 | G9: 12
A10: 2010992011 | B10: 28 | C10: 19 | D10: 12 | E10: 17 | F10: 1 | G10: 12
A11: 2010992012 | B11: 26 | C11: 17 | D11: 10 | E11: 15 | F11: 1 | G11: 10
A12: 2010992014 | B12: 29 | C12: 19 | D12: 13 | E12: 17 | F12: 1 | G12: 12
A13: 2010992015 | B13: 23 | C13: 14 | D13: 12 | E13: 15 | F13: 1 | G13: 10
A14: 2010992016 | B14: 21 | C14: 15 | D14: 8 | E14: 11 | F14: 1 | G14: 7
... A19: 2010992202 | B19: 30 | C19: 20 | D19: 13 | E19: 17 | F19: 2 | G19: 12

Sheet ST1 Student Attainment percent
A1: {=INDEX('ST1 Result'!B:B, 1):INDEX('ST1 Result'!B:B, COUNTA('ST1 Result'!B:B))} -> Admission No. (Roll No.) | B1: {='ST1 Questions'!C1:H1} -> CO1 | C1: CO2 | D1: CO3 | E1: CO4 | F1: CO5 | G1: CO6
A2: 2010990089 | B2: {=_xlfn.BYROW($A2:INDEX($A:$A,COUNTA($A:$A)),_xlfn.LAMBDA(_xlpm.studentID,IFERROR(_xlfn.XLOOKUP(_xlpm.studentID,'ST1 Student Attained CO Score'!$A:$A, 'ST1 Student Attained CO Score'!B:B) / _xlfn.XLOOKUP(_xlpm.studentID,'ST1 Student MO CO Score'!$A:$A,'ST1 Student MO CO Score'!B:B)*100, "NA")))} -> 38.888889 | C2: {=_xlfn.BYROW($A2:INDEX($A:$A,COUNTA($A:$A)),_xlfn.LAMBDA(_xlpm.studentID,IFERROR(_xlfn.XLOOKUP(_xlpm.studentID,'ST1 Student Attained CO Score'!$A:$A, 'ST1 Student Attained CO Score'!C:C) / _xlfn.XLOOKUP(_xlpm.studentID,'ST1 Student MO CO Score'!$A:$A,'ST1 Student MO CO Score'!C:C)*100, "NA")))} -> 36.363636 | D2: {=_xlfn.BYROW($A2:INDEX($A:$A,COUNTA($A:$A)),_xlfn.LAMBDA(_xlpm.studentID,IFERROR(_xlfn.XLOOKUP(_xlpm.studentID,'ST1 Student Attained CO Score'!$A:$A, 'ST1 Student Attained CO Score'!D:D) / _xlfn.XLOOKUP(_xlpm.studentID,'ST1 Student MO CO Score'!$A:$A,'ST1 Student MO CO Score'!D:D)*100, "NA")))} -> 35.294118 | E2: {=_xlfn.BYROW($A2:INDEX($A:$A,COUNTA($A:$A)),_xlfn.LAMBDA(_xlpm.studentID,IFERROR(_xlfn.XLOOKUP(_xlpm.studentID,'ST1 Student Attained CO Score'!$A:$A, 'ST1 Student Attained CO Score'!E:E) / _xlfn.XLOOKUP(_xlpm.studentID,'ST1 Student MO CO Score'!$A:$A,'ST1 Student MO CO Score'!E:E)*100, "NA")))} -> 45.454545 | F2: {=_xlfn.BYROW($A2:INDEX($A:$A,COUNTA($A:$A)),_xlfn.LAMBDA(_xlpm.studentID,IFERROR(_xlfn.XLOOKUP(_xlpm.studentID,'ST1 Student Attained CO Score'!$A:$A, 'ST1 Student Attained CO Score'!F:F) / _xlfn.XLOOKUP(_xlpm.studentID,'ST1 Student MO CO Score'!$A:$A,'ST1 Student MO CO Score'!F:F)*100, "NA")))} -> NA | G2: {=_xlfn.BYROW($A2:INDEX($A:$A,COUNTA($A:$A)),_xlfn.LAMBDA(_xlpm.studentID,IFERROR(_xlfn.XLOOKUP(_xlpm.studentID,'ST1 Student Attained CO Score'!$A:$A, 'ST1 Student Attained CO Score'!G:G) / _xlfn.XLOOKUP(_xlpm.studentID,'ST1 Student MO CO Score'!$A:$A,'ST1 Student MO CO Score'!G:G)*100, "NA")))} -> 53.333333
A3: 2010992002 | B3: 94.444444 | C3: 95.454545 | D3: 100 | E3: 90.909091 | F3: NA | G3: 93.333333
A4: 2010992004 | B4: 70 | C4: 69.230769 | D4: 70.588235 | E4: 68.181818 | F4: 100 | G4: 66.666667
A5: 2010992005 | B5: 69.444444 | C5: 72.727273 | D5: 76.470588 | E5: 72.727273 | F5: NA | G5: 73.333333
A6: 2010992006 | B6: 70 | C6: 69.230769 | D6: 70.588235 | E6: 68.181818 | F6: 100 | G6: 66.666667
A7: 2010992008 | B7: 72.5 | C7: 73.076923 | D7: 70.588235 | E7: 72.727273 | F7: 100 | G7: 73.333333
A8: 2010992009 | B8: 70 | C8: 69.230769 | D8: 82.352941 | E8: 72.727273 | F8: 50 | G8: 73.333333
A9: 2010992010 | B9: 72.5 | C9: 73.076923 | D9: 76.470588 | E9: 77.272727 | F9: 50 | G9: 80
A10: 2010992011 | B10: 70 | C10: 73.076923 | D10: 70.588235 | E10: 77.272727 | F10: 50 | G10: 80
A11: 2010992012 | B11: 65 | C11: 65.384615 | D11: 58.823529 | E11: 68.181818 | F11: 50 | G11: 66.666667
A12: 2010992014 | B12: 72.5 | C12: 73.076923 | D12: 76.470588 | E12: 77.272727 | F12: 50 | G12: 80
A13: 2010992015 | B13: 65.714286 | C13: 66.666667 | D13: 70.588235 | E13: 68.181818 | F13: 50 | G13: 66.666667
A14: 2010992016 | B14: 52.5 | C14: 57.692308 | D14: 47.058824 | E14: 50 | F14: 50 | G14: 46.666667
A15: 2010992017 | B15: 77.5 | C15: 76.923077 | D15: 76.470588 | E15: 77.272727 | F15: 100 | G15: 80
A16: 2010992018 | B16: 65 | C16: 65.384615 | D16: 76.470588 | E16: 72.727273 | F16: 50 | G16: 73.333333
A17: 2010992019 | B17: 55 | C17: 50 | D17: 52.941176 | E17: 59.090909 | F17: 50 | G17: 60
... A19: 2010992202 | B19: 75 | C19: 76.923077 | D19: 76.470588 | E19: 77.272727 | F19: 100 | G19: 80

Sheet ST1 CO Attainment Score
A1: {=INDEX('ST1 Result'!B:B, 1):INDEX('ST1 Result'!B:B, COUNTA('ST1 Result'!B:B) )} -> Admission No. (Roll No.) | B1: {='ST1 Questions'!C1:H1} -> CO1 | C1: CO2 | D1: CO3 | E1: CO4 | F1: CO5 | G1: CO6
A2: 2010990089 | B2: {=_xlfn.BYROW('ST1 Student Attainment percent'!B2:INDEX('ST1 Student Attainment percent'!B:B,COUNTA('ST1 Student Attainment percent'!B:B)),_xlfn.LAMBDA(_xlpm.score,_xlfn.IFS(_xlpm.score="NA","NA",_xlpm.score>'OBE Data'!$B$2-1,3,_xlpm.score>'OBE Data'!$B$3-1,2,_xlpm.score>'OBE Data'!$B$4-1,1,_xlpm.score<'OBE Data'!$B$4,0)))} -> 0 | C2: {=_xlfn.BYROW('ST1 Student Attainment percent'!C2:INDEX('ST1 Student Attainment percent'!C:C,COUNTA('ST1 Student Attainment percent'!C:C)),_xlfn.LAMBDA(_xlpm.score,_xlfn.IFS(_xlpm.score="NA","NA",_xlpm.score>'OBE Data'!$B$2-1,3,_xlpm.score>'OBE Data'!$B$3-1,2,_xlpm.score>'OBE Data'!$B$4-1,1,_xlpm.score<'OBE Data'!$B$4,0)))} -> 0 | D2: {=_xlfn.BYROW('ST1 Student Attainment percent'!D2:INDEX('ST1 Student Attainment percent'!D:D,COUNTA('ST1 Student Attainment percent'!D:D)),_xlfn.LAMBDA(_xlpm.score,_xlfn.IFS(_xlpm.score="NA","NA",_xlpm.score>'OBE Data'!$B$2-1,3,_xlpm.score>'OBE Data'!$B$3-1,2,_xlpm.score>'OBE Data'!$B$4-1,1,_xlpm.score<'OBE Data'!$B$4,0)))} -> 0 | E2: {=_xlfn.BYROW('ST1 Student Attainment percent'!E2:INDEX('ST1 Student Attainment percent'!E:E,COUNTA('ST1 Student Attainment percent'!E:E)),_xlfn.LAMBDA(_xlpm.score,_xlfn.IFS(_xlpm.score="NA","NA",_xlpm.score>'OBE Data'!$B$2-1,3,_xlpm.score>'OBE Data'!$B$3-1,2,_xlpm.score>'OBE Data'!$B$4-1,1,_xlpm.score<'OBE Data'!$B$4,0)))} -> 0 | F2: {=_xlfn.BYROW('ST1 Student Attainment percent'!F2:INDEX('ST1 Student Attainment percent'!F:F,COUNTA('ST1 Student Attainment percent'!F:F)),_xlfn.LAMBDA(_xlpm.score,_xlfn.IFS(_xlpm.score="NA","NA",_xlpm.score>'OBE Data'!$B$2-1,3,_xlpm.score>'OBE Data'!$B$3-1,2,_xlpm.score>'OBE Data'!$B$4-1,1,_xlpm.score<'OBE Data'!$B$4,0)))} -> NA | G2: {=_xlfn.BYROW('ST1 Student Attainment percent'!G2:INDEX('ST1 Student Attainment percent'!G:G,COUNTA('ST1 Student Attainment percent'!G:G)),_xlfn.LAMBDA(_xlpm.score,_xlfn.IFS(_xlpm.score="NA","NA",_xlpm.score>'OBE Data'!$B$2-1,3,_xlpm.score>'OBE Data'!$B$3-1,2,_xlpm.score>'OBE Data'!$B$4-1,1,_xlpm.score<'OBE Data'!$B$4,0)))} -> 0
A3: 2010992002 | B3: 3 | C3: 3 | D3: 3 | E3: 3 | F3: NA | G3: 3
A4: 2010992004 | B4: 3 | C4: 3 | D4: 3 | E4: 3 | F4: 3 | G4: 3
A5: 2010992005 | B5: 3 | C5: 3 | D5: 3 | E5: 3 | F5: NA | G5: 3
A6: 2010992006 | B6: 3 | C6: 3 | D6: 3 | E6: 3 | F6: 3 | G6: 3
A7: 2010992008 | B7: 3 | C7: 3 | D7: 3 | E7: 3 | F7: 3 | G7: 3
A8: 2010992009 | B8: 3 | C8: 3 | D8: 3 | E8: 3 | F8: 0 | G8: 3
A9: 2010992010 | B9: 3 | C9: 3 | D9: 3 | E9: 3 | F9: 0 | G9: 3
A10: 2010992011 | B10: 3 | C10: 3 | D10: 3 | E10: 3 | F10: 0 | G10: 3
A11: 2010992012 | B11: 3 | C11: 3 | D11: 0 | E11: 3 | F11: 0 | G11: 3
A12: 2010992014 | B12: 3 | C12: 3 | D12: 3 | E12: 3 | F12: 0 | G12: 3
A13: 2010992015 | B13: 3 | C13: 3 | D13: 3 | E13: 3 | F13: 0 | G13: 3
A14: 2010992016 | B14: 0 | C14: 0 | D14: 0 | E14: 0 | F14: 0 | G14: 0
A15: 2010992017 | B15: 3 | C15: 3 | D15: 3 | E15: 3 | F15: 3 | G15: 3
A16: 2010992018 | B16: 3 | C16: 3 | D16: 3 | E16: 3 | F16: 0 | G16: 3
A17: 2010992019 | B17: 0 | C17: 0 | D17: 0 | E17: 3 | F17: 0 | G17: 3
... A19: 2010992202 | B19: 3 | C19: 3 | D19: 3 | E19: 3 | F19: 3 | G19: 3

Sheet ST1 Target Attained
A1: {=INDEX('ST1 Result'!B:B, 1):INDEX('ST1 Result'!B:B, COUNTA('ST1 Result'!B:B) )} -> Admission No. (Roll No.) | B1: {='ST1 Questions'!C1:H1} -> CO1 | C1: CO2 | D1: CO3 | E1: CO4 | F1: CO5 | G1: CO6
A2: 2010990089 | B2: {=_xlfn.BYROW('ST1 Student Attainment percent'!B2:INDEX('ST1 Student Attainment percent'!B:B,COUNTA('ST1 Student Attainment percent'!B:B)),_xlfn.LAMBDA(_xlpm.score,_xlfn.IFS(_xlpm.score="NA","NA",_xlpm.score>='OBE Data'!$B$5,"Y",_xlpm.score<'OBE Data'!$B$5,"N")))} -> N | C2: {=_xlfn.BYROW('ST1 Student Attainment percent'!C2:INDEX('ST1 Student Attainment percent'!C:C,COUNTA('ST1 Student Attainment percent'!C:C)),_xlfn.LAMBDA(_xlpm.score,_xlfn.IFS(_xlpm.score="NA","NA",_xlpm.score>='OBE Data'!$B$5,"Y",_xlpm.score<'OBE Data'!$B$5,"N")))} -> N | D2: {=_xlfn.BYROW('ST1 Student Attainment percent'!D2:INDEX('ST1 Student Attainment percent'!D:D,COUNTA('ST1 Student Attainment percent'!D:D)),_xlfn.LAMBDA(_xlpm.score,_xlfn.IFS(_xlpm.score="NA","NA",_xlpm.score>='OBE Data'!$B$5,"Y",_xlpm.score<'OBE Data'!$B$5,"N")))} -> N | E2: {=_xlfn.BYROW('ST1 Student Attainment percent'!E2:INDEX('ST1 Student Attainment percent'!E:E,COUNTA('ST1 Student Attainment percent'!E:E)),_xlfn.LAMBDA(_xlpm.score,_xlfn.IFS(_xlpm.score="NA","NA",_xlpm.score>='OBE Data'!$B$5,"Y",_xlpm.score<'OBE Data'!$B$5,"N")))} -> N | F2: {=_xlfn.BYROW('ST1 Student Attainment percent'!F2:INDEX('ST1 Student Attainment percent'!F:F,COUNTA('ST1 Student Attainment percent'!F:F)),_xlfn.LAMBDA(_xlpm.score,_xlfn.IFS(_xlpm.score="NA","NA",_xlpm.score>='OBE Data'!$B$5,"Y",_xlpm.score<'OBE Data'!$B$5,"N")))} -> NA | G2: {=_xlfn.BYROW('ST1 Student Attainment percent'!G2:INDEX('ST1 Student Attainment percent'!G:G,COUNTA('ST1 Student Attainment percent'!G:G)),_xlfn.LAMBDA(_xlpm.score,_xlfn.IFS(_xlpm.score="NA","NA",_xlpm.score>='OBE Data'!$B$5,"Y",_xlpm.score<'OBE Data'!$B$5,"N")))} -> N
A3: 2010992002 | B3: Y | C3: Y | D3: Y | E3: Y | F3: NA | G3: Y
A4: 2010992004 | B4: Y | C4: Y | D4: Y | E4: Y | F4: Y | G4: Y
A5: 2010992005 | B5: Y | C5: Y | D5: Y | E5: Y | F5: NA | G5: Y
A6: 2010992006 | B6: Y | C6: Y | D6: Y | E6: Y | F6: Y | G6: Y
A7: 2010992008 | B7: Y | C7: Y | D7: Y | E7: Y | F7: Y | G7: Y
A8: 2010992009 | B8: Y | C8: Y | D8: Y | E8: Y | F8: N | G8: Y
A9: 2010992010 | B9: Y | C9: Y | D9: Y | E9: Y | F9: N | G9: Y
A10: 2010992011 | B10: Y | C10: Y | D10: Y | E10: Y | F10: N | G10: Y
A11: 2010992012 | B11: Y | C11: Y | D11: N | E11: Y | F11: N | G11: Y
A12: 2010992014 | B12: Y | C12: Y | D12: Y | E12: Y | F12: N | G12: Y
A13: 2010992015 | B13: Y | C13: Y | D13: Y | E13: Y | F13: N | G13: Y
A14: 2010992016 | B14: N | C14: N | D14: N | E14: N | F14: N | G14: N
... A19: 2010992202 | B19: Y | C19: Y | D19: Y | E19: Y | F19: Y | G19: Y

Sheet ST2 Questions
A1: {='[1]ST2 Question Map'!$A$1:$H$21} -> Q_Id | B1: Max Marks | C1: CO1 | D1: CO2 | E1: CO3 | F1: CO4 | G1: CO5 | H1: CO6
A2: 1a | B2: 0 | C2: FALSE | D2: FALSE | E2: FALSE | F2: FALSE | G2: FALSE | H2: FALSE
A3: 1b | B3: 0 | C3: FALSE | D3: FALSE | E3: FALSE | F3: FALSE | G3: FALSE | H3: FALSE
A4: 1c | B4: 0 | C4: FALSE | D4: FALSE | E4: FALSE | F4: FALSE | G4: FALSE | H4: FALSE
A5: 1d | B5: 0 | C5: FALSE | D5: FALSE | E5: FALSE | F5: FALSE | G5: FALSE | H5: FALSE
A6: 1e | B6: 0 | C6: FALSE | D6: FALSE | E6: FALSE | F6: FALSE | G6: FALSE | H6: FALSE
A7: Q2 | B7: 0 | C7: FALSE | D7: FALSE | E7: FALSE | F7: FALSE | G7: FALSE | H7: FALSE
A8: Q3 | B8: 0 | C8: FALSE | D8: FALSE | E8: FALSE | F8: FALSE | G8: FALSE | H8: FALSE
A9: Q4 | B9: 0 | C9: FALSE | D9: FALSE | E9: FALSE | F9: FALSE | G9: FALSE | H9: FALSE
A10: Q5 | B10: 0 | C10: FALSE | D10: FALSE | E10: FALSE | F10: FALSE | G10: FALSE | H10: FALSE
A11: Q6 | B11: 0 | C11: FALSE | D11: FALSE | E11: FALSE | F11: FALSE | G11: FALSE | H11: FALSE
A12: Q7 | B12: 0 | C12: FALSE | D12: FALSE | E12: FALSE | F12: FALSE | G12: FALSE | H12: FALSE
A13: Q8 | B13: 0 | C13: FALSE | D13: FALSE | E13: FALSE | F13: FALSE | G13: FALSE | H13: FALSE
... A21: Q16 | B21: 0 | C21: FALSE | D21: FALSE | E21: FALSE | F21: FALSE | G21: FALSE | H21: FALSE

Sheet ST2 Result
A1: {=INDEX('[1]ST2 Result'!$A:$AK, 1, 1):INDEX('[1]ST2 Result'!$AK:$AK,COUNTA('[1]ST2 Result'!$AK:$AK))} -> Sr.no | B1: Admission No. (Roll No.) | C1: Name of Student | D1: Division(Section) | E1: Course Code | F1: Course Name | G1: Lecture Type (Theory/Practical) | H1: Program Name | I1: Department Name | J1: Class Name (Batch) | K1: Semester Name | L1: Exam Name (ETE/ST/FA) | M1: 1a | N1: 1b | O1: 1c | P1: 1d | Q1: 1e | R1: Q2 | S1: Q3 | T1: Q4 | U1: Q5 | V1: Q6 | W1: Q7 | X1: Q8 | Y1: Q9 | Z1: Q10 | AA1: Q11 | AB1: Q12 | AC1: Q13 | AD1: Q14 | AE1: Q15 | AF1: Q16 | AG1: Assignment | AH1: FA1 | AI1: FA2 | AJ1: Total Marks | AK1: max Marks
A2: 1 | B2: 2010990089 | C2: ANSH GARG | D2: 0 | E2: EC112 | F2: Network Analysis and Synthesis | G2: Theory | H2: B.E | I2: ECE | J2: 2020 | K2: 3 | L2: ST2 | M2: U | N2: U | O2: U | P2: U | Q2: U | R2: U | S2: U | T2: U | U2: U | V2: U | W2: U | X2: U | Y2: U | Z2: U | AA2: U | AB2: U | AC2: U | AD2: U | AE2: U | AF2: U | AG2: 7 | AH2: 15 | AI2: 18 | AJ2: 40 | AK2: 50
A3: 2 | B3: 2010992002 | C3: PANSY VERMA | D3: 0 | E3: EC112 | F3: Network Analysis and Synthesis | G3: Theory | H3: B.E | I3: ECE | J3: 2020 | K3: 3 | L3: ST2 | M3: U | N3: U | O3: U | P3: U | Q3: U | R3: U | S3: U | T3: U | U3: U | V3: U | W3: U | X3: U | Y3: U | Z3: U | AA3: U | AB3: U | AC3: U | AD3: U | AE3: U | AF3: U | AG3: 10 | AH3: 16 | AI3: 18 | AJ3: 44 | AK3: 50
A4: 3 | B4: 2010992004 | C4: UTKARSH BHATT | D4: 0 | E4: EC112 | F4: Network Analysis and Synthesis | G4: Theory | H4: B.E | I4: ECE | J4: 2020 | K4: 3 | L4: ST2 | M4: U | N4: U | O4: U | P4: U | Q4: U | R4: U | S4: U | T4: U | U4: U | V4: U | W4: U | X4: U | Y4: U | Z4: U | AA4: U | AB4: U | AC4: U | AD4: U | AE4: U | AF4: U | AG4: 7 | AH4: 15 | AI4: 18 | AJ4: 40 | AK4: 50
A5: 4 | B5: 2010992005 | C5: RATANABH SHARMA | D5: 0 | E5: EC112 | F5: Network Analysis and Synthesis | G5: Theory | H5: B.E | I5: ECE | J5: 2020 | K5: 3 | L5: ST2 | M5: U | N5: U | O5: U | P5: U | Q5: U | R5: U | S5: U | T5: U | U5: U | V5: U | W5: U | X5: U | Y5: U | Z5: U | AA5: U | AB5: U | AC5: U | AD5: U | AE5: U | AF5: U | AG5: 10 | AH5: 17 | AI5: 18 | AJ5: 45 | AK5: 50
A6: 5 | B6: 2010992006 | C6: AYUSH SHARMA | D6: 0 | E6: EC112 | F6: Network Analysis and Synthesis | G6: Theory | H6: B.E | I6: ECE | J6: 2020 | K6: 3 | L6: ST2 | M6: U | N6: U | O6: U | P6: U | Q6: U | R6: U | S6: U | T6: U | U6: U | V6: U | W6: U | X6: U | Y6: U | Z6: U | AA6: U | AB6: U | AC6: U | AD6: U | AE6: U | AF6: U | AG6: 7 | AH6: 14 | AI6: 16 | AJ6: 37 | AK6: 50
A7: 6 | B7: 2010992008 | C7: NAVDEEP SINGH | D7: 0 | E7: EC112 | F7: Network Analysis and Synthesis | G7: Theory | H7: B.E | I7: ECE | J7: 2020 | K7: 3 | L7: ST2 | M7: U | N7: U | O7: U | P7: U | Q7: U | R7: U | S7: U | T7: U | U7: U | V7: U | W7: U | X7: U | Y7: U | Z7: U | AA7: U | AB7: U | AC7: U | AD7: U | AE7: U | AF7: U | AG7: 9 | AH7: 16 | AI7: 18 | AJ7: 43 | AK7: 50
A8: 7 | B8: 2010992009 | C8: RIYA | D8: 0 | E8: EC112 | F8: Network Analysis and Synthesis | G8: Theory | H8: B.E | I8: ECE | J8: 2020 | K8: 3 | L8: ST2 | M8: U | N8: U | O8: U | P8: U | Q8: U | R8: U | S8: U | T8: U | U8: U | V8: U | W8: U | X8: U | Y8: U | Z8: U | AA8: U | AB8: U | AC8: U | AD8: U | AE8: U | AF8: U | AG8: 9 | AH8: 16 | AI8: 18 | AJ8: 43 | AK8: 50
