Workbook

Sheet Output
A1: Course Name | B1: ='[1]ST1 Result'!$F$2 -> Network Analysis and Synthesis | E1: {=Averages!A11:B18} -> Course Outcome | F1: Achieved CO Score | J1: CO Attempts | K1: ST1 | L1: ST2 | M1: ST3 | N1: ` | O1: ASN
A2: Course Code | B2: ='[2]ST1 Result'!$E$2 -> EC112 | E2: CO1 | F2: 3 | J2: CO1 | K2: =COUNTIFS( '[1]ST1 Attempted COs'!$A$2 : INDEX( '[1]ST1 Attempted COs'!$A:$A, COUNTA('[1]ST1 Attempted COs'!$A:$A) ), "<>", '[1]ST1 Attempted COs'!$A$2 : INDEX( '[1]ST1 Attempted COs'!$A:$A, COUNTA('[1]ST1 Attempted COs'!$A:$A) ), "<>Not Found" ) & " (" & TEXT( COUNTIFS( '[1]ST1 Attempted COs'!$A$2 : INDEX( '[1]ST1 Attempted COs'!$A:$A, COUNTA('[1]ST1 Attempted COs'!$A:$A) ), "<>", '[1]ST1 Attempted COs'!$A$2 : INDEX( '[1]ST1 Attempted COs'!$A:$A, COUNTA('[1]ST1 Attempted COs'!$A:$A) ), "<>Not Found" ) / COUNTA( '[1]ST1 Result'!$B$2 : INDEX( '[1]ST1 Result'!$B:$B, COUNTA('[1]ST1 Result'!$B:$B) ) ), "0.00%" ) & ")" -> 18 (100.00%) | L2: =COUNTIFS( '[1]ST2 Attempted COs'!$A$2 : INDEX( '[1]ST2 Attempted COs'!$A:$A, COUNTA('[1]ST2 Attempted COs'!$A:$A) ), "<>", '[1]ST2 Attempted COs'!$A$2 : INDEX( '[1]ST2 Attempted COs'!$A:$A, COUNTA('[1]ST2 Attempted COs'!$A:$A) ), "<>Not Found" ) & " (" & TEXT( COUNTIFS( '[1]ST2 Attempted COs'!$A$2 : INDEX( '[1]ST2 Attempted COs'!$A:$A, COUNTA('[1]ST2 Attempted COs'!$A:$A) ), "<>", '[1]ST2 Attempted COs'!$A$2 : INDEX( '[1]ST2 Attempted COs'!$A:$A, COUNTA('[1]ST2 Attempted COs'!$A:$A) ), "<>Not Found" ) / COUNTA( '[1]ST2 Result'!$B$2 : INDEX( '[1]ST2 Result'!$B:$B, COUNTA('[1]ST2 Result'!$B:$B) ) ), "0.00%" ) & ")" -> 0 (0.00%) | M2: =COUNTIFS( '[1]ST3 Attempted COs'!$A$2 : INDEX( '[1]ST3 Attempted COs'!$A:$A, COUNTA('[1]ST3 Attempted COs'!$A:$A) ), "<>", '[1]ST3 Attempted COs'!$A$2 : INDEX( '[1]ST3 Attempted COs'!$A:$A, COUNTA('[1]ST3 Attempted COs'!$A:$A) ), "<>Not Found" ) & " (" & TEXT( COUNTIFS( '[1]ST3 Attempted COs'!$A$2 : INDEX( '[1]ST3 Attempted COs'!$A:$A, COUNTA('[1]ST3 Attempted COs'!$A:$A) ), "<>", '[1]ST3 Attempted COs'!$A$2 : INDEX( '[1]ST3 Attempted COs'!$A:$A, COUNTA('[1]ST3 Attempted COs'!$A:$A) ), "<>Not Found" ) / COUNTA( '[1]ST3 Result'!$B$2 : INDEX( '[1]ST3 Result'!$B:$B, COUNTA('[1]ST3 Result'!$B:$B) ) ), "0.00%" ) & ")" -> 0 (0.00%) | N2: =COUNTIFS( '[1]ETE Attempted COs'!$A$2 : INDEX( '[1]ETE Attempted COs'!$A:$A, COUNTA('[1]ETE Attempted COs'!$A:$A) ), "<>", '[1]ETE Attempted COs'!$A$2 : INDEX( '[1]ETE Attempted COs'!$A:$A, COUNTA('[1]ETE Attempted COs'!$A:$A) ), "<>Not Found" ) & " (" & TEXT( COUNTIFS( '[1]ETE Attempted COs'!$A$2 : INDEX( '[1]ETE Attempted COs'!$A:$A, COUNTA('[1]ETE Attempted COs'!$A:$A) ), "<>", '[1]ETE Attempted COs'!$A$2 : INDEX( '[1]ETE Attempted COs'!$A:$A, COUNTA('[1]ETE Attempted COs'!$A:$A) ), "<>Not Found" ) / COUNTA( '[1]ETE Result'!$B$2 : INDEX( '[1]ETE Result'!$B:$B, COUNTA('[1]ETE Result'!$B:$B) ) ), "0.00%" ) & ")" -> 18 (100.00%) | O2: =COUNTIFS( '[1]ASN Attempted COs'!$A$2 : INDEX( '[1]ASN Attempted COs'!$A:$A, COUNTA('[1]ASN Attempted COs'!$A:$A) ), "<>", '[1]ASN Attempted COs'!$A$2 : INDEX( '[1]ASN Attempted COs'!$A:$A, COUNTA('[1]ASN Attempted COs'!$A:$A) ), "<>Not Found" ) & " (" & TEXT( COUNTIFS( '[1]ASN Attempted COs'!$A$2 : INDEX( '[1]ASN Attempted COs'!$A:$A, COUNTA('[1]ASN Attempted COs'!$A:$A) ), "<>", '[1]ASN Attempted COs'!$A$2 : INDEX( '[1]ASN Attempted COs'!$A:$A, COUNTA('[1]ASN Attempted COs'!$A:$A) ), "<>Not Found" ) / COUNTA( '[1]ASN Result'!$B$2 : INDEX( '[1]ASN Result'!$B:$B, COUNTA('[1]ASN Result'!$B:$B) ) ), "0.00%" ) & ")" -> 18 (100.00%)
A3: - | B3: - | E3: CO2 | F3: 3 | J3: CO2 | K3: =COUNTIFS( '[1]ST1 Attempted COs'!$B$2 : INDEX( '[1]ST1 Attempted COs'!$B:$B, COUNTA('[1]ST1 Attempted COs'!$B:$B) ), "<>", '[1]ST1 Attempted COs'!$B$2 : INDEX( '[1]ST1 Attempted COs'!$B:$B, COUNTA('[1]ST1 Attempted COs'!$B:$B) ), "<>Not Found" ) & " (" & TEXT( COUNTIFS( '[1]ST1 Attempted COs'!$B$2 : INDEX( '[1]ST1 Attempted COs'!$B:$B, COUNTA('[1]ST1 Attempted COs'!$B:$B) ), "<>", '[1]ST1 Attempted COs'!$B$2 : INDEX( '[1]ST1 Attempted COs'!$B:$B, COUNTA('[1]ST1 Attempted COs'!$B:$B) ), "<>Not Found" ) / COUNTA( '[1]ST1 Result'!$B$2 : INDEX( '[1]ST1 Result'!$B:$B, COUNTA('[1]ST1 Result'!$B:$B) ) ), "0.00%" ) & ")" -> 18 (100.00%) | L3: =COUNTIFS( '[1]ST2 Attempted COs'!$B$2 : INDEX( '[1]ST2 Attempted COs'!$B:$B, COUNTA('[1]ST2 Attempted COs'!$B:$B) ), "<>", '[1]ST2 Attempted COs'!$B$2 : INDEX( '[1]ST2 Attempted COs'!$B:$B, COUNTA('[1]ST2 Attempted COs'!$B:$B) ), "<>Not Found" ) & " (" & TEXT( COUNTIFS( '[1]ST2 Attempted COs'!$B$2 : INDEX( '[1]ST2 Attempted COs'!$B:$B, COUNTA('[1]ST2 Attempted COs'!$B:$B) ), "<>", '[1]ST2 Attempted COs'!$B$2 : INDEX( '[1]ST2 Attempted COs'!$B:$B, COUNTA('[1]ST2 Attempted COs'!$B:$B) ), "<>Not Found" ) / COUNTA( '[1]ST2 Result'!$B$2 : INDEX( '[1]ST2 Result'!$B:$B, COUNTA('[1]ST2 Result'!$B:$B) ) ), "0.00%" ) & ")" -> 0 (0.00%) | M3: =COUNTIFS( '[1]ST3 Attempted COs'!$B$2 : INDEX( '[1]ST3 Attempted COs'!$B:$B, COUNTA('[1]ST3 Attempted COs'!$B:$B) ), "<>", '[1]ST3 Attempted COs'!$B$2 : INDEX( '[1]ST3 Attempted COs'!$B:$B, COUNTA('[1]ST3 Attempted COs'!$B:$B) ), "<>Not Found" ) & " (" & TEXT( COUNTIFS( '[1]ST3 Attempted COs'!$B$2 : INDEX( '[1]ST3 Attempted COs'!$B:$B, COUNTA('[1]ST3 Attempted COs'!$B:$B) ), "<>", '[1]ST3 Attempted COs'!$B$2 : INDEX( '[1]ST3 Attempted COs'!$B:$B, COUNTA('[1]ST3 Attempted COs'!$B:$B) ), "<>Not Found" ) / COUNTA( '[1]ST3 Result'!$B$2 : INDEX( '[1]ST3 Result'!$B:$B, COUNTA('[1]ST3 Result'!$B:$B) ) ), "0.00%" ) & ")" -> 0 (0.00%) | N3: =COUNTIFS( '[1]ETE Attempted COs'!$B$2 : INDEX( '[1]ETE Attempted COs'!$B:$B, COUNTA('[1]ETE Attempted COs'!$B:$B) ), "<>", '[1]ETE Attempted COs'!$B$2 : INDEX( '[1]ETE Attempted COs'!$B:$B, COUNTA('[1]ETE Attempted COs'!$B:$B) ), "<>Not Found" ) & " (" & TEXT( COUNTIFS( '[1]ETE Attempted COs'!$B$2 : INDEX( '[1]ETE Attempted COs'!$B:$B, COUNTA('[1]ETE Attempted COs'!$B:$B) ), "<>", '[1]ETE Attempted COs'!$B$2 : INDEX( '[1]ETE Attempted COs'!$B:$B, COUNTA('[1]ETE Attempted COs'!$B:$B) ), "<>Not Found" ) / COUNTA( '[1]ETE Result'!$B$2 : INDEX( '[1]ETE Result'!$B:$B, COUNTA('[1]ETE Result'!$B:$B) ) ), "0.00%" ) & ")" -> 18 (100.00%) | O3: =COUNTIFS( '[1]ASN Attempted COs'!$B$2 : INDEX( '[1]ASN Attempted COs'!$B:$B, COUNTA('[1]ASN Attempted COs'!$B:$B) ), "<>", '[1]ASN Attempted COs'!$B$2 : INDEX( '[1]ASN Attempted COs'!$B:$B, COUNTA('[1]ASN Attempted COs'!$B:$B) ), "<>Not Found" ) & " (" & TEXT( COUNTIFS( '[1]ASN Attempted COs'!$B$2 : INDEX( '[1]ASN Attempted COs'!$B:$B, COUNTA('[1]ASN Attempted COs'!$B:$B) ), "<>", '[1]ASN Attempted COs'!$B$2 : INDEX( '[1]ASN Attempted COs'!$B:$B, COUNTA('[1]ASN Attempted COs'!$B:$B) ), "<>Not Found" ) / COUNTA( '[1]ASN Result'!$B$2 : INDEX( '[1]ASN Result'!$B:$B, COUNTA('[1]ASN Result'!$B:$B) ) ), "0.00%" ) & ")" -> 18 (100.00%)
A4: CO Score | B4: Student pass percentage required | E4: CO3 | F4: 3 | J4: CO3 | K4: =COUNTIFS( '[1]ST1 Attempted COs'!$C$2 : INDEX( '[1]ST1 Attempted COs'!$C:$C, COUNTA('[1]ST1 Attempted COs'!$C:$C) ), "<>", '[1]ST1 Attempted COs'!$C$2 : INDEX( '[1]ST1 Attempted COs'!$C:$C, COUNTA('[1]ST1 Attempted COs'!$C:$C) ), "<>Not Found" ) & " (" & TEXT( COUNTIFS( '[1]ST1 Attempted COs'!$C$2 : INDEX( '[1]ST1 Attempted COs'!$C:$C, COUNTA('[1]ST1 Attempted COs'!$C:$C) ), "<>", '[1]ST1 Attempted COs'!$C$2 : INDEX( '[1]ST1 Attempted COs'!$C:$C, COUNTA('[1]ST1 Attempted COs'!$C:$C) ), "<>Not Found" ) / COUNTA( '[1]ST1 Result'!$B$2 : INDEX( '[1]ST1 Result'!$B:$B, COUNTA('[1]ST1 Result'!$B:$B) ) ), "0.00%" ) & ")" -> 18 (100.00%) | L4: =COUNTIFS( '[1]ST2 Attempted COs'!$C$2 : INDEX( '[1]ST2 Attempted COs'!$C:$C, COUNTA('[1]ST2 Attempted COs'!$C:$C) ), "<>", '[1]ST2 Attempted COs'!$C$2 : INDEX( '[1]ST2 Attempted COs'!$C:$C, COUNTA('[1]ST2 Attempted COs'!$C:$C) ), "<>Not Found" ) & " (" & TEXT( COUNTIFS( '[1]ST2 Attempted COs'!$C$2 : INDEX( '[1]ST2 Attempted COs'!$C:$C, COUNTA('[1]ST2 Attempted COs'!$C:$C) ), "<>", '[1]ST2 Attempted COs'!$C$2 : INDEX( '[1]ST2 Attempted COs'!$C:$C, COUNTA('[1]ST2 Attempted COs'!$C:$C) ), "<>Not Found" ) / COUNTA( '[1]ST2 Result'!$B$2 : INDEX( '[1]ST2 Result'!$B:$B, COUNTA('[1]ST2 Result'!$B:$B) ) ), "0.00%" ) & ")" -> 0 (0.00%) | M4: =COUNTIFS( '[1]ST3 Attempted COs'!$C$2 : INDEX( '[1]ST3 Attempted COs'!$C:$C, COUNTA('[1]ST3 Attempted COs'!$C:$C) ), "<>", '[1]ST3 Attempted COs'!$C$2 : INDEX( '[1]ST3 Attempted COs'!$C:$C, COUNTA('[1]ST3 Attempted COs'!$C:$C) ), "<>Not Found" ) & " (" & TEXT( COUNTIFS( '[1]ST3 Attempted COs'!$C$2 : INDEX( '[1]ST3 Attempted COs'!$C:$C, COUNTA('[1]ST3 Attempted COs'!$C:$C) ), "<>", '[1]ST3 Attempted COs'!$C$2 : INDEX( '[1]ST3 Attempted COs'!$C:$C, COUNTA('[1]ST3 Attempted COs'!$C:$C) ), "<>Not Found" ) / COUNTA( '[1]ST3 Result'!$B$2 : INDEX( '[1]ST3 Result'!$B:$B, COUNTA('[1]ST3 Result'!$B:$B) ) ), "0.00%" ) & ")" -> 0 (0.00%) | N4: =COUNTIFS( '[1]ETE Attempted COs'!$C$2 : INDEX( '[1]ETE Attempted COs'!$C:$C, COUNTA('[1]ETE Attempted COs'!$C:$C) ), "<>", '[1]ETE Attempted COs'!$C$2 : INDEX( '[1]ETE Attempted COs'!$C:$C, COUNTA('[1]ETE Attempted COs'!$C:$C) ), "<>Not Found" ) & " (" & TEXT( COUNTIFS( '[1]ETE Attempted COs'!$C$2 : INDEX( '[1]ETE Attempted COs'!$C:$C, COUNTA('[1]ETE Attempted COs'!$C:$C) ), "<>", '[1]ETE Attempted COs'!$C$2 : INDEX( '[1]ETE Attempted COs'!$C:$C, COUNTA('[1]ETE Attempted COs'!$C:$C) ), "<>Not Found" ) / COUNTA( '[1]ETE Result'!$B$2 : INDEX( '[1]ETE Result'!$B:$B, COUNTA('[1]ETE Result'!$B:$B) ) ), "0.00%" ) & ")" -> 18 (100.00%) | O4: =COUNTIFS( '[1]ASN Attempted COs'!$C$2 : INDEX( '[1]ASN Attempted COs'!$C:$C, COUNTA('[1]ASN Attempted COs'!$C:$C) ), "<>", '[1]ASN Attempted COs'!$C$2 : INDEX( '[1]ASN Attempted COs'!$C:$C, COUNTA('[1]ASN Attempted COs'!$C:$C) ), "<>Not Found" ) & " (" & TEXT( COUNTIFS( '[1]ASN Attempted COs'!$C$2 : INDEX( '[1]ASN Attempted COs'!$C:$C, COUNTA('[1]ASN Attempted COs'!$C:$C) ), "<>", '[1]ASN Attempted COs'!$C$2 : INDEX( '[1]ASN Attempted COs'!$C:$C, COUNTA('[1]ASN Attempted COs'!$C:$C) ), "<>Not Found" ) / COUNTA( '[1]ASN Result'!$B$2 : INDEX( '[1]ASN Result'!$B:$B, COUNTA('[1]ASN Result'!$B:$B) ) ), "0.00%" ) & ")" -> 18 (100.00%)
A5: 3 | B5: {='[1]OBE Data'!$B$13:$B$15} -> 0.8 | E5: CO4 | F5: 3 | J5: CO4 | K5: =COUNTIFS( '[1]ST1 Attempted COs'!$D$2 : INDEX( '[1]ST1 Attempted COs'!$D:$D, COUNTA('[1]ST1 Attempted COs'!$D:$D) ), "<>", '[1]ST1 Attempted COs'!$D$2 : INDEX( '[1]ST1 Attempted COs'!$D:$D, COUNTA('[1]ST1 Attempted COs'!$D:$D) ), "<>Not Found" ) & " (" & TEXT( COUNTIFS( '[1]ST1 Attempted COs'!$D$2 : INDEX( '[1]ST1 Attempted COs'!$D:$D, COUNTA('[1]ST1 Attempted COs'!$D:$D) ), "<>", '[1]ST1 Attempted COs'!$D$2 : INDEX( '[1]ST1 Attempted COs'!$D:$D, COUNTA('[1]ST1 Attempted COs'!$D:$D) ), "<>Not Found" ) / COUNTA( '[1]ST1 Result'!$B$2 : INDEX( '[1]ST1 Result'!$B:$B, COUNTA('[1]ST1 Result'!$B:$B) ) ), "0.00%" ) & ")" -> 18 (100.00%) | L5: =COUNTIFS( '[1]ST2 Attempted COs'!$D$2 : INDEX( '[1]ST2 Attempted COs'!$D:$D, COUNTA('[1]ST2 Attempted COs'!$D:$D) ), "<>", '[1]ST2 Attempted COs'!$D$2 : INDEX( '[1]ST2 Attempted COs'!$D:$D, COUNTA('[1]ST2 Attempted COs'!$D:$D) ), "<>Not Found" ) & " (" & TEXT( COUNTIFS( '[1]ST2 Attempted COs'!$D$2 : INDEX( '[1]ST2 Attempted COs'!$D:$D, COUNTA('[1]ST2 Attempted COs'!$D:$D) ), "<>", '[1]ST2 Attempted COs'!$D$2 : INDEX( '[1]ST2 Attempted COs'!$D:$D, COUNTA('[1]ST2 Attempted COs'!$D:$D) ), "<>Not Found" ) / COUNTA( '[1]ST2 Result'!$B$2 : INDEX( '[1]ST2 Result'!$B:$B, COUNTA('[1]ST2 Result'!$B:$B) ) ), "0.00%" ) & ")" -> 0 (0.00%) | M5: =COUNTIFS( '[1]ST3 Attempted COs'!$D$2 : INDEX( '[1]ST3 Attempted COs'!$D:$D, COUNTA('[1]ST3 Attempted COs'!$D:$D) ), "<>", '[1]ST3 Attempted COs'!$D$2 : INDEX( '[1]ST3 Attempted COs'!$D:$D, COUNTA('[1]ST3 Attempted COs'!$D:$D) ), "<>Not Found" ) & " (" & TEXT( COUNTIFS( '[1]ST3 Attempted COs'!$D$2 : INDEX( '[1]ST3 Attempted COs'!$D:$D, COUNTA('[1]ST3 Attempted COs'!$D:$D) ), "<>", '[1]ST3 Attempted COs'!$D$2 : INDEX( '[1]ST3 Attempted COs'!$D:$D, COUNTA('[1]ST3 Attempted COs'!$D:$D) ), "<>Not Found" ) / COUNTA( '[1]ST3 Result'!$B$2 : INDEX( '[1]ST3 Result'!$B:$B, COUNTA('[1]ST3 Result'!$B:$B) ) ), "0.00%" ) & ")" -> 0 (0.00%) | N5: =COUNTIFS( '[1]ETE Attempted COs'!$D$2 : INDEX( '[1]ETE Attempted COs'!$D:$D, COUNTA('[1]ETE Attempted COs'!$D:$D) ), "<>", '[1]ETE Attempted COs'!$D$2 : INDEX( '[1]ETE Attempted COs'!$D:$D, COUNTA('[1]ETE Attempted COs'!$D:$D) ), "<>Not Found" ) & " (" & TEXT( COUNTIFS( '[1]ETE Attempted COs'!$D$2 : INDEX( '[1]ETE Attempted COs'!$D:$D, COUNTA('[1]ETE Attempted COs'!$D:$D) ), "<>", '[1]ETE Attempted COs'!$D$2 : INDEX( '[1]ETE Attempted COs'!$D:$D, COUNTA('[1]ETE Attempted COs'!$D:$D) ), "<>Not Found" ) / COUNTA( '[1]ETE Result'!$B$2 : INDEX( '[1]ETE Result'!$B:$B, COUNTA('[1]ETE Result'!$B:$B) ) ), "0.00%" ) & ")" -> 0 (0.00%) | O5: =COUNTIFS( '[1]ASN Attempted COs'!$D$2 : INDEX( '[1]ASN Attempted COs'!$D:$D, COUNTA('[1]ASN Attempted COs'!$D:$D) ), "<>", '[1]ASN Attempted COs'!$D$2 : INDEX( '[1]ASN Attempted COs'!$D:$D, COUNTA('[1]ASN Attempted COs'!$D:$D) ), "<>Not Found" ) & " (" & TEXT( COUNTIFS( '[1]ASN Attempted COs'!$D$2 : INDEX( '[1]ASN Attempted COs'!$D:$D, COUNTA('[1]ASN Attempted COs'!$D:$D) ), "<>", '[1]ASN Attempted COs'!$D$2 : INDEX( '[1]ASN Attempted COs'!$D:$D, COUNTA('[1]ASN Attempted COs'!$D:$D) ), "<>Not Found" ) / COUNTA( '[1]ASN Result'!$B$2 : INDEX( '[1]ASN Result'!$B:$B, COUNTA('[1]ASN Result'!$B:$B) ) ), "0.00%" ) & ")" -> 0 (0.00%)
A6: 2 | B6: 0.7 | E6: CO5 | F6: 3 | J6: CO5 | K6: =COUNTIFS( '[1]ST1 Attempted COs'!$E$2 : INDEX( '[1]ST1 Attempted COs'!$E:$E, COUNTA('[1]ST1 Attempted COs'!$E:$E) ), "<>", '[1]ST1 Attempted COs'!$E$2 : INDEX( '[1]ST1 Attempted COs'!$E:$E, COUNTA('[1]ST1 Attempted COs'!$E:$E) ), "<>Not Found" ) & " (" & TEXT( COUNTIFS( '[1]ST1 Attempted COs'!$E$2 : INDEX( '[1]ST1 Attempted COs'!$E:$E, COUNTA('[1]ST1 Attempted COs'!$E:$E) ), "<>", '[1]ST1 Attempted COs'!$E$2 : INDEX( '[1]ST1 Attempted COs'!$E:$E, COUNTA('[1]ST1 Attempted COs'!$E:$E) ), "<>Not Found" ) / COUNTA( '[1]ST1 Result'!$B$2 : INDEX( '[1]ST1 Result'!$B:$B, COUNTA('[1]ST1 Result'!$B:$B) ) ), "0.00%" ) & ")" -> 15 (83.33%) | L6: =COUNTIFS( '[1]ST2 Attempted COs'!$E$2 : INDEX( '[1]ST2 Attempted COs'!$E:$E, COUNTA('[1]ST2 Attempted COs'!$E:$E) ), "<>", '[1]ST2 Attempted COs'!$E$2 : INDEX( '[1]ST2 Attempted COs'!$E:$E, COUNTA('[1]ST2 Attempted COs'!$E:$E) ), "<>Not Found" ) & " (" & TEXT( COUNTIFS( '[1]ST2 Attempted COs'!$E$2 : INDEX( '[1]ST2 Attempted COs'!$E:$E, COUNTA('[1]ST2 Attempted COs'!$E:$E) ), "<>", '[1]ST2 Attempted COs'!$E$2 : INDEX( '[1]ST2 Attempted COs'!$E:$E, COUNTA('[1]ST2 Attempted COs'!$E:$E) ), "<>Not Found" ) / COUNTA( '[1]ST2 Result'!$B$2 : INDEX( '[1]ST2 Result'!$B:$B, COUNTA('[1]ST2 Result'!$B:$B) ) ), "0.00%" ) & ")" -> 0 (0.00%) | M6: =COUNTIFS( '[1]ST3 Attempted COs'!$E$2 : INDEX( '[1]ST3 Attempted COs'!$E:$E, COUNTA('[1]ST3 Attempted COs'!$E:$E) ), "<>", '[1]ST3 Attempted COs'!$E$2 : INDEX( '[1]ST3 Attempted COs'!$E:$E, COUNTA('[1]ST3 Attempted COs'!$E:$E) ), "<>Not Found" ) & " (" & TEXT( COUNTIFS( '[1]ST3 Attempted COs'!$E$2 : INDEX( '[1]ST3 Attempted COs'!$E:$E, COUNTA('[1]ST3 Attempted COs'!$E:$E) ), "<>", '[1]ST3 Attempted COs'!$E$2 : INDEX( '[1]ST3 Attempted COs'!$E:$E, COUNTA('[1]ST3 Attempted COs'!$E:$E) ), "<>Not Found" ) / COUNTA( '[1]ST3 Result'!$B$2 : INDEX( '[1]ST3 Result'!$B:$B, COUNTA('[1]ST3 Result'!$B:$B) ) ), "0.00%" ) & ")" -> 0 (0.00%) | N6: =COUNTIFS( '[1]ETE Attempted COs'!$E$2 : INDEX( '[1]ETE Attempted COs'!$E:$E, COUNTA('[1]ETE Attempted COs'!$E:$E) ), "<>", '[1]ETE Attempted COs'!$E$2 : INDEX( '[1]ETE Attempted COs'!$E:$E, COUNTA('[1]ETE Attempted COs'!$E:$E) ), "<>Not Found" ) & " (" & TEXT( COUNTIFS( '[1]ETE Attempted COs'!$E$2 : INDEX( '[1]ETE Attempted COs'!$E:$E, COUNTA('[1]ETE Attempted COs'!$E:$E) ), "<>", '[1]ETE Attempted COs'!$E$2 : INDEX( '[1]ETE Attempted COs'!$E:$E, COUNTA('[1]ETE Attempted COs'!$E:$E) ), "<>Not Found" ) / COUNTA( '[1]ETE Result'!$B$2 : INDEX( '[1]ETE Result'!$B:$B, COUNTA('[1]ETE Result'!$B:$B) ) ), "0.00%" ) & ")" -> 0 (0.00%) | O6: =COUNTIFS( '[1]ASN Attempted COs'!$E$2 : INDEX( '[1]ASN Attempted COs'!$E:$E, COUNTA('[1]ASN Attempted COs'!$E:$E) ), "<>", '[1]ASN Attempted COs'!$E$2 : INDEX( '[1]ASN Attempted COs'!$E:$E, COUNTA('[1]ASN Attempted COs'!$E:$E) ), "<>Not Found" ) & " (" & TEXT( COUNTIFS( '[1]ASN Attempted COs'!$E$2 : INDEX( '[1]ASN Attempted COs'!$E:$E, COUNTA('[1]ASN Attempted COs'!$E:$E) ), "<>", '[1]ASN Attempted COs'!$E$2 : INDEX( '[1]ASN Attempted COs'!$E:$E, COUNTA('[1]ASN Attempted COs'!$E:$E) ), "<>Not Found" ) / COUNTA( '[1]ASN Result'!$B$2 : INDEX( '[1]ASN Result'!$B:$B, COUNTA('[1]ASN Result'!$B:$B) ) ), "0.00%" ) & ")" -> 0 (0.00%)
A7: 1 | B7: 0.6 | E7: CO6 | F7: 3 | J7: CO6 | K7: =COUNTIFS( '[1]ST1 Attempted COs'!$F$2 : INDEX( '[1]ST1 Attempted COs'!$F:$F, COUNTA('[1]ST1 Attempted COs'!$F:$F) ), "<>", '[1]ST1 Attempted COs'!$F$2 : INDEX( '[1]ST1 Attempted COs'!$F:$F, COUNTA('[1]ST1 Attempted COs'!$F:$F) ), "<>Not Found" ) &" ("& TEXT( COUNTIFS( '[1]ST1 Attempted COs'!$F$2 : INDEX( '[1]ST1 Attempted COs'!$F:$F, COUNTA('[1]ST1 Attempted COs'!$F:$F) ), "<>", '[1]ST1 Attempted COs'!$F$2 : INDEX( '[1]ST1 Attempted COs'!$F:$F, COUNTA('[1]ST1 Attempted COs'!$F:$F) ), "<>Not Found" ) / COUNTA( '[1]ST1 Result'!$B$2 : INDEX( '[1]ST1 Result'!$B:$B, COUNTA('[1]ST1 Result'!$B:$B) ) ), "0.00%" &")") -> 18 (100.00%) | L7: =COUNTIFS( '[1]ST2 Attempted COs'!$F$2 : INDEX( '[1]ST2 Attempted COs'!$F:$F, COUNTA('[1]ST2 Attempted COs'!$F:$F) ), "<>", '[1]ST2 Attempted COs'!$F$2 : INDEX( '[1]ST2 Attempted COs'!$F:$F, COUNTA('[1]ST2 Attempted COs'!$F:$F) ), "<>Not Found" ) & " (" & TEXT( COUNTIFS( '[1]ST2 Attempted COs'!$F$2 : INDEX( '[1]ST2 Attempted COs'!$F:$F, COUNTA('[1]ST2 Attempted COs'!$F:$F) ), "<>", '[1]ST2 Attempted COs'!$F$2 : INDEX( '[1]ST2 Attempted COs'!$F:$F, COUNTA('[1]ST2 Attempted COs'!$F:$F) ), "<>Not Found" ) / COUNTA( '[1]ST2 Result'!$B$2 : INDEX( '[1]ST2 Result'!$B:$B, COUNTA('[1]ST2 Result'!$B:$B) ) ), "0.00%" ) & ")" -> 0 (0.00%) | M7: =COUNTIFS( '[1]ST3 Attempted COs'!$F$2 : INDEX( '[1]ST3 Attempted COs'!$F:$F, COUNTA('[1]ST3 Attempted COs'!$F:$F) ), "<>", '[1]ST3 Attempted COs'!$F$2 : INDEX( '[1]ST3 Attempted COs'!$F:$F, COUNTA('[1]ST3 Attempted COs'!$F:$F) ), "<>Not Found" ) & " (" & TEXT( COUNTIFS( '[1]ST3 Attempted COs'!$F$2 : INDEX( '[1]ST3 Attempted COs'!$F:$F, COUNTA('[1]ST3 Attempted COs'!$F:$F) ), "<>", '[1]ST3 Attempted COs'!$F$2 : INDEX( '[1]ST3 Attempted COs'!$F:$F, COUNTA('[1]ST3 Attempted COs'!$F:$F) ), "<>Not Found" ) / COUNTA( '[1]ST3 Result'!$B$2 : INDEX( '[1]ST3 Result'!$B:$B, COUNTA('[1]ST3 Result'!$B:$B) ) ), "0.00%" ) & ")" -> 0 (0.00%) | N7: =COUNTIFS( '[1]ETE Attempted COs'!$F$2 : INDEX( '[1]ETE Attempted COs'!$F:$F, COUNTA('[1]ETE Attempted COs'!$F:$F) ), "<>", '[1]ETE Attempted COs'!$F$2 : INDEX( '[1]ETE Attempted COs'!$F:$F, COUNTA('[1]ETE Attempted COs'!$F:$F) ), "<>Not Found" ) & " (" & TEXT( COUNTIFS( '[1]ETE Attempted COs'!$F$2 : INDEX( '[1]ETE Attempted COs'!$F:$F, COUNTA('[1]ETE Attempted COs'!$F:$F) ), "<>", '[1]ETE Attempted COs'!$F$2 : INDEX( '[1]ETE Attempted COs'!$F:$F, COUNTA('[1]ETE Attempted COs'!$F:$F) ), "<>Not Found" ) / COUNTA( '[1]ETE Result'!$B$2 : INDEX( '[1]ETE Result'!$B:$B, COUNTA('[1]ETE Result'!$B:$B) ) ), "0.00%" ) & ")" -> 0 (0.00%) | O7: =COUNTIFS( '[1]ASN Attempted COs'!$F$2 : INDEX( '[1]ASN Attempted COs'!$F:$F, COUNTA('[1]ASN Attempted COs'!$F:$F) ), "<>", '[1]ASN Attempted COs'!$F$2 : INDEX( '[1]ASN Attempted COs'!$F:$F, COUNTA('[1]ASN Attempted COs'!$F:$F) ), "<>Not Found" ) & " (" & TEXT( COUNTIFS( '[1]ASN Attempted COs'!$F$2 : INDEX( '[1]ASN Attempted COs'!$F:$F, COUNTA('[1]ASN Attempted COs'!$F:$F) ), "<>", '[1]ASN Attempted COs'!$F$2 : INDEX( '[1]ASN Attempted COs'!$F:$F, COUNTA('[1]ASN Attempted COs'!$F:$F) ), "<>Not Found" ) / COUNTA( '[1]ASN Result'!$B$2 : INDEX( '[1]ASN Result'!$B:$B, COUNTA('[1]ASN Result'!$B:$B) ) ), "0.00%" ) & ")" -> 0 (0.00%)
A8: Target Threshold | B8: ='[1]OBE Data'!$B$5&"%" -> 60% | E8: Overall Attainment | F8: 3 | J8: Strength Of Class | K8: =COUNTA('[1]ST1 Result'!$B$2:INDEX('[1]ST1 Result'!$B:$B,COUNTA('[1]ST1 Result'!B:B))) -> 18 | L8: =COUNTA('[1]ST1 Result'!$B$2:INDEX('[1]ST1 Result'!$B:$B,COUNTA('[1]ST1 Result'!C:C))) -> 18 | M8: =COUNTA('[1]ST1 Result'!$B$2:INDEX('[1]ST1 Result'!$B:$B,COUNTA('[1]ST1 Result'!D:D))) -> 18 | N8: =COUNTA('[1]ST1 Result'!$B$2:INDEX('[1]ST1 Result'!$B:$B,COUNTA('[1]ST1 Result'!E:E))) -> 18 | O8: =COUNTA('[1]ST1 Result'!$B$2:INDEX('[1]ST1 Result'!$B:$B,COUNTA('[1]ST1 Result'!F:F))) -> 18
A9: Exam | B9: ST1 | N9: ST2 | Z9: ST3 | AL9: ETE | AX9: ASN | BJ9: Overall
A10: {='[1]ST1 Result'!$B$1:INDEX('[1]ST1 Result'!$B:$B,COUNTA('[1]ST1 Result'!$B:$B))} -> Admission No. (Roll No.) | B10: CO1 | D10: CO2 | F10: CO3 | H10: CO4 | J10: CO5 | L10: CO6 | N10: CO1 | P10: CO2 | R10: CO3 | T10: CO4 | V10: CO5 | X10: CO6 | Z10: CO1 | AB10: CO2 | AD10: CO3 | AF10: CO4 | AH10: CO5 | AJ10: CO6 | AL10: CO1 | AN10: CO2 | AP10: CO3 | AR10: CO4 | AT10: CO5 | AV10: CO6 | AX10: CO1 | AZ10: CO2 | BB10: CO3 | BD10: CO4 | BF10: CO5 | BH10: CO6 | BJ10: CO1 | BL10: CO2 | BN10: CO3 | BP10: CO4 | BR10: CO5 | BT10: CO6
A11: 2010990089 | B11: {=IFERROR(ROUND('[1]ST1 Student Attainment percent'!$B$2:INDEX('[1]ST1 Student Attainment percent'!$B:$B,COUNTA('[1]ST1 Student Attainment percent'!$B:$B)),2),"NA")} -> 38.89 | C11: {='[1]ST1 Target Attained'!$B$2:INDEX('[1]ST1 Target Attained'!$B:$B,COUNTA('[1]ST1 Target Attained'!$B:$B))} -> N | D11: {=IFERROR(ROUND('[1]ST1 Student Attainment percent'!$C$2:INDEX('[1]ST1 Student Attainment percent'!$C:$C,COUNTA('[1]ST1 Student Attainment percent'!$C:$C)),2),"NA")} -> 36.36 | E11: {='[1]ST1 Target Attained'!$C$2:INDEX('[1]ST1 Target Attained'!$C:$C,COUNTA('[1]ST1 Target Attained'!$C:$C))} -> N | F11: {=IFERROR(ROUND('[1]ST1 Student Attainment percent'!$D$2:INDEX('[1]ST1 Student Attainment percent'!$D:$D,COUNTA('[1]ST1 Student Attainment percent'!$D:$D)),2),"NA")} -> 35.29 | G11: {='[1]ST1 Target Attained'!$D$2:INDEX('[1]ST1 Target Attained'!$D:$D,COUNTA('[1]ST1 Target Attained'!$D:$D))} -> N | H11: {=IFERROR(ROUND('[1]ST1 Student Attainment percent'!$E$2:INDEX('[1]ST1 Student Attainment percent'!$E:$E,COUNTA('[1]ST1 Student Attainment percent'!$E:$E)),2),"NA")} -> 45.45 | I11: {='[1]ST1 Target Attained'!$E$2:INDEX('[1]ST1 Target Attained'!$E:$E,COUNTA('[1]ST1 Target Attained'!$E:$E))} -> N | J11: {=IFERROR(ROUND('[1]ST1 Student Attainment percent'!$F$2:INDEX('[1]ST1 Student Attainment percent'!$F:$F,COUNTA('[1]ST1 Student Attainment percent'!$F:$F)),2),"NA")} -> NA | K11: {='[1]ST1 Target Attained'!$F$2:INDEX('[1]ST1 Target Attained'!$F:$F,COUNTA('[1]ST1 Target Attained'!$F:$F))} -> NA | L11: {=IFERROR(ROUND('[1]ST1 Student Attainment percent'!$G$2:INDEX('[1]ST1 Student Attainment percent'!$G:$G,COUNTA('[1]ST1 Student Attainment percent'!$G:$G)),2),"NA")} -> 53.33 | M11: {='[1]ST1 Target Attained'!$G$2:INDEX('[1]ST1 Target Attained'!$G:$G,COUNTA('[1]ST1 Target Attained'!$G:$G))} -> N | N11: {=IFERROR(ROUND('[1]ST2 Student Attainment percent'!$B$2:INDEX('[1]ST2 Student Attainment percent'!$B:$B,COUNTA('[1]ST2 Student Attainment percent'!$B:$B)),2),"NA")} -> NA | O11: {='[1]ST2 Target Attained'!$B$2:INDEX('[1]ST2 Target Attained'!$B:$B,COUNTA('[1]ST2 Target Attained'!$B:$B))} -> Y | P11: {=IFERROR(ROUND('[1]ST2 Student Attainment percent'!$C$2:INDEX('[1]ST2 Student Attainment percent'!$C:$C,COUNTA('[1]ST2 Student Attainment percent'!$C:$C)),2),"NA")} -> NA | Q11: {='[1]ST2 Target Attained'!$C$2:INDEX('[1]ST2 Target Attained'!$C:$C,COUNTA('[1]ST2 Target Attained'!$C:$C))} -> NA | R11: {=IFERROR(ROUND('[1]ST2 Student Attainment percent'!$D$2:INDEX('[1]ST2 Student Attainment percent'!$D:$D,COUNTA('[1]ST2 Student Attainment percent'!$D:$D)),2),"NA")} -> NA | S11: {='[1]ST2 Target Attained'!$D$2:INDEX('[1]ST2 Target Attained'!$D:$D,COUNTA('[1]ST2 Target Attained'!$D:$D))} -> NA | T11: {=IFERROR(ROUND('[1]ST2 Student Attainment percent'!$E$2:INDEX('[1]ST2 Student Attainment percent'!$E:$E,COUNTA('[1]ST2 Student Attainment percent'!$E:$E)),2),"NA")} -> NA | U11: {='[1]ST2 Target Attained'!$E$2:INDEX('[1]ST2 Target Attained'!$E:$E,COUNTA('[1]ST2 Target Attained'!$E:$E))} -> NA | V11: {=IFERROR(ROUND('[1]ST2 Student Attainment percent'!$F$2:INDEX('[1]ST2 Student Attainment percent'!$F:$F,COUNTA('[1]ST2 Student Attainment percent'!$F:$F)),2),"NA")} -> NA | W11: {='[1]ST2 Target Attained'!$F$2:INDEX('[1]ST2 Target Attained'!$F:$F,COUNTA('[1]ST2 Target Attained'!$F:$F))} -> NA | X11: {=IFERROR(ROUND('[1]ST2 Student Attainment percent'!$G$2:INDEX('[1]ST2 Student Attainment percent'!$G:$G,COUNTA('[1]ST2 Student Attainment percent'!$G:$G)),2),"NA")} -> NA | Y11: {='[1]ST2 Target Attained'!$G$2:INDEX('[1]ST2 Target Attained'!$G:$G,COUNTA('[1]ST2 Target Attained'!$G:$G))} -> NA | Z11: {=IFERROR(ROUND('[1]ST3 Student Attainment percent'!$B$2:INDEX('[1]ST3 Student Attainment percent'!$B:$B,COUNTA('[1]ST3 Student Attainment percent'!$B:$B)),2),"NA")} -> NA | AA11: {='[1]ST3 Target Attained'!$B$2:INDEX('[1]ST3 Target Attained'!$B:$B,COUNTA('[1]ST3 Target Attained'!$B:$B))} -> NA | AB11: {=IFERROR(ROUND('[1]ST3 Student Attainment percent'!$C$2:INDEX('[1]ST3 Student Attainment percent'!$C:$C,COUNTA('[1]ST3 Student Attainment percent'!$C:$C)),2),"NA")} -> NA | AC11: {='[1]ST3 Target Attained'!$C$2:INDEX('[1]ST3 Target Attained'!$C:$C,COUNTA('[1]ST3 Target Attained'!$C:$C))} -> NA | AD11: {=IFERROR(ROUND('[1]ST3 Student Attainment percent'!$D$2:INDEX('[1]ST3 Student Attainment percent'!$D:$D,COUNTA('[1]ST3 Student Attainment percent'!$D:$D)),2),"NA")} -> NA | AE11: {='[1]ST3 Target Attained'!$D$2:INDEX('[1]ST3 Target Attained'!$D:$D,COUNTA('[1]ST3 Target Attained'!$D:$D))} -> NA | AF11: {=IFERROR(ROUND('[1]ST3 Student Attainment percent'!$E$2:INDEX('[1]ST3 Student Attainment percent'!$E:$E,COUNTA('[1]ST3 Student Attainment percent'!$E:$E)),2),"NA")} -> NA | AG11: {='[1]ST3 Target Attained'!$E$2:INDEX('[1]ST3 Target Attained'!$E:$E,COUNTA('[1]ST3 Target Attained'!$E:$E))} -> NA | AH11: {=IFERROR(ROUND('[1]ST3 Student Attainment percent'!$F$2:INDEX('[1]ST3 Student Attainment percent'!$F:$F,COUNTA('[1]ST3 Student Attainment percent'!$F:$F)),2),"NA")} -> NA | AI11: {='[1]ST3 Target Attained'!$F$2:INDEX('[1]ST3 Target Attained'!$F:$F,COUNTA('[1]ST3 Target Attained'!$F:$F))} -> NA | AJ11: {=IFERROR(ROUND('[1]ST3 Student Attainment percent'!$G$2:INDEX('[1]ST3 Student Attainment percent'!$G:$G,COUNTA('[1]ST3 Student Attainment percent'!$G:$G)),2),"NA")} -> NA | AK11: {='[1]ST3 Target Attained'!$G$2:INDEX('[1]ST3 Target Attained'!$G:$G,COUNTA('[1]ST3 Target Attained'!$G:$G))} -> NA | AL11: {=IFERROR(ROUND('[1]ETE Student Attainment percent'!$B$2:INDEX('[1]ETE Student Attainment percent'!$B:$B,COUNTA('[1]ETE Student Attainment percent'!$B:$B)),2),"NA")} -> 75 | AM11: {='[1]ETE Target Attained'!$B$2:INDEX('[1]ETE Target Attained'!$B:$B,COUNTA('[1]ETE Target Attained'!$B:$B))} -> Y | AN11: {=IFERROR(ROUND('[1]ETE Student Attainment percent'!$C$2:INDEX('[1]ETE Student Attainment percent'!$C:$C,COUNTA('[1]ETE Student Attainment percent'!$C:$C)),2),"NA")} -> 75 | AO11: {='[1]ETE Target Attained'!$C$2:INDEX('[1]ETE Target Attained'!$C:$C,COUNTA('[1]ETE Target Attained'!$C:$C))} -> Y | AP11: {=IFERROR(ROUND('[1]ETE Student Attainment percent'!$D$2:INDEX('[1]ETE Student Attainment percent'!$D:$D,COUNTA('[1]ETE Student Attainment percent'!$D:$D)),2),"NA")} -> 75 | AQ11: {='[1]ETE Target Attained'!$D$2:INDEX('[1]ETE Target Attained'!$D:$D,COUNTA('[1]ETE Target Attained'!$D:$D))} -> Y | AR11: {=IFERROR(ROUND('[1]ETE Student Attainment percent'!$E$2:INDEX('[1]ETE Student Attainment percent'!$E:$E,COUNTA('[1]ETE Student Attainment percent'!$E:$E)),2),"NA")} -> NA | AS11: {='[1]ETE Target Attained'!$E$2:INDEX('[1]ETE Target Attained'!$E:$E,COUNTA('[1]ETE Target Attained'!$E:$E))} -> Y | AT11: {=IFERROR(ROUND('[1]ETE Student Attainment percent'!$F$2:INDEX('[1]ETE Student Attainment percent'!$F:$F,COUNTA('[1]ETE Student Attainment percent'!$F:$F)),2),"NA")} -> NA | AU11: {='[1]ETE Target Attained'!$F$2:INDEX('[1]ETE Target Attained'!$F:$F,COUNTA('[1]ETE Target Attained'!$F:$F))} -> Y | AV11: {=IFERROR(ROUND('[1]ETE Student Attainment percent'!$G$2:INDEX('[1]ETE Student Attainment percent'!$G:$G,COUNTA('[1]ETE Student Attainment percent'!$G:$G)),2),"NA")} -> NA | AW11: {='[1]ETE Target Attained'!$G$2:INDEX('[1]ETE Target Attained'!$G:$G,COUNTA('[1]ETE Target Attained'!$G:$G))} -> Y | AX11: {=IFERROR(ROUND('[1]ASN Student Attainment percent'!$B$2:INDEX('[1]ASN Student Attainment percent'!$B:$B,COUNTA('[1]ASN Student Attainment percent'!$B:$B)),2),"NA")} -> 66.67 | AY11: {='[1]ASN Target Attained'!$B$2:INDEX('[1]ASN Target Attained'!$B:$B,COUNTA('[1]ASN Target Attained'!$B:$B))} -> Y | AZ11: {=IFERROR(ROUND('[1]ASN Student Attainment percent'!$C$2:INDEX('[1]ASN Student Attainment percent'!$C:$C,COUNTA('[1]ASN Student Attainment percent'!$C:$C)),2),"NA")} -> 66.67 | BA11: {='[1]ASN Target Attained'!$C$2:INDEX('[1]ASN Target Attained'!$C:$C,COUNTA('[1]ASN Target Attained'!$C:$C))} -> Y | BB11: {=IFERROR(ROUND('[1]ASN Student Attainment percent'!$D$2:INDEX('[1]ASN Student Attainment percent'!$D:$D,COUNTA('[1]ASN Student Attainment percent'!$D:$D)),2),"NA")} -> 80 | BC11: {='[1]ASN Target Attained'!$D$2:INDEX('[1]ASN Target Attained'!$D:$D,COUNTA('[1]ASN Target Attained'!$D:$D))} -> Y | BD11: {=IFERROR(ROUND('[1]ASN Student Attainment percent'!$E$2:INDEX('[1]ASN Student Attainment percent'!$E:$E,COUNTA('[1]ASN Student Attainment percent'!$E:$E)),2),"NA")} -> NA | BE11: {='[1]ASN Target Attained'!$E$2:INDEX('[1]ASN Target Attained'!$E:$E,COUNTA('[1]ASN Target Attained'!$E:$E))} -> Y | BF11: {=IFERROR(ROUND('[1]ASN Student Attainment percent'!$F$2:INDEX('[1]ASN Student Attainment percent'!$F:$F,COUNTA('[1]ASN Student Attainment percent'!$F:$F)),2),"NA")} -> NA | BG11: {='[1]ASN Target Attained'!$F$2:INDEX('[1]ASN Target Attained'!$F:$F,COUNTA('[1]ASN Target Attained'!$F:$F))} -> Y | BH11: {=IFERROR(ROUND('[1]ASN Student Attainment percent'!$G$2:INDEX('[1]ASN Student Attainment percent'!$G:$G,COUNTA('[1]ASN Student Attainment percent'!$G:$G)),2),"NA")} -> NA | BI11: {='[1]ASN Target Attained'!$G$2:INDEX('[1]ASN Target Attained'!$G:$G,COUNTA('[1]ASN Target Attained'!$G:$G))} -> Y | BJ11: {=_xlfn.BYROW($A$11:INDEX($A:$A,COUNTA($A:$A)),_xlfn.LAMBDA(_xlpm.row,IFERROR(IFERROR(AVERAGE(INDEX(B:B,ROW(_xlpm.row)),INDEX(N:N,ROW(_xlpm.row)),INDEX(Z:Z,ROW(_xlpm.row)))*'[1]OBE Data'!$B$9+INDEX(AL:AL,ROW(_xlpm.row))*'[1]OBE Data'!$B$10,SUM(AVERAGE(INDEX(B:B,ROW(_xlpm.row)),INDEX(N:N,ROW(_xlpm.row)),INDEX(Z:Z,ROW(_xlpm.row))),INDEX(AL:AL,ROW(_xlpm.row)))),"NA")))} -> 60.556 | BK11: {=_xlfn.BYROW($A$11:INDEX($A:$A,COUNTA($A:$A)),_xlfn.LAMBDA(_xlpm.row,_xlfn.IFS(INDEX(BJ:BJ,ROW(_xlpm.row))="NA","NA",INDEX(BJ:BJ,ROW(_xlpm.row))>='[1]OBE Data'!$B$5,"Y",INDEX(BJ:BJ,ROW(_xlpm.row))<'[1]OBE Data'!$B$5,"N")))} -> Y | BL11: {=_xlfn.BYROW($A$11:INDEX($A:$A,COUNTA($A:$A)),_xlfn.LAMBDA(_xlpm.row,IFERROR(IFERROR(AVERAGE(INDEX(D:D,ROW(_xlpm.row)),INDEX(P:P,ROW(_xlpm.row)),INDEX(AB:AB,ROW(_xlpm.row)))*'[1]OBE Data'!$B$9+INDEX(AN:AN,ROW(_xlpm.row))*'[1]OBE Data'!$B$10,SUM(AVERAGE(INDEX(D:D,ROW(_xlpm.row)),INDEX(P:P,ROW(_xlpm.row)),INDEX(AB:AB,ROW(_xlpm.row))),INDEX(AN:AN,ROW(_xlpm.row)))),"NA")))} -> 59.544 | BM11: {=_xlfn.BYROW($A$11:INDEX($A:$A,COUNTA($A:$A)),_xlfn.LAMBDA(_xlpm.row,_xlfn.IFS(INDEX(BL:BL,ROW(_xlpm.row))="NA","NA",INDEX(BL:BL,ROW(_xlpm.row))>='[1]OBE Data'!$B$5,"Y",INDEX(BL:BL,ROW(_xlpm.row))<'[1]OBE Data'!$B$5,"N")))} -> N | BN11: {=_xlfn.BYROW($A$11:INDEX($A:$A,COUNTA($A:$A)),_xlfn.LAMBDA(_xlpm.row,IFERROR(IFERROR(AVERAGE(INDEX(F:F,ROW(_xlpm.row)),INDEX(R:R,ROW(_xlpm.row)),INDEX(AD:AD,ROW(_xlpm.row)))*'[1]OBE Data'!$B$9+INDEX(AP:AP,ROW(_xlpm.row))*'[1]OBE Data'!$B$10,SUM(AVERAGE(INDEX(F:F,ROW(_xlpm.row)),INDEX(R:R,ROW(_xlpm.row)),INDEX(AD:AD,ROW(_xlpm.row))),INDEX(AP:AP,ROW(_xlpm.row)))),"NA")))} -> 59.116 | BO11: {=_xlfn.BYROW($A$11:INDEX($A:$A,COUNTA($A:$A)),_xlfn.LAMBDA(_xlpm.row,_xlfn.IFS(INDEX(BN:BN,ROW(_xlpm.row))="NA","NA",INDEX(BN:BN,ROW(_xlpm.row))>='[1]OBE Data'!$B$5,"Y",INDEX(BN:BN,ROW(_xlpm.row))<'[1]OBE Data'!$B$5,"N")))} -> N | BP11: {=_xlfn.BYROW($A$11:INDEX($A:$A,COUNTA($A:$A)),_xlfn.LAMBDA(_xlpm.row,IFERROR(IFERROR(AVERAGE(INDEX(H:H,ROW(_xlpm.row)),INDEX(T:T,ROW(_xlpm.row)),INDEX(AF:AF,ROW(_xlpm.row)))*'[1]OBE Data'!$B$9+INDEX(AR:AR,ROW(_xlpm.row))*'[1]OBE Data'!$B$10,SUM(AVERAGE(INDEX(H:H,ROW(_xlpm.row)),INDEX(T:T,ROW(_xlpm.row)),INDEX(AF:AF,ROW(_xlpm.row))),INDEX(AR:AR,ROW(_xlpm.row)))),"NA")))} -> 45.45 | BQ11: {=_xlfn.BYROW($A$11:INDEX($A:$A,COUNTA($A:$A)),_xlfn.LAMBDA(_xlpm.row,_xlfn.IFS(INDEX(BP:BP,ROW(_xlpm.row))="NA","NA",INDEX(BP:BP,ROW(_xlpm.row))>='[1]OBE Data'!$B$5,"Y",INDEX(BP:BP,ROW(_xlpm.row))<'[1]OBE Data'!$B$5,"N")))} -> N | BR11: {=_xlfn.BYROW($A$11:INDEX($A:$A,COUNTA($A:$A)),_xlfn.LAMBDA(_xlpm.row,IFERROR(IFERROR(AVERAGE(INDEX(J:J,ROW(_xlpm.row)),INDEX(V:V,ROW(_xlpm.row)),INDEX(AH:AH,ROW(_xlpm.row)))*'[1]OBE Data'!$B$9+INDEX(AT:AT,ROW(_xlpm.row))*'[1]OBE Data'!$B$10,SUM(AVERAGE(INDEX(J:J,ROW(_xlpm.row)),INDEX(V:V,ROW(_xlpm.row)),INDEX(AH:AH,ROW(_xlpm.row))),INDEX(AT:AT,ROW(_xlpm.row)))),"NA")))} -> NA | BS11: {=_xlfn.BYROW($A$11:INDEX($A:$A,COUNTA($A:$A)),_xlfn.LAMBDA(_xlpm.row,_xlfn.IFS(INDEX(BR:BR,ROW(_xlpm.row))="NA","NA",INDEX(BR:BR,ROW(_xlpm.row))>='[1]OBE Data'!$B$5,"Y",INDEX(BR:BR,ROW(_xlpm.row))<'[1]OBE Data'!$B$5,"N")))} -> NA | BT11: {=_xlfn.BYROW($A$11:INDEX($A:$A,COUNTA($A:$A)),_xlfn.LAMBDA(_xlpm.row,IFERROR(IFERROR(AVERAGE(INDEX(L:L,ROW(_xlpm.row)),INDEX(X:X,ROW(_xlpm.row)),INDEX(AJ:AJ,ROW(_xlpm.row)))*'[1]OBE Data'!$B$9+INDEX(AV:AV,ROW(_xlpm.row))*'[1]OBE Data'!$B$10,SUM(AVERAGE(INDEX(L:L,ROW(_xlpm.row)),INDEX(X:X,ROW(_xlpm.row)),INDEX(AJ:AJ,ROW(_xlpm.row))),INDEX(AV:AV,ROW(_xlpm.row)))),"NA")))} -> 53.33 | BU11: {=_xlfn.BYROW($A$11:INDEX($A:$A,COUNTA($A:$A)),_xlfn.LAMBDA(_xlpm.row,_xlfn.IFS(INDEX(BT:BT,ROW(_xlpm.row))="NA","NA",INDEX(BT:BT,ROW(_xlpm.row))>='[1]OBE Data'!$B$5,"Y",INDEX(BT:BT,ROW(_xlpm.row))<'[1]OBE Data'!$B$5,"N")))} -> N
A12: 2010992002 | B12: 94.44 | C12: Y | D12: 95.45 | E12: Y | F12: 100 | G12: Y | H12: 90.91 | I12: Y | J12: NA | K12: NA | L12: 93.33 | M12: Y | N12: NA | O12: Y | P12: NA | Q12: NA | R12: NA | S12: NA | T12: NA | U12: NA | V12: NA | W12: NA | X12: NA | Y12: NA | Z12: NA | AA12: NA | AB12: NA | AC12: NA | AD12: NA | AE12: NA | AF12: NA | AG12: NA | AH12: NA | AI12: NA | AJ12: NA | AK12: NA | AL12: 78.33 | AM12: Y | AN12: 78.33 | AO12: Y | AP12: 78.33 | AQ12: Y | AR12: NA | AS12: Y | AT12: NA | AU12: Y | AV12: NA | AW12: Y | AX12: 73.33 | AY12: Y | AZ12: 73.33 | BA12: Y | BB12: 88 | BC12: Y | BD12: NA | BE12: Y | BF12: NA | BG12: Y | BH12: NA | BI12: Y | BJ12: 84.774 | BK12: Y | BL12: 85.178 | BM12: Y | BN12: 86.998 | BO12: Y | BP12: 90.91 | BQ12: Y | BR12: NA | BS12: NA | BT12: 93.33 | BU12: Y
A13: 2010992004 | B13: 70 | C13: Y | D13: 69.23 | E13: Y | F13: 70.59 | G13: Y | H13: 68.18 | I13: Y | J13: 100 | K13: Y | L13: 66.67 | M13: Y | N13: NA | O13: Y | P13: NA | Q13: NA | R13: NA | S13: NA | T13: NA | U13: NA | V13: NA | W13: NA | X13: NA | Y13: NA | Z13: NA | AA13: NA | AB13: NA | AC13: NA | AD13: NA | AE13: NA | AF13: NA | AG13: NA | AH13: NA | AI13: NA | AJ13: NA | AK13: NA | AL13: 76.67 | AM13: Y | AN13: 76.67 | AO13: Y | AP13: 76.67 | AQ13: Y | AR13: NA | AS13: Y | AT13: NA | AU13: Y | AV13: NA | AW13: Y | AX13: 66.67 | AY13: Y | AZ13: 66.67 | BA13: Y | BB13: 80 | BC13: Y | BD13: NA | BE13: Y | BF13: NA | BG13: Y | BH13: NA | BI13: Y | BJ13: 74.002 | BK13: Y | BL13: 73.694 | BM13: Y | BN13: 74.238 | BO13: Y | BP13: 68.18 | BQ13: Y | BR13: 100 | BS13: Y | BT13: 66.67 | BU13: Y
A14: 2010992005 | B14: 69.44 | C14: Y | D14: 72.73 | E14: Y | F14: 76.47 | G14: Y | H14: 72.73 | I14: Y | J14: NA | K14: NA | L14: 73.33 | M14: Y | N14: NA | O14: Y | P14: NA | Q14: NA | R14: NA | S14: NA | T14: NA | U14: NA | V14: NA | W14: NA | X14: NA | Y14: NA | Z14: NA | AA14: NA | AB14: NA | AC14: NA | AD14: NA | AE14: NA | AF14: NA | AG14: NA | AH14: NA | AI14: NA | AJ14: NA | AK14: NA | AL14: 71.67 | AM14: Y | AN14: 71.67 | AO14: Y | AP14: 71.67 | AQ14: Y | AR14: NA | AS14: Y | AT14: NA | AU14: Y | AV14: NA | AW14: Y | AX14: 75 | AY14: Y | AZ14: 75 | BA14: Y | BB14: 90 | BC14: Y | BD14: NA | BE14: Y | BF14: NA | BG14: Y | BH14: NA | BI14: Y | BJ14: 70.778 | BK14: Y | BL14: 72.094 | BM14: Y | BN14: 73.59 | BO14: Y | BP14: 72.73 | BQ14: Y | BR14: NA | BS14: NA | BT14: 73.33 | BU14: Y
A15: 2010992006 | B15: 70 | C15: Y | D15: 69.23 | E15: Y | F15: 70.59 | G15: Y | H15: 68.18 | I15: Y | J15: 100 | K15: Y | L15: 66.67 | M15: Y | N15: NA | O15: Y | P15: NA | Q15: NA | R15: NA | S15: NA | T15: NA | U15: NA | V15: NA | W15: NA | X15: NA | Y15: NA | Z15: NA | AA15: NA | AB15: NA | AC15: NA | AD15: NA | AE15: NA | AF15: NA | AG15: NA | AH15: NA | AI15: NA | AJ15: NA | AK15: NA | AL15: 80 | AM15: Y | AN15: 80 | AO15: Y | AP15: 80 | AQ15: Y | AR15: NA | AS15: Y | AT15: NA | AU15: Y | AV15: NA | AW15: Y | AX15: 61.67 | AY15: Y | AZ15: 61.67 | BA15: Y | BB15: 74 | BC15: Y | BD15: NA | BE15: Y | BF15: NA | BG15: Y | BH15: NA | BI15: Y | BJ15: 76 | BK15: Y | BL15: 75.692 | BM15: Y | BN15: 76.236 | BO15: Y | BP15: 68.18 | BQ15: Y | BR15: 100 | BS15: Y | BT15: 66.67 | BU15: Y
A16: 2010992008 | B16: 72.5 | C16: Y | D16: 73.08 | E16: Y | F16: 70.59 | G16: Y | H16: 72.73 | I16: Y | J16: 100 | K16: Y | L16: 73.33 | M16: Y | N16: NA | O16: Y | P16: NA | Q16: NA | R16: NA | S16: NA | T16: NA | U16: NA | V16: NA | W16: NA | X16: NA | Y16: NA | Z16: NA | AA16: NA | AB16: NA | AC16: NA | AD16: NA | AE16: NA | AF16: NA | AG16: NA | AH16: NA | AI16: NA | AJ16: NA | AK16: NA | AL16: 80 | AM16: Y | AN16: 80 | AO16: Y | AP16: 80 | AQ16: Y | AR16: NA | AS16: Y | AT16: NA | AU16: Y | AV16: NA | AW16: Y | AX16: 71.67 | AY16: Y | AZ16: 71.67 | BA16: Y | BB16: 86 | BC16: Y | BD16: NA | BE16: Y | BF16: NA | BG16: Y | BH16: NA | BI16: Y | BJ16: 77 | BK16: Y | BL16: 77.232 | BM16: Y | BN16: 76.236 | BO16: Y | BP16: 72.73 | BQ16: Y | BR16: 100 | BS16: Y | BT16: 73.33 | BU16: Y
A17: 2010992009 | B17: 70 | C17: Y | D17: 69.23 | E17: Y | F17: 82.35 | G17: Y | H17: 72.73 | I17: Y | J17: 50 | K17: N | L17: 73.33 | M17: Y | N17: NA | O17: Y | P17: NA | Q17: NA | R17: NA | S17: NA | T17: NA | U17: NA | V17: NA | W17: NA | X17: NA | Y17: NA | Z17: NA | AA17: NA | AB17: NA | AC17: NA | AD17: NA | AE17: NA | AF17: NA | AG17: NA | AH17: NA | AI17: NA | AJ17: NA | AK17: NA | AL17: 83.33 | AM17: Y | AN17: 83.33 | AO17: Y | AP17: 83.33 | AQ17: Y | AR17: NA | AS17: Y | AT17: NA | AU17: Y | AV17: NA | AW17: Y | AX17: 71.67 | AY17: Y | AZ17: 71.67 | BA17: Y | BB17: 86 | BC17: Y | BD17: NA | BE17: Y | BF17: NA | BG17: Y | BH17: NA | BI17: Y | BJ17: 77.998 | BK17: Y | BL17: 77.69 | BM17: Y | BN17: 82.938 | BO17: Y | BP17: 72.73 | BQ17: Y | BR17: 50 | BS17: N | BT17: 73.33 | BU17: Y
A18: 2010992010 | B18: 72.5 | C18: Y | D18: 73.08 | E18: Y | F18: 76.47 | G18: Y | H18: 77.27 | I18: Y | J18: 50 | K18: N | L18: 80 | M18: Y | N18: NA | O18: Y | P18: NA | Q18: NA | R18: NA | S18: NA | T18: NA | U18: NA | V18: NA | W18: NA | X18: NA | Y18: NA | Z18: NA | AA18: NA | AB18: NA | AC18: NA | AD18: NA | AE18: NA | AF18: NA | AG18: NA | AH18: NA | AI18: NA | AJ18: NA | AK18: NA | AL18: 80 | AM18: Y | AN18: 80 | AO18: Y | AP18: 80 | AQ18: Y | AR18: NA | AS18: Y | AT18: NA | AU18: Y | AV18: NA | AW18: Y | AX18: 73.33 | AY18: Y | AZ18: 73.33 | BA18: Y | BB18: 88 | BC18: Y | BD18: NA | BE18: Y | BF18: NA | BG18: Y | BH18: NA | BI18: Y | BJ18: 77 | BK18: Y | BL18: 77.232 | BM18: Y | BN18: 78.588 | BO18: Y | BP18: 77.27 | BQ18: Y | BR18: 50 | BS18: N | BT18: 80 | BU18: Y
A19: 2010992011 | B19: 70 | C19: Y | D19: 73.08 | E19: Y | F19: 70.59 | G19: Y | H19: 77.27 | I19: Y | J19: 50 | K19: N | L19: 80 | M19: Y | N19: NA | O19: Y | P19: NA | Q19: NA | R19: NA | S19: NA | T19: NA | U19: NA | V19: NA | W19: NA | X19: NA | Y19: NA | Z19: NA | AA19: NA | AB19: NA | AC19: NA | AD19: NA | AE19: NA | AF19: NA | AG19: NA | AH19: NA | AI19: NA | AJ19: NA | AK19: NA | AL19: 76.67 | AM19: Y | AN19: 76.67 | AO19: Y | AP19: 76.67 | AQ19: Y | AR19: NA | AS19: Y | AT19: NA | AU19: Y | AV19: NA | AW19: Y | AX19: 48.33 | AY19: N | AZ19: 48.33 | BA19: N | BB19: 58 | BC19: N | BD19: NA | BE19: Y | BF19: NA | BG19: Y | BH19: NA | BI19: Y | BJ19: 74.002 | BK19: Y | BL19: 75.234 | BM19: Y | BN19: 74.238 | BO19: Y | BP19: 77.27 | BQ19: Y | BR19: 50 | BS19: N | BT19: 80 | BU19: Y
A20: 2010992012 | B20: 65 | C20: Y | D20: 65.38 | E20: Y | F20: 58.82 | G20: N | H20: 68.18 | I20: Y | J20: 50 | K20: N | L20: 66.67 | M20: Y | N20: NA | O20: Y | P20: NA | Q20: NA | R20: NA | S20: NA | T20: NA | U20: NA | V20: NA | W20: NA | X20: NA | Y20: NA | Z20: NA | AA20: NA | AB20: NA | AC20: NA | AD20: NA | AE20: NA | AF20: NA | AG20: NA | AH20: NA | AI20: NA | AJ20: NA | AK20: NA | AL20: 68.33 | AM20: Y | AN20: 68.33 | AO20: Y | AP20: 68.33 | AQ20: Y | AR20: NA | AS20: Y | AT20: NA | AU20: Y | AV20: NA | AW20: Y | AX20: 73.33 | AY20: Y | AZ20: 73.33 | BA20: Y | BB20: 88 | BC20: Y | BD20: NA | BE20: Y | BF20: NA | BG20: Y | BH20: NA | BI20: Y | BJ20: 66.998 | BK20: Y | BL20: 67.15 | BM20: Y | BN20: 64.526 | BO20: Y | BP20: 68.18 | BQ20: Y | BR20: 50 | BS20: N | BT20: 66.67 | BU20: Y
A21: 2010992014 | B21: 72.5 | C21: Y | D21: 73.08 | E21: Y | F21: 76.47 | G21: Y | H21: 77.27 | I21: Y | J21: 50 | K21: N | L21: 80 | M21: Y | N21: NA | O21: Y | P21: NA | Q21: NA | R21: NA | S21: NA | T21: NA | U21: NA | V21: NA | W21: NA | X21: NA | Y21: NA | Z21: NA | AA21: NA | AB21: NA | AC21: NA | AD21: NA | AE21: NA | AF21: NA | AG21: NA | AH21: NA | AI21: NA | AJ21: NA | AK21: NA | AL21: 80 | AM21: Y | AN21: 80 | AO21: Y | AP21: 80 | AQ21: Y | AR21: NA | AS21: Y | AT21: NA | AU21: Y | AV21: NA | AW21: Y | AX21: 71.67 | AY21: Y | AZ21: 71.67 | BA21: Y | BB21: 86 | BC21: Y | BD21: NA | BE21: Y | BF21: NA | BG21: Y | BH21: NA | BI21: Y | BJ21: 77 | BK21: Y | BL21: 77.232 | BM21: Y | BN21: 78.588 | BO21: Y | BP21: 77.27 | BQ21: Y | BR21: 50 | BS21: N | BT21: 80 | BU21: Y
A22: 2010992015 | B22: 65.71 | C22: Y | D22: 66.67 | E22: Y | F22: 70.59 | G22: Y | H22: 68.18 | I22: Y | J22: 50 | K22: N | L22: 66.67 | M22: Y | N22: NA | O22: Y | P22: NA | Q22: NA | R22: NA | S22: NA | T22: NA | U22: NA | V22: NA | W22: NA | X22: NA | Y22: NA | Z22: NA | AA22: NA | AB22: NA | AC22: NA | AD22: NA | AE22: NA | AF22: NA | AG22: NA | AH22: NA | AI22: NA | AJ22: NA | AK22: NA | AL22: 63.33 | AM22: Y | AN22: 63.33 | AO22: Y | AP22: 63.33 | AQ22: Y | AR22: NA | AS22: Y | AT22: NA | AU22: Y | AV22: NA | AW22: Y | AX22: 58.33 | AY22: N | AZ22: 58.33 | BA22: N | BB22: 70 | BC22: Y | BD22: NA | BE22: Y | BF22: NA | BG22: Y | BH22: NA | BI22: Y | BJ22: 64.282 | BK22: Y | BL22: 64.666 | BM22: Y | BN22: 66.234 | BO22: Y | BP22: 68.18 | BQ22: Y | BR22: 50 | BS22: N | BT22: 66.67 | BU22: Y
A23: 2010992016 | B23: 52.5 | C23: N | D23: 57.69 | E23: N | F23: 47.06 | G23: N | H23: 50 | I23: N | J23: 50 | K23: N | L23: 46.67 | M23: N | N23: NA | O23: Y | P23: NA | Q23: NA | R23: NA | S23: NA | T23: NA | U23: NA | V23: NA | W23: NA | X23: NA | Y23: NA | Z23: NA | AA23: NA | AB23: NA | AC23: NA | AD23: NA | AE23: NA | AF23: NA | AG23: NA | AH23: NA | AI23: NA | AJ23: NA | AK23: NA | AL23: 83.33 | AM23: Y | AN23: 83.33 | AO23: Y | AP23: 83.33 | AQ23: Y | AR23: NA | AS23: Y | AT23: NA | AU23: Y | AV23: NA | AW23: Y | AX23: 51.67 | AY23: N | AZ23: 51.67 | BA23: N | BB23: 62 | BC23: Y | BD23: NA | BE23: Y | BF23: NA | BG23: Y | BH23: NA | BI23: Y | BJ23: 70.998 | BK23: Y | BL23: 73.074 | BM23: Y | BN23: 68.822 | BO23: Y | BP23: 50 | BQ23: N | BR23: 50 | BS23: N | BT23: 46.67 | BU23: N
A24: 2010992017 | B24: 77.5 | C24: Y | D24: 76.92 | E24: Y | F24: 76.47 | G24: Y | H24: 77.27 | I24: Y | J24: 100 | K24: Y | L24: 80 | M24: Y | N24: NA | O24: Y | P24: NA | Q24: NA | R24: NA | S24: NA | T24: NA | U24: NA | V24: NA | W24: NA | X24: NA | Y24: NA | Z24: NA | AA24: NA | AB24: NA | AC24: NA | AD24: NA | AE24: NA | AF24: NA | AG24: NA | AH24: NA | AI24: NA | AJ24: NA | AK24: NA | AL24: 83.33 | AM24: Y | AN24: 83.33 | AO24: Y | AP24: 83.33 | AQ24: Y | AR24: NA | AS24: Y | AT24: NA | AU24: Y | AV24: NA | AW24: Y | AX24: 66.67 | AY24: Y | AZ24: 66.67 | BA24: Y | BB24: 80 | BC24: Y | BD24: NA | BE24: Y | BF24: NA | BG24: Y | BH24: NA | BI24: Y | BJ24: 80.998 | BK24: Y | BL24: 80.766 | BM24: Y | BN24: 80.586 | BO24: Y | BP24: 77.27 | BQ24: Y | BR24: 100 | BS24: Y | BT24: 80 | BU24: Y
A25: 2010992018 | B25: 65 | C25: Y | D25: 65.38 | E25: Y | F25: 76.47 | G25: Y | H25: 72.73 | I25: Y | J25: 50 | K25: N | L25: 73.33 | M25: Y | N25: NA | O25: Y | P25: NA | Q25: NA | R25: NA | S25: NA | T25: NA | U25: NA | V25: NA | W25: NA | X25: NA | Y25: NA | Z25: NA | AA25: NA | AB25: NA | AC25: NA | AD25: NA | AE25: NA | AF25: NA | AG25: NA | AH25: NA | AI25: NA | AJ25: NA | AK25: NA | AL25: 85 | AM25: Y | AN25: 85 | AO25: Y | AP25: 85 | AQ25: Y | AR25: NA | AS25: Y | AT25: NA | AU25: Y | AV25: NA | AW25: Y | AX25: 71.67 | AY25: Y | AZ25: 71.67 | BA25: Y | BB25: 86 | BC25: Y | BD25: NA | BE25: Y | BF25: NA | BG25: Y | BH25: NA | BI25: Y | BJ25: 77 | BK25: Y | BL25: 77.152 | BM25: Y | BN25: 81.588 | BO25: Y | BP25: 72.73 | BQ25: Y | BR25: 50 | BS25: N | BT25: 73.33 | BU25: Y
A26: 2010992019 | B26: 55 | C26: N | D26: 50 | E26: N | F26: 52.94 | G26: N | H26: 59.09 | I26: N | J26: 50 | K26: N | L26: 60 | M26: Y | N26: NA | O26: Y | P26: NA | Q26: NA | R26: NA | S26: NA | T26: NA | U26: NA | V26: NA | W26: NA | X26: NA | Y26: NA | Z26: NA | AA26: NA | AB26: NA | AC26: NA | AD26: NA | AE26: NA | AF26: NA | AG26: NA | AH26: NA | AI26: NA | AJ26: NA | AK26: NA | AL26: 83.33 | AM26: Y | AN26: 83.33 | AO26: Y | AP26: 83.33 | AQ26: Y | AR26: NA | AS26: Y | AT26: NA | AU26: Y | AV26: NA | AW26: Y | AX26: 70 | AY26: Y | AZ26: 70 | BA26: Y | BB26: 84 | BC26: Y | BD26: NA | BE26: Y | BF26: NA | BG26: Y | BH26: NA | BI26: Y | BJ26: 71.998 | BK26: Y | BL26: 69.998 | BM26: Y | BN26: 71.174 | BO26: Y | BP26: 59.09 | BQ26: N | BR26: 50 | BS26: N | BT26: 60 | BU26: Y
A27: 2010992163 | B27: 77.5 | C27: Y | D27: 80.77 | E27: Y | F27: 82.35 | G27: Y | H27: 81.82 | I27: Y | J27: 100 | K27: Y | L27: 86.67 | M27: Y | N27: NA | O27: Y | P27: NA | Q27: NA | R27: NA | S27: NA | T27: NA | U27: NA | V27: NA | W27: NA | X27: NA | Y27: NA | Z27: NA | AA27: NA | AB27: NA | AC27: NA | AD27: NA | AE27: NA | AF27: NA | AG27: NA | AH27: NA | AI27: NA | AJ27: NA | AK27: NA | AL27: 68.33 | AM27: Y | AN27: 68.33 | AO27: Y | AP27: 68.33 | AQ27: Y | AR27: NA | AS27: Y | AT27: NA | AU27: Y | AV27: NA | AW27: Y | AX27: 66.67 | AY27: Y | AZ27: 66.67 | BA27: Y | BB27: 80 | BC27: Y | BD27: NA | BE27: Y | BF27: NA | BG27: Y | BH27: NA | BI27: Y | BJ27: 71.998 | BK27: Y | BL27: 73.306 | BM27: Y | BN27: 73.938 | BO27: Y | BP27: 81.82 | BQ27: Y | BR27: 100 | BS27: Y | BT27: 86.67 | BU27: Y
A28: 2010992202 | B28: 75 | C28: Y | D28: 76.92 | E28: Y | F28: 76.47 | G28: Y | H28: 77.27 | I28: Y | J28: 100 | K28: Y | L28: 80 | M28: Y | N28: NA | O28: Y | P28: NA | Q28: NA | R28: NA | S28: NA | T28: NA | U28: NA | V28: NA | W28: NA | X28: NA | Y28: NA | Z28: NA | AA28: NA | AB28: NA | AC28: NA | AD28: NA | AE28: NA | AF28: NA | AG28: NA | AH28: NA | AI28: NA | AJ28: NA | AK28: NA | AL28: 78.33 | AM28: Y | AN28: 78.33 | AO28: Y | AP28: 78.33 | AQ28: Y | AR28: NA | AS28: Y | AT28: NA | AU28: Y | AV28: NA | AW28: Y | AX28: 66.67 | AY28: Y | AZ28: 66.67 | BB28: 80 | BD28: NA | BF28: NA | BH28: NA | BJ28: 76.998 | BK28: Y | BL28: 77.766 | BM28: Y | BN28: 77.586 | BO28: Y | BP28: 77.27 | BQ28: Y | BR28: 100 | BS28: Y | BT28: 80 | BU28: Y

Sheet ST1 Student Wise
A1: Cos | B1: CO1 | C1: CO1 | D1: CO1 | E1: CO1 | F1: CO1 | G1: CO2 | H1: CO2 | I1: CO2 | J1: CO2 | K1: CO2 | L1: CO3 | M1: CO3 | N1: CO3 | O1: CO3 | P1: CO3 | Q1: CO4 | R1: CO4 | S1: CO4 | T1: CO4 | U1: CO4 | V1: CO5 | W1: CO5 | X1: CO5 | Y1: CO5 | Z1: CO5 | AA1: CO6 | AB1: CO6 | AC1: CO6 | AD1: CO6 | AE1: CO6
A2: {='[1]ST1 Result'!$B$1:INDEX('[1]ST1 Result'!$B:$B,COUNTA('[1]ST1 Result'!$B:$B))} -> Admission No. (Roll No.) | B2: Max | C2: Achieved | D2: Percentage | E2: Score | F2: Tarrget Achieved | G2: Max | H2: Achieved | I2: Percentage | J2: Score | K2: Tarrget Achieved | L2: Max | M2: Achieved | N2: Percentage | O2: Score | P2: Tarrget Achieved | Q2: Max | R2: Achieved | S2: Percentage | T2: Score | U2: Tarrget Achieved | V2: Max | W2: Achieved | X2: Percentage | Y2: Score | Z2: Tarrget Achieved | AA2: Max | AB2: Achieved | AC2: Percentage | AD2: Score | AE2: Tarrget Achieved | AH2: Course Outcome | AI2: Achieved CO Score
A3: 2010990089 | B3: {='[1]ST1 Student MO CO Score'!$B$2:INDEX('[1]ST1 Student MO CO Score'!$B:$B,COUNTA('[1]ST1 Student MO CO Score'!$B:$B))} -> 36 | C3: {='[1]ST1 Student Attained CO Score'!$B$2:INDEX('[1]ST1 Student Attained CO Score'!$B:$B,COUNTA('[1]ST1 Student Attained CO Score'!$B:$B))} -> 14 | D3: {=IFERROR(ROUND('[1]ST1 Student Attainment percent'!$B$2:INDEX('[1]ST1 Student Attainment percent'!$B:$B,COUNTA('[1]ST1 Student Attainment percent'!$B:$B)),2),"NA")} -> 38.89 | E3: {='[1]ST1 CO Attainment Score'!$B$2:INDEX('[1]ST1 CO Attainment Score'!$B:$B,COUNTA('[1]ST1 CO Attainment Score'!$B:$B))} -> 0 | F3: {='[1]ST1 Target Attained'!$B$2:INDEX('[1]ST1 Target Attained'!$B:$B,COUNTA('[1]ST1 Target Attained'!$B:$B))} -> N | G3: {='[1]ST1 Student MO CO Score'!$C$2:INDEX('[1]ST1 Student MO CO Score'!$C:$C,COUNTA('[1]ST1 Student MO CO Score'!$C:$C))} -> 22 | H3: {='[1]ST1 Student Attained CO Score'!$C$2:INDEX('[1]ST1 Student Attained CO Score'!$C:$C,COUNTA('[1]ST1 Student Attained CO Score'!$C:$C))} -> 8 | I3: {=IFERROR(ROUND('[1]ST1 Student Attainment percent'!$C$2:INDEX('[1]ST1 Student Attainment percent'!$C:$C,COUNTA('[1]ST1 Student Attainment percent'!$C:$C)),2),"NA")} -> 36.36 | J3: {='[1]ST1 CO Attainment Score'!$C$2:INDEX('[1]ST1 CO Attainment Score'!$C:$C,COUNTA('[1]ST1 CO Attainment Score'!$C:$C))} -> 0 | K3: {='[1]ST1 Target Attained'!$C$2:INDEX('[1]ST1 Target Attained'!$C:$C,COUNTA('[1]ST1 Target Attained'!$C:$C))} -> N | L3: {='[1]ST1 Student MO CO Score'!$D$2:INDEX('[1]ST1 Student MO CO Score'!$D:$D,COUNTA('[1]ST1 Student MO CO Score'!$D:$D))} -> 17 | M3: {='[1]ST1 Student Attained CO Score'!$D$2:INDEX('[1]ST1 Student Attained CO Score'!$D:$D,COUNTA('[1]ST1 Student Attained CO Score'!$D:$D))} -> 6 | N3: {=IFERROR(ROUND('[1]ST1 Student Attainment percent'!$D$2:INDEX('[1]ST1 Student Attainment percent'!$D:$D,COUNTA('[1]ST1 Student Attainment percent'!$D:$D)),2),"NA")} -> 35.29 | O3: {='[1]ST1 CO Attainment Score'!$D$2:INDEX('[1]ST1 CO Attainment Score'!$D:$D,COUNTA('[1]ST1 CO Attainment Score'!$D:$D))} -> 0 | P3: {='[1]ST1 Target Attained'!$D$2:INDEX('[1]ST1 Target Attained'!$D:$D,COUNTA('[1]ST1 Target Attained'!$D:$D))} -> N | Q3: {='[1]ST1 Student MO CO Score'!$E$2:INDEX('[1]ST1 Student MO CO Score'!$E:$E,COUNTA('[1]ST1 Student MO CO Score'!$E:$E))} -> 22 | R3: {='[1]ST1 Student Attained CO Score'!$E$2:INDEX('[1]ST1 Student Attained CO Score'!$E:$E,COUNTA('[1]ST1 Student Attained CO Score'!$E:$E))} -> 10 | S3: {=IFERROR(ROUND('[1]ST1 Student Attainment percent'!$E$2:INDEX('[1]ST1 Student Attainment percent'!$E:$E,COUNTA('[1]ST1 Student Attainment percent'!$E:$E)),2),"NA")} -> 45.45 | T3: {='[1]ST1 CO Attainment Score'!$E$2:INDEX('[1]ST1 CO Attainment Score'!$E:$E,COUNTA('[1]ST1 CO Attainment Score'!$E:$E))} -> 0 | U3: {='[1]ST1 Target Attained'!$E$2:INDEX('[1]ST1 Target Attained'!$E:$E,COUNTA('[1]ST1 Target Attained'!$E:$E))} -> N | V3: {='[1]ST1 Student MO CO Score'!$F$2:INDEX('[1]ST1 Student MO CO Score'!$F:$F,COUNTA('[1]ST1 Student MO CO Score'!$F:$F))} -> 0 | W3: {='[1]ST1 Student Attained CO Score'!$F$2:INDEX('[1]ST1 Student Attained CO Score'!$F:$F,COUNTA('[1]ST1 Student Attained CO Score'!$F:$F))} -> 0 | X3: {=IFERROR(ROUND('[1]ST1 Student Attainment percent'!$F$2:INDEX('[1]ST1 Student Attainment percent'!$F:$F,COUNTA('[1]ST1 Student Attainment percent'!$F:$F)),2),"NA")} -> NA | Y3: {='[1]ST1 CO Attainment Score'!$F$2:INDEX('[1]ST1 CO Attainment Score'!$F:$F,COUNTA('[1]ST1 CO Attainment Score'!$F:$F))} -> NA | Z3: {='[1]ST1 Target Attained'!$F$2:INDEX('[1]ST1 Target Attained'!$F:$F,COUNTA('[1]ST1 Target Attained'!$F:$F))} -> NA | AA3: {='[1]ST1 Student MO CO Score'!$G$2:INDEX('[1]ST1 Student MO CO Score'!$G:$G,COUNTA('[1]ST1 Student MO CO Score'!$G:$G))} -> 15 | AB3: {='[1]ST1 Student Attained CO Score'!$G$2:INDEX('[1]ST1 Student Attained CO Score'!$G:$G,COUNTA('[1]ST1 Student Attained CO Score'!$G:$G))} -> 8 | AC3: {=IFERROR(ROUND('[1]ST1 Student Attainment percent'!$G$2:INDEX('[1]ST1 Student Attainment percent'!$G:$G,COUNTA('[1]ST1 Student Attainment percent'!$G:$G)),2),"NA")} -> 53.33 | AD3: {='[1]ST1 CO Attainment Score'!$G$2:INDEX('[1]ST1 CO Attainment Score'!$G:$G,COUNTA('[1]ST1 CO Attainment Score'!$G:$G))} -> 0 | AE3: {='[1]ST1 Target Attained'!$G$2:INDEX('[1]ST1 Target Attained'!$G:$G,COUNTA('[1]ST1 Target Attained'!$G:$G))} -> N | AH3: CO1 | AI3: =Averages!E3 -> 3
A4: 2010992002 | B4: 36 | C4: 34 | D4: 94.44 | E4: 3 | F4: Y | G4: 22 | H4: 21 | I4: 95.45 | J4: 3 | K4: Y | L4: 17 | M4: 17 | N4: 100 | O4: 3 | P4: Y | Q4: 22 | R4: 20 | S4: 90.91 | T4: 3 | U4: Y | V4: 0 | W4: 0 | X4: NA | Y4: NA | Z4: NA | AA4: 15 | AB4: 14 | AC4: 93.33 | AD4: 3 | AE4: Y | AH4: CO2 | AI4: =Averages!I3 -> 3
A5: 2010992004 | B5: 40 | C5: 28 | D5: 70 | E5: 3 | F5: Y | G5: 26 | H5: 18 | I5: 69.23 | J5: 3 | K5: Y | L5: 17 | M5: 12 | N5: 70.59 | O5: 3 | P5: Y | Q5: 22 | R5: 15 | S5: 68.18 | T5: 3 | U5: Y | V5: 2 | W5: 2 | X5: 100 | Y5: 3 | Z5: Y | AA5: 15 | AB5: 10 | AC5: 66.67 | AD5: 3 | AE5: Y | AH5: CO3 | AI5: =Averages!M3 -> 2
A6: 2010992005 | B6: 36 | C6: 25 | D6: 69.44 | E6: 3 | F6: Y | G6: 22 | H6: 16 | I6: 72.73 | J6: 3 | K6: Y | L6: 17 | M6: 13 | N6: 76.47 | O6: 3 | P6: Y | Q6: 22 | R6: 16 | S6: 72.73 | T6: 3 | U6: Y | V6: 0 | W6: 0 | X6: NA | Y6: NA | Z6: NA | AA6: 15 | AB6: 11 | AC6: 73.33 | AD6: 3 | AE6: Y | AH6: CO4 | AI6: =Averages!Q3 -> 3
A7: 2010992006 | B7: 40 | C7: 28 | D7: 70 | E7: 3 | F7: Y | G7: 26 | H7: 18 | I7: 69.23 | J7: 3 | K7: Y | L7: 17 | M7: 12 | N7: 70.59 | O7: 3 | P7: Y | Q7: 22 | R7: 15 | S7: 68.18 | T7: 3 | U7: Y | V7: 2 | W7: 2 | X7: 100 | Y7: 3 | Z7: Y | AA7: 15 | AB7: 10 | AC7: 66.67 | AD7: 3 | AE7: Y | AH7: CO5 | AI7: =Averages!U3 -> 0
A8: 2010992008 | B8: 40 | C8: 29 | D8: 72.5 | E8: 3 | F8: Y | G8: 26 | H8: 19 | I8: 73.08 | J8: 3 | K8: Y | L8: 17 | M8: 12 | N8: 70.59 | O8: 3 | P8: Y | Q8: 22 | R8: 16 | S8: 72.73 | T8: 3 | U8: Y | V8: 2 | W8: 2 | X8: 100 | Y8: 3 | Z8: Y | AA8: 15 | AB8: 11 | AC8: 73.33 | AD8: 3 | AE8: Y | AH8: CO6 | AI8: =Averages!Y3 -> 3
A9: 2010992009 | B9: 40 | C9: 28 | D9: 70 | E9: 3 | F9: Y | G9: 26 | H9: 18 | I9: 69.23 | J9: 3 | K9: Y | L9: 17 | M9: 14 | N9: 82.35 | O9: 3 | P9: Y | Q9: 22 | R9: 16 | S9: 72.73 | T9: 3 | U9: Y | V9: 2 | W9: 1 | X9: 50 | Y9: 0 | Z9: N | AA9: 15 | AB9: 11 | AC9: 73.33 | AD9: 3 | AE9: Y | AH9: Overall Attainment
A10: 2010992010 | B10: 40 | C10: 29 | D10: 72.5 | E10: 3 | F10: Y | G10: 26 | H10: 19 | I10: 73.08 | J10: 3 | K10: Y | L10: 17 | M10: 13 | N10: 76.47 | O10: 3 | P10: Y | Q10: 22 | R10: 17 | S10: 77.27 | T10: 3 | U10: Y | V10: 2 | W10: 1 | X10: 50 | Y10: 0 | Z10: N | AA10: 15 | AB10: 12 | AC10: 80 | AD10: 3 | AE10: Y
A11: 2010992011 | B11: 40 | C11: 28 | D11: 70 | E11: 3 | F11: Y | G11: 26 | H11: 19 | I11: 73.08 | J11: 3 | K11: Y | L11: 17 | M11: 12 | N11: 70.59 | O11: 3 | P11: Y | Q11: 22 | R11: 17 | S11: 77.27 | T11: 3 | U11: Y | V11: 2 | W11: 1 | X11: 50 | Y11: 0 | Z11: N | AA11: 15 | AB11: 12 | AC11: 80 | AD11: 3 | AE11: Y
A12: 2010992012 | B12: 40 | C12: 26 | D12: 65 | E12: 3 | F12: Y | G12: 26 | H12: 17 | I12: 65.38 | J12: 3 | K12: Y | L12: 17 | M12: 10 | N12: 58.82 | O12: 0 | P12: N | Q12: 22 | R12: 15 | S12: 68.18 | T12: 3 | U12: Y | V12: 2 | W12: 1 | X12: 50 | Y12: 0 | Z12: N | AA12: 15 | AB12: 10 | AC12: 66.67 | AD12: 3 | AE12: Y
A13: 2010992014 | B13: 40 | C13: 29 | D13: 72.5 | E13: 3 | F13: Y | G13: 26 | H13: 19 | I13: 73.08 | J13: 3 | K13: Y | L13: 17 | M13: 13 | N13: 76.47 | O13: 3 | P13: Y | Q13: 22 | R13: 17 | S13: 77.27 | T13: 3 | U13: Y | V13: 2 | W13: 1 | X13: 50 | Y13: 0 | Z13: N | AA13: 15 | AB13: 12 | AC13: 80 | AD13: 3 | AE13: Y
A14: 2010992015 | B14: 35 | C14: 23 | D14: 65.71 | E14: 3 | F14: Y | G14: 21 | H14: 14 | I14: 66.67 | J14: 3 | K14: Y | L14: 17 | M14: 12 | N14: 70.59 | O14: 3 | P14: Y | Q14: 22 | R14: 15 | S14: 68.18 | T14: 3 | U14: Y | V14: 2 | W14: 1 | X14: 50 | Y14: 0 | Z14: N | AA14: 15 | AB14: 10 | AC14: 66.67 | AD14: 3 | AE14: Y
A15: 2010992016 | B15: 40 | C15: 21 | D15: 52.5 | E15: 0 | F15: N | G15: 26 | H15: 15 | I15: 57.69 | J15: 0 | K15: N | L15: 17 | M15: 8 | N15: 47.06 | O15: 0 | P15: N | Q15: 22 | R15: 11 | S15: 50 | T15: 0 | U15: N | V15: 2 | W15: 1 | X15: 50 | Y15: 0 | Z15: N | AA15: 15 | AB15: 7 | AC15: 46.67 | AD15: 0 | AE15: N
A16: 2010992017 | B16: 40 | C16: 31 | D16: 77.5 | E16: 3 | F16: Y | G16: 26 | H16: 20 | I16: 76.92 | J16: 3 | K16: Y | L16: 17 | M16: 13 | N16: 76.47 | O16: 3 | P16: Y | Q16: 22 | R16: 17 | S16: 77.27 | T16: 3 | U16: Y | V16: 2 | W16: 2 | X16: 100 | Y16: 3 | Z16: Y | AA16: 15 | AB16: 12 | AC16: 80 | AD16: 3 | AE16: Y
A17: 2010992018 | B17: 40 | C17: 26 | D17: 65 | E17: 3 | F17: Y | G17: 26 | H17: 17 | I17: 65.38 | J17: 3 | K17: Y | L17: 17 | M17: 13 | N17: 76.47 | O17: 3 | P17: Y | Q17: 22 | R17: 16 | S17: 72.73 | T17: 3 | U17: Y | V17: 2 | W17: 1 | X17: 50 | Y17: 0 | Z17: N | AA17: 15 | AB17: 11 | AC17: 73.33 | AD17: 3 | AE17: Y
A18: 2010992019 | B18: 40 | C18: 22 | D18: 55 | E18: 0 | F18: N | G18: 26 | H18: 13 | I18: 50 | J18: 0 | K18: N | L18: 17 | M18: 9 | N18: 52.94 | O18: 0 | P18: N | Q18: 22 | R18: 13 | S18: 59.09 | T18: 3 | U18: N | V18: 2 | W18: 1 | X18: 50 | Y18: 0 | Z18: N | AA18: 15 | AB18: 9 | AC18: 60 | AD18: 3 | AE18: Y
A19: 2010992163 | B19: 40 | C19: 31 | D19: 77.5 | E19: 3 | F19: Y | G19: 26 | H19: 21 | I19: 80.77 | J19: 3 | K19: Y | L19: 17 | M19: 14 | N19: 82.35 | O19: 3 | P19: Y | Q19: 22 | R19: 18 | S19: 81.82 | T19: 3 | U19: Y | V19: 2 | W19: 2 | X19: 100 | Y19: 3 | Z19: Y | AA19: 15 | AB19: 13 | AC19: 86.67 | AD19: 3 | AE19: Y
A20: 2010992202 | B20: 40 | C20: 30 | D20: 75 | E20: 3 | F20: Y | G20: 26 | H20: 20 | I20: 76.92 | J20: 3 | K20: Y | L20: 17 | M20: 13 | N20: 76.47 | O20: 3 | P20: Y | Q20: 22 | R20: 17 | S20: 77.27 | T20: 3 | U20: Y | V20: 2 | W20: 2 | X20: 100 | Y20: 3 | Z20: Y | AA20: 15 | AB20: 12 | AC20: 80 | AD20: 3 | AE20: Y

Sheet ST2 Student Wise
A1: Cos | B1: CO1 | C1: CO1 | D1: CO1 | E1: CO1 | F1: CO1 | G1: CO2 | H1: CO2 | I1: CO2 | J1: CO2 | K1: CO2 | L1: CO3 | M1: CO3 | N1: CO3 | O1: CO3 | P1: CO3 | Q1: CO4 | R1: CO4 | S1: CO4 | T1: CO4 | U1: CO4 | V1: CO5 | W1: CO5 | X1: CO5 | Y1: CO5 | Z1: CO5 | AA1: CO6 | AB1: CO6 | AC1: CO6 | AD1: CO6 | AE1: CO6
A2: {='[1]ST2 Result'!$B$1:INDEX('[1]ST2 Result'!$B:$B,COUNTA('[1]ST2 Result'!$B:$B))} -> Admission No. (Roll No.) | B2: Max | C2: Achieved | D2: Percentage | E2: Score | F2: Tarrget Achieved | G2: Max | H2: Achieved | I2: Percentage | J2: Score | K2: Tarrget Achieved | L2: Max | M2: Achieved | N2: Percentage | O2: Score | P2: Tarrget Achieved | Q2: Max | R2: Achieved | S2: Percentage | T2: Score | U2: Tarrget Achieved | V2: Max | W2: Achieved | X2: Percentage | Y2: Score | Z2: Tarrget Achieved | AA2: Max | AB2: Achieved | AC2: Percentage | AD2: Score | AE2: Tarrget Achieved
